Workbook
Name TOTAL_DIRETO: 'DIRETOS.DET'!$I$87
Name DIRETOS_RES_SEM_BDI: 'DIRETOS.RES'!$I$18
Name DIRETOS_RES_COM_BDI: 'DIRETOS.RES'!$N$18
Name TOTAL_ADM: 'INDIRETOS.DET'!$H$5
Name TOTAL_TOP: 'INDIRETOS.DET'!$H$8
Name TOTAL_LAB: 'INDIRETOS.DET'!$H$11
Name TOTAL_QSMS: 'INDIRETOS.DET'!$H$14
Name TOTAL_MOB: 'INDIRETOS.DET'!$H$17
Name TOTAL_INDIRETO: 'INDIRETOS.DET'!$H$19
Name TOTAL_SEM_BDI: PLANEJAMENTO!$I$18
Name TOTAL_COM_BDI: PLANEJAMENTO!$N$18

Sheet BDI
A1: BDI — BONIFICAÇÕES E DESPESAS INDIRETAS (FÓRMULA TCU AC.2622/2013)
A2: Categoria | B2: AC (%) | C2: DF (%) | D2: R (%) | E2: CR (%) | F2: Lucro L (%) | G2: COFINS (%) | H2: ISS (%) | I2: PIS (%) | J2: CSSL (%) | K2: IR (%) | L2: T=Tributos (%) | M2: BDI Total (%)
A3: MÃO DE OBRA | B3: 5 | C3: 1.5 | D3: 1 | E3: 0 | F3: 9 | G3: 3 | H3: 5 | I3: 0.65 | J3: 1.99 | K3: 2.74 | L3: 13.38 | M3: 34.5
A4: MATERIAL | B4: 5 | C4: 0 | D4: 0 | E4: 0 | F4: 0 | G4: 0 | H4: 0 | I4: 0 | J4: 0 | K4: 0 | L4: 0 | M4: 5
A5: SERVIÇOS | B5: 5 | C5: 1.5 | D5: 1 | E5: 0 | F5: 9 | G5: 3 | H5: 5 | I5: 0.65 | J5: 1.99 | K5: 2.74 | L5: 13.38 | M5: 34.5
A6: INDIRETO | B6: 4 | C6: 0 | D6: 0 | E6: 0 | F6: 2 | G6: 3 | H6: 5 | I6: 0.65 | J6: 1.99 | K6: 2.74 | L6: 13.38 | M6: 22.37
A7: DIESEL | B7: 4 | C7: 0 | D7: 0 | E7: 0 | F7: 5 | G7: 3 | H7: 5 | I7: 0.65 | J7: 1.99 | K7: 2.74 | L7: 13.38 | M7: 25.84
A9: Fórmula: BDI = (1 + AC + DF + R + CR + L) / (1 - T) - 1 | T = COFINS+ISS+PIS+CSSL+IR
A11: BDI Efetivo Aplicado por Item do Planejamento
A12: Item ID | B12: MO BDI (%) | C12: EQ BDI (%) | D12: MAT BDI (%) | E12: DIESEL BDI (%)
A13: eap-3_1 | B13: 34.5 | C13: 34.5 | D13: 20 | E13: 34.5
A14: eap-1_2 | B14: 34.5 | C14: 34.5 | D14: 20 | E14: 34.5
A15: eap-1_1 | B15: 34.5 | C15: 34.5 | D15: 20 | E15: 34.5
A16: eap-1_3 | B16: 34.5 | C16: 34.5 | D16: 20 | E16: 34.5
A17: eap-2_1 | B17: 34.5 | C17: 34.5 | D17: 20 | E17: 34.5
A18: eap-3_3 | B18: 34.5 | C18: 34.5 | D18: 20 | E18: 34.5
A19: eap-3_6 | B19: 34.5 | C19: 34.5 | D19: 20 | E19: 34.5
A20: eap-5_1 | B20: 34.5 | C20: 34.5 | D20: 20 | E20: 34.5
A21: eap-2_3 | B21: 34.5 | C21: 34.5 | D21: 20 | E21: 34.5
A22: eap-4_1 | B22: 34.5 | C22: 34.5 | D22: 20 | E22: 34.5
A23: eap-3_5 | B23: 34.5 | C23: 34.5 | D23: 20 | E23: 34.5
A24: eap-3_2 | B24: 34.5 | C24: 34.5 | D24: 20 | E24: 34.5
... A26: eap-3_4 | B26: 34.5 | C26: 34.5 | D26: 20 | E26: 34.5

Sheet DIRETOS.DET
A1: DIRETOS — EQUIPES E RECURSOS
A2: Tipo | B2: Código | C2: Descrição | D2: Papel | E2: Qtd | F2: Custo Unit/Mês (R$) | G2: Custo Total/Mês (R$) | H2: Perm. (meses) | I2: Custo Total (R$)
A3: eap-3_1 — Cerca arame liso (5 fios) com mourões de concreto, seção quadrada 10 x 10 cm (padrão VALEC) executada em solos compostos por material de 1ª e 2ª categoria
A4: MÃO DE OBRA | B4: MO-ENCARREG-TERRA | C4: Encarregado de Terraplenagem | D4: DIRETO | E4: 1 | F4: 11549.8 | G4: =E4*F4 | H4: 5.98 | I4: =G4*H4
A5: MÃO DE OBRA | B5: MO-CERQUEIRO | C5: Cerqueiro | D5: DIRETO | E5: 3 | F5: 9901.17 | G5: =E5*F5 | H5: 5.98 | I5: =G5*H5
A6: EQUIPAMENTO | B6: EQ-E0001 | C6: Automóvel (veículo leve) | D6: — | E6: 1 | F6: 3872 | G6: =E6*F6 | H6: 5.98 | I6: =G6*H6
A7: COMBUSTÍVEL | B7: EQ-E0001 | C7: Diesel S-10 (0.8 L/h) | D7: — | E7: 1 | F7: 1020.34 | G7: =E7*F7 | H7: 5.98 | I7: =G7*H7
A8: Subtotal eap-3_1 | G8: =SUM(G4:G7) | H8: 5.98 | I8: =SUM(I4:I7)
A9: eap-1_2 — Supressão vegetal, destocamento e limpeza de árvores, arbustos, vegetação rasteira e entulhos com remoção para área de depósito - DMT até 350m
A10: MÃO DE OBRA | B10: MO-OPER-ESCAV | C10: Operador de Escavadeira | D10: DIRETO | E10: 1 | F10: 12875 | G10: =E10*F10 | H10: 5.98 | I10: =G10*H10
A11: MÃO DE OBRA | B11: MO-OPER-TRATOR-EST | C11: Operador de Trator de Esteiras | D11: DIRETO | E11: 1 | F11: 12875 | G11: =E11*F11 | H11: 5.98 | I11: =G11*H11
A12: MÃO DE OBRA | B12: MO-AJUDANTE | C12: Ajudante | D12: DIRETO | E12: 3 | F12: 5261.65 | G12: =E12*F12 | H12: 5.98 | I12: =G12*H12
A13: EQUIPAMENTO | B13: EQ-E0016 | C13: Escavadeira Hidráulica 22t | D13: — | E13: 1 | F13: 35639.3 | G13: =E13*F13 | H13: 5.98 | I13: =G13*H13
A14: EQUIPAMENTO | B14: EQ-E0024 | C14: Trator de Esteiras 20t (300HP) | D14: — | E14: 1 | F14: 49477.12 | G14: =E14*F14 | H14: 5.98 | I14: =G14*H14
A15: COMBUSTÍVEL | B15: EQ-E0024 | C15: Diesel S-10 (18.0 L/h) | D15: — | E15: 1 | F15: 22957.71 | G15: =E15*F15 | H15: 5.98 | I15: =G15*H15
A16: Subtotal eap-1_2 | G16: =SUM(G10:G15) | H16: 5.98 | I16: =SUM(I10:I15)
A17: eap-1_1 — Supressão vegetal com ou sem destocamento de vegetação com Ø =< 30cm, assim como remoção de arbustos, vegetação rasteira e limpeza para a área de depósito - DMT até 350m - ALTA
A18: MÃO DE OBRA | B18: MO-OPER-ESCAV | C18: Operador de Escavadeira | D18: DIRETO | E18: 1 | F18: 12875 | G18: =E18*F18 | H18: 5.98 | I18: =G18*H18
A19: MÃO DE OBRA | B19: MO-OPER-TRATOR-EST | C19: Operador de Trator de Esteiras | D19: DIRETO | E19: 1 | F19: 12875 | G19: =E19*F19 | H19: 5.98 | I19: =G19*H19
A20: MÃO DE OBRA | B20: MO-AJUDANTE | C20: Ajudante | D20: DIRETO | E20: 3 | F20: 5261.65 | G20: =E20*F20 | H20: 5.98 | I20: =G20*H20
A21: EQUIPAMENTO | B21: EQ-E0016 | C21: Escavadeira Hidráulica 22t | D21: — | E21: 1 | F21: 35639.3 | G21: =E21*F21 | H21: 5.98 | I21: =G21*H21
A22: EQUIPAMENTO | B22: EQ-E0024 | C22: Trator de Esteiras 20t (300HP) | D22: — | E22: 1 | F22: 49477.12 | G22: =E22*F22 | H22: 5.98 | I22: =G22*H22
A23: COMBUSTÍVEL | B23: EQ-E0024 | C23: Diesel S-10 (18.0 L/h) | D23: — | E23: 1 | F23: 22957.71 | G23: =E23*F23 | H23: 5.98 | I23: =G23*H23
A24: Subtotal eap-1_1 | G24: =SUM(G18:G23) | H24: 5.98 | I24: =SUM(I18:I23)
A25: eap-1_3 — Corte com destocamento de árvores com Ø > 30cm e remoção para a área de depósito - DMT até 1000m
A26: MÃO DE OBRA | B26: MO-OPERADOR-DE-MOTOSCRA | C26: Operador de Motoscraper | D26: DIRETO | E26: 1 | F26: 13892.78 | G26: =E26*F26 | H26: 5.98 | I26: =G26*H26
A27: MÃO DE OBRA | B27: MO-AJUDANTE | C27: Ajudante | D27: DIRETO | E27: 3 | F27: 5261.65 | G27: =E27*F27 | H27: 5.98 | I27: =G27*H27
A28: EQUIPAMENTO | B28: EQ-E0031 | C28: Spread | D28: — | E28: 2 | F28: 6336 | G28: =E28*F28 | H28: 5.98 | I28: =G28*H28
A29: COMBUSTÍVEL | B29: EQ-E0031 | C29: Diesel S-10 (2.0 L/h) | D29: — | E29: 2 | F29: 2550.86 | G29: =E29*F29 | H29: 5.98 | I29: =G29*H29
A30: Subtotal eap-1_3 | G30: =SUM(G26:G29) | H30: 5.98 | I30: =SUM(I26:I29)
A31: eap-2_1 — Fornecimento e Instalação de Mata burro (padrão VALEC)
A32: MÃO DE OBRA | B32: MO-OFICIAL | C32: Oficial | D32: DIRETO | E32: 2 | F32: 7926.47 | G32: =E32*F32 | H32: 5.98 | I32: =G32*H32
A33: MÃO DE OBRA | B33: MO-AJUDANTE | C33: Ajudante | D33: DIRETO | E33: 4 | F33: 5261.65 | G33: =E33*F33 | H33: 5.98 | I33: =G33*H33
A34: EQUIPAMENTO | B34: EQ-CAM-MUNCK-23T | C34: Caminhão munck 23T | D34: — | E34: 1 | F34: 30800 | G34: =E34*F34 | H34: 5.98 | I34: =G34*H34
A35: COMBUSTÍVEL | B35: EQ-CAM-MUNCK-23T | C35: Diesel S-10 (3.0 L/h) | D35: — | E35: 1 | F35: 3826.29 | G35: =E35*F35 | H35: 5.98 | I35: =G35*H35
A36: Subtotal eap-2_1 | G36: =SUM(G32:G35) | H36: 5.98 | I36: =SUM(I32:I35)
A37: eap-3_3 — Cerca arame liso (5 fios) com mourão de eucalipto e mourão de madeira a cada 4,0 m e esticador a cada 50 m executada em solos compostos por material de 1ª e 2ª categoria
A38: MÃO DE OBRA | B38: MO-ENCARREG-TERRA | C38: Encarregado de Terraplenagem | D38: DIRETO | E38: 1 | F38: 11549.8 | G38: =E38*F38 | H38: 5.98 | I38: =G38*H38
A39: MÃO DE OBRA | B39: MO-CERQUEIRO | C39: Cerqueiro | D39: DIRETO | E39: 3 | F39: 9901.17 | G39: =E39*F39 | H39: 5.98 | I39: =G39*H39
A40: EQUIPAMENTO | B40: EQ-E0001 | C40: Automóvel (veículo leve) | D40: — | E40: 1 | F40: 3872 | G40: =E40*F40 | H40: 5.98 | I40: =G40*H40
...

Sheet DIRETOS.RES
A1: DIRETOS RESUMIDO — COMPONENTES MO/EQ/COMB/MAT s/BDI e c/BDI
A2: Item ID | B2: Descrição | C2: Un. | D2: Quantitativo | E2: MO s/BDI | F2: EQ s/BDI | G2: Comb. s/BDI | H2: MAT s/BDI | I2: Total s/BDI | J2: MO c/BDI | K2: EQ c/BDI | L2: Comb. c/BDI | M2: MAT c/BDI | N2: Total c/BDI
A3: eap-3_1 | B3: Cerca arame liso (5 fios) com mourões de concreto, seção quadrada 10 x 10 cm (padrão VALEC) executada em solos compostos por material de 1ª e 2ª categoria | C3: M | D3: 77928.38 | E3: 246694.79 | F3: 23154.56 | G3: 6101.63 | H3: 0 | I3: 275950.99 | J3: 331793.4 | K3: 31141.84 | L3: 8206.42 | M3: 0 | N3: 371141.66
A4: eap-1_2 | B4: Supressão vegetal, destocamento e limpeza de árvores, arbustos, vegetação rasteira e entulhos com remoção para área de depósito - DMT até 350m | C4: M2 | D4: 2036512.4 | E4: 248379 | F4: 508996.19 | G4: 137287.11 | H4: 622683.39 | I4: 1517345.7 | J4: 334058.58 | K4: 684576.97 | L4: 184644.98 | M4: 747220.07 | N4: 1950500.6
A5: eap-1_1 | B5: Supressão vegetal com ou sem destocamento de vegetação com Ø =< 30cm, assim como remoção de arbustos, vegetação rasteira e limpeza para a área de depósito - DMT até 350m - ALTA | C5: M2 | D5: 383592.55 | E5: 248379 | F5: 508996.19 | G5: 137287.11 | H5: 117287.14 | I5: 1011949.4 | J5: 334058.58 | K5: 684576.97 | L5: 184644.98 | M5: 140744.57 | N5: 1344025.1
A6: eap-1_3 | B6: Corte com destocamento de árvores com Ø > 30cm e remoção para a área de depósito - DMT até 1000m | C6: UNIDADE | D6: 12240.2 | E6: 177472.83 | F6: 75778.56 | G6: 30508.29 | H6: 22848.37 | I6: 306608.04 | J6: 238692.96 | K6: 101918.75 | L6: 41032.27 | M6: 27418.05 | N6: 409062.04
A7: eap-2_1 | B7: Fornecimento e Instalação de Mata burro (padrão VALEC) | C7: UNIDADE | D7: 59 | E7: 220659.25 | F7: 184184 | G7: 22881.21 | H7: 0 | I7: 427724.46 | J7: 296776.76 | K7: 247719.19 | L7: 30774.2 | M7: 0 | N7: 575270.16
A8: eap-3_3 | B8: Cerca arame liso (5 fios) com mourão de eucalipto e mourão de madeira a cada 4,0 m e esticador a cada 50 m executada em solos compostos por material de 1ª e 2ª categoria | C8: M | D8: 16451.19 | E8: 246694.79 | F8: 23154.56 | G8: 6101.63 | H8: 0 | I8: 275950.99 | J8: 331793.4 | K8: 31141.84 | L8: 8206.42 | M8: 0 | N8: 371141.66
A9: eap-3_6 | B9: Remoção de cerca de mourão de madeira | C9: M | D9: 37143.75 | E9: 131997.14 | F9: 23154.56 | G9: 6101.63 | H9: 0 | I9: 161253.33 | J9: 177530.21 | K9: 31141.84 | L9: 8206.42 | M9: 0 | N9: 216878.47
A10: eap-5_1 | B10: Abertura de acesso para implantação de cerca | C10: M | D10: 57000 | E10: 246694.79 | F10: 23154.56 | G10: 6101.63 | H10: 0 | I10: 275950.99 | J10: 331793.4 | K10: 31141.84 | L10: 8206.42 | M10: 0 | N10: 371141.66
A11: eap-2_3 | B11: Fornecimento e Instalação de Porteira Metálica (padrão VALEC) | C11: UNIDADE | D11: 44 | E11: 110329.62 | F11: 0 | G11: 0 | H11: 0 | I11: 110329.62 | J11: 148388.38 | K11: 0 | L11: 0 | M11: 0 | N11: 148388.38
A12: eap-4_1 | B12: Implantação do eixo | C12: KM | D12: 57 | E12: 175935.43 | F12: 15787.2 | G12: 0 | H12: 0 | I12: 191722.63 | J12: 236625.23 | K12: 21233.07 | L12: 0 | M12: 0 | N12: 257858.31
A13: eap-3_5 | B13: Cerca arame liso (5 fios) com mourão de eucalipto e mourão de madeira a cada 4,0 m e esticador a cada 50 m executada em solos alagadas | C13: M | D13: 1827.91 | E13: 246694.79 | F13: 23154.56 | G13: 6101.63 | H13: 0 | I13: 275950.99 | J13: 331793.4 | K13: 31141.84 | L13: 8206.42 | M13: 0 | N13: 371141.66
A14: eap-3_2 | B14: Cerca arame liso (5 fios) com mourões de concreto, seção quadrada 10 x 10 cm (padrão VALEC) executada em solos alagáveis | C14: M | D14: 575 | E14: 246694.79 | F14: 23154.56 | G14: 6101.63 | H14: 0 | I14: 275950.99 | J14: 331793.4 | K14: 31141.84 | L14: 8206.42 | M14: 0 | N14: 371141.66
... A16: eap-3_4 | B16: Cerca arame liso (5 fios) com mourão de eucalipto e mourão de madeira a cada 2,5 m e esticador a cada 50 m executada em solos compostos por material de 1ª e 2ª categoria | C16: M | D16: 700 | E16: 246694.79 | F16: 23154.56 | G16: 6101.63 | H16: 0 | I16: 275950.99 | J16: 331793.4 | K16: 31141.84 | L16: 8206.42 | M16: 0 | N16: 371141.66
A18: TOTAL DIRETO | E18: =SUM(E3:E17) | F18: =SUM(F3:F17) | G18: =SUM(G3:G17) | H18: =SUM(H3:H17) | I18: =SUM(I3:I17) | J18: =SUM(J3:J17) | K18: =SUM(K3:K17) | L18: =SUM(L3:L17) | ... N18: =SUM(N3:N17)

Sheet INDIRETOS.DET
A1: INDIRETOS — CUSTOS INDIRETOS DETALHADOS
A2: Categoria | B2: Tipo | C2: Código/Função | D2: Descrição | E2: Qtd | F2: Custo Mensal (R$) | G2: Perm. (m) | H2: Custo Total (R$)
A3: ADM — Administracao de obra
A4: ADM | B4: CUSTO TOTAL | C4: — | D4: Administracao de obra | E4: 1 | F4: 0 | G4: 6 | H4: 11251273
A5: Subtotal ADM | H5: =SUM(H4:H4)
A6: TOP — Topografia
A7: TOP | B7: CUSTO TOTAL | C7: — | D7: Topografia | E7: 1 | F7: 0 | G7: 6 | H7: 1573664.6
A8: Subtotal TOP | H8: =SUM(H7:H7)
A9: LAB — Laboratorio de solos e materiais
A10: LAB | B10: CUSTO TOTAL | C10: — | D10: Laboratorio de solos e materiais | E10: 1 | F10: 0 | G10: 6 | H10: 0
A11: Subtotal LAB | H11: =SUM(H10:H10)
A12: QSMS — Qualidade, Saude, Seguranca e Meio Ambiente
A13: QSMS | B13: CUSTO TOTAL | C13: — | D13: Qualidade, Saude, Seguranca e Meio Ambiente | E13: 1 | F13: 0 | G13: 6 | H13: 1400240.1
A14: Subtotal QSMS | H14: =SUM(H13:H13)
A15: MOB — Mobilizacao e desmobilizacao
A16: MOB | B16: CUSTO TOTAL | C16: — | D16: Mobilizacao e desmobilizacao | E16: 1 | F16: 0 | G16: 6 | H16: 0
A17: Subtotal MOB | H17: =SUM(H16:H16)
A19: TOTAL INDIRETO | H19: =H5+H8+H11+H14+H17
A22: Distribuição Mensal de Indiretos
A23: Mês | B23: Despesa Indireta (R$)
A24: Dez/24 | B24: 2370863
A25: Jan/25 | B25: 2370863
A26: Fev/25 | B26: 2370863
A27: Mar/25 | B27: 2370863
A28: Abr/25 | B28: 2370863
A29: Mai/25 | B29: 2370863
A30: Jun/25 | B30: 0

Sheet INDIRETOS.RES
A1: INDIRETOS RESUMIDO — CATEGORIAS + INDICADORES
A2: Categoria | B2: Descrição | C2: Custo s/BDI (R$) | D2: BDI (%) | E2: Custo c/BDI (R$) | F2: % do Total
A3: ADM | B3: Administracao de obra | C3: 11251273 | D3: 22.37 | E3: 13768588 | F3: 79.09
A4: TOP | B4: Topografia | C4: 1573664.6 | D4: 22.37 | E4: 1925750 | F4: 11.06
A5: LAB | B5: Laboratorio de solos e materiais | C5: 0 | D5: 22.37 | E5: 0 | F5: 0
A6: QSMS | B6: Qualidade, Saude, Seguranca e Meio Ambiente | C6: 1400240.1 | D6: 22.37 | E6: 1713524.3 | F6: 9.84
A7: MOB | B7: Mobilizacao e desmobilizacao | C7: 0 | D7: 22.37 | E7: 0 | F7: 0
A9: TOTAL INDIRETO | C9: =C3+C4+C5+C6+C7 | E9: =E3+E4+E5+E6+E7
A12: INDICADORES DE COMPOSIÇÃO DE CUSTO
A13: TOTAL DIRETO (catálogo s/BDI) | C13: 5492968.8
A14: TOTAL INDIRETO s/BDI | C14: 14225178
A15: RAZÃO CI / CD | C15: 258.97
A16: PREÇO DE VENDA TOTAL | C16: 7277221.4
A17: CI / PVT | C17: 195.48

Sheet PLANEJAMENTO
A1: PLANEJAMENTO — ORÇAMENTO POR EAP (COMPONENTES s/BDI e c/BDI)
A2: Item ID | B2: Descrição | C2: Un. | D2: Quantitativo | E2: MO s/BDI (R$) | F2: EQ s/BDI (R$) | G2: Comb. s/BDI (R$) | H2: MAT s/BDI (R$) | I2: Total s/BDI (R$) | J2: MO c/BDI (R$) | K2: EQ c/BDI (R$) | L2: Comb. c/BDI (R$) | M2: MAT c/BDI (R$) | N2: Total c/BDI (R$) | O2: Criticidade
A3: eap-3_1 | B3: Cerca arame liso (5 fios) com mourões de concreto, seção quadrada 10 x 10 cm (padrão VALEC) executada em solos compostos por material de 1ª e 2ª categoria | C3: M | D3: 77928.38 | E3: 246694.79 | F3: 23154.56 | G3: 6101.63 | H3: 0 | I3: 275950.99 | J3: 331793.4 | K3: 31141.84 | L3: 8206.42 | M3: 0 | N3: 371141.66 | O3: B
A4: eap-1_2 | B4: Supressão vegetal, destocamento e limpeza de árvores, arbustos, vegetação rasteira e entulhos com remoção para área de depósito - DMT até 350m | C4: M2 | D4: 2036512.4 | E4: 248379 | F4: 508996.19 | G4: 137287.11 | H4: 622683.39 | I4: 1517345.7 | J4: 334058.58 | K4: 684576.97 | L4: 184644.98 | M4: 747220.07 | N4: 1950500.6 | O4: A
A5: eap-1_1 | B5: Supressão vegetal com ou sem destocamento de vegetação com Ø =< 30cm, assim como remoção de arbustos, vegetação rasteira e limpeza para a área de depósito - DMT até 350m - ALTA | C5: M2 | D5: 383592.55 | E5: 248379 | F5: 508996.19 | G5: 137287.11 | H5: 117287.14 | I5: 1011949.4 | J5: 334058.58 | K5: 684576.97 | L5: 184644.98 | M5: 140744.57 | N5: 1344025.1 | O5: A
A6: eap-1_3 | B6: Corte com destocamento de árvores com Ø > 30cm e remoção para a área de depósito - DMT até 1000m | C6: UNIDADE | D6: 12240.2 | E6: 177472.83 | F6: 75778.56 | G6: 30508.29 | H6: 22848.37 | I6: 306608.04 | J6: 238692.96 | K6: 101918.75 | L6: 41032.27 | M6: 27418.05 | N6: 409062.04 | O6: B
A7: eap-2_1 | B7: Fornecimento e Instalação de Mata burro (padrão VALEC) | C7: UNIDADE | D7: 59 | E7: 220659.25 | F7: 184184 | G7: 22881.21 | H7: 0 | I7: 427724.46 | J7: 296776.76 | K7: 247719.19 | L7: 30774.2 | M7: 0 | N7: 575270.16 | O7: A
A8: eap-3_3 | B8: Cerca arame liso (5 fios) com mourão de eucalipto e mourão de madeira a cada 4,0 m e esticador a cada 50 m executada em solos compostos por material de 1ª e 2ª categoria | C8: M | D8: 16451.19 | E8: 246694.79 | F8: 23154.56 | G8: 6101.63 | H8: 0 | I8: 275950.99 | J8: 331793.4 | K8: 31141.84 | L8: 8206.42 | M8: 0 | N8: 371141.66 | O8: C
A9: eap-3_6 | B9: Remoção de cerca de mourão de madeira | C9: M | D9: 37143.75 | E9: 131997.14 | F9: 23154.56 | G9: 6101.63 | H9: 0 | I9: 161253.33 | J9: 177530.21 | K9: 31141.84 | L9: 8206.42 | M9: 0 | N9: 216878.47 | O9: C
A10: eap-5_1 | B10: Abertura de acesso para implantação de cerca | C10: M | D10: 57000 | E10: 246694.79 | F10: 23154.56 | G10: 6101.63 | H10: 0 | I10: 275950.99 | J10: 331793.4 | K10: 31141.84 | L10: 8206.42 | M10: 0 | N10: 371141.66 | O10: B
A11: eap-2_3 | B11: Fornecimento e Instalação de Porteira Metálica (padrão VALEC) | C11: UNIDADE | D11: 44 | E11: 110329.62 | F11: 0 | G11: 0 | H11: 0 | I11: 110329.62 | J11: 148388.38 | K11: 0 | L11: 0 | M11: 0 | N11: 148388.38 | O11: C
A12: eap-4_1 | B12: Implantação do eixo | C12: KM | D12: 57 | E12: 175935.43 | F12: 15787.2 | G12: 0 | H12: 0 | I12: 191722.63 | J12: 236625.23 | K12: 21233.07 | L12: 0 | M12: 0 | N12: 257858.31 | O12: C
A13: eap-3_5 | B13: Cerca arame liso (5 fios) com mourão de eucalipto e mourão de madeira a cada 4,0 m e esticador a cada 50 m executada em solos alagadas | C13: M | D13: 1827.91 | E13: 246694.79 | F13: 23154.56 | G13: 6101.63 | H13: 0 | I13: 275950.99 | J13: 331793.4 | K13: 31141.84 | L13: 8206.42 | M13: 0 | N13: 371141.66 | O13: C
A14: eap-3_2 | B14: Cerca arame liso (5 fios) com mourões de concreto, seção quadrada 10 x 10 cm (padrão VALEC) executada em solos alagáveis | C14: M | D14: 575 | E14: 246694.79 | F14: 23154.56 | G14: 6101.63 | H14: 0 | I14: 275950.99 | J14: 331793.4 | K14: 31141.84 | L14: 8206.42 | M14: 0 | N14: 371141.66 | O14: C
... A16: eap-3_4 | B16: Cerca arame liso (5 fios) com mourão de eucalipto e mourão de madeira a cada 2,5 m e esticador a cada 50 m executada em solos compostos por material de 1ª e 2ª categoria | C16: M | D16: 700 | E16: 246694.79 | F16: 23154.56 | G16: 6101.63 | H16: 0 | I16: 275950.99 | J16: 331793.4 | K16: 31141.84 | L16: 8206.42 | M16: 0 | N16: 371141.66 | O16: C
A18: TOTAL | E18: =SUM(E3:E17) | F18: =SUM(F3:F17) | G18: =SUM(G3:G17) | H18: =SUM(H3:H17) | I18: =SUM(I3:I17) | J18: =SUM(J3:J17) | K18: =SUM(K3:K17) | L18: =SUM(L3:L17) | ... O18: =SUM(O3:O17)

Sheet CRONOGRAMA.DET
A1: CRONOGRAMA SEMANAL — ACOMPANHAMENTO FÍSICO DE PRODUÇÃO
A2: Item ID | B2: Descrição | C2: Un. | D2: Métrica | E2: 30/Dez | F2: 06/Jan | G2: 13/Jan | H2: 20/Jan | I2: 27/Jan | J2: 03/Fev | K2: 10/Fev | L2: 17/Fev | M2: 24/Fev | N2: 03/Mar | O2: 10/Mar | P2: 17/Mar | Q2: 24/Mar | R2: 31/Mar | S2: 07/Abr | T2: 14/Abr | U2: 21/Abr | V2: 28/Abr | W2: 05/Mai | X2: 12/Mai | Y2: 19/Mai | Z2: 26/Mai | AA2: 02/Jun | AB2: 09/Jun | AC2: 16/Jun | AD2: 23/Jun | AE2: 30/Jun
D3: Praticabilidade | E3: 0.8571 | F3: 1 | G3: 0.8571 | H3: 0.7143 | I3: 0.8571 | J3: 0.7143 | K3: 0.8571 | L3: 0.5714 | M3: 0.7143 | N3: 0.5714 | O3: 0.8571 | P3: 0.5714 | Q3: 0.5714 | R3: 0.8571 | S3: 1 | T3: 0.8571 | U3: 0.8571 | V3: 0.8571 | W3: 0.8571 | X3: 1 | Y3: 0.7143 | Z3: 1 | AA3: 1 | AB3: 1 | AC3: 1 | AD3: 1 | AE3: 1
A4: eap-3_1 | B4: Cerca arame liso (5 fios) com mourões de concreto, seção quadrada 10 x 10 cm (padrão VALEC) executada em solos compostos por material de 1ª e 2ª categoria | C4: M | D4: Dias Trabalhados | E4: 6 | F4: 6 | G4: 6 | H4: 6 | I4: 6 | J4: 6 | K4: 6 | L4: 6 | M4: 6 | N4: 6 | O4: 6 | P4: 6 | Q4: 6 | R4: 6 | S4: 6 | T4: 6 | U4: 6 | V4: 6 | W4: 6 | X4: 6 | Y4: 6 | Z4: 6 | AA4: 6 | AB4: 6 | AC4: 6 | AD4: 6
D5: Nº De Equipes | E5: 2 | F5: 2 | G5: 2 | H5: 2 | I5: 2 | J5: 2 | K5: 2 | L5: 2 | M5: 2 | N5: 2 | O5: 2 | P5: 2 | Q5: 2 | R5: 2 | S5: 2 | T5: 2 | U5: 2 | V5: 2 | W5: 2 | X5: 2 | Y5: 2 | Z5: 2 | AA5: 2 | AB5: 2 | AC5: 2 | AD5: 2
D6: Qtd. Planejada | E6: 4114.08 | F6: 4800 | G6: 4114.08 | H6: 3428.64 | I6: 4114.08 | J6: 3428.64 | K6: 4114.08 | L6: 2742.72 | M6: 3428.64 | N6: 2742.72 | O6: 4114.08 | P6: 2742.72 | Q6: 2742.72 | R6: 4114.08 | S6: 4800 | T6: 4114.08 | U6: 4114.08 | V6: 4114.08 | W6: 4114.08 | X6: 4800 | Y6: 1130.78
D7: Qtd Plan. Acumulada | E7: 4114.08 | F7: 8914.08 | G7: 13028.16 | H7: 16456.8 | I7: 20570.88 | J7: 23999.52 | K7: 28113.6 | L7: 30856.32 | M7: 34284.96 | N7: 37027.68 | O7: 41141.76 | P7: 43884.48 | Q7: 46627.2 | R7: 50741.28 | S7: 55541.28 | T7: 59655.36 | U7: 63769.44 | V7: 67883.52 | W7: 71997.6 | X7: 76797.6 | Y7: 77928.38 | Z7: 77928.38 | AA7: 77928.38 | AB7: 77928.38 | AC7: 77928.38 | AD7: 77928.38 | AE7: 77928.38
D8: Eficiência | E8: 0.8571 | F8: 1 | G8: 0.8571 | H8: 0.7143 | I8: 0.8571 | J8: 0.7143 | K8: 0.8571 | L8: 0.5714 | M8: 0.7143 | N8: 0.5714 | O8: 0.8571 | P8: 0.5714 | Q8: 0.5714 | R8: 0.8571 | S8: 1 | T8: 0.8571 | U8: 0.8571 | V8: 0.8571 | W8: 0.8571 | X8: 1 | Y8: 0.7143 | Z8: 1 | AA8: 1 | AB8: 1 | AC8: 1 | AD8: 1
A9: eap-1_2 | B9: Supressão vegetal, destocamento e limpeza de árvores, arbustos, vegetação rasteira e entulhos com remoção para área de depósito - DMT até 350m | C9: M2 | D9: Dias Trabalhados | E9: 6 | F9: 6 | G9: 6 | H9: 6 | I9: 6 | J9: 6 | K9: 6 | L9: 6 | M9: 6 | N9: 6 | O9: 6 | P9: 6 | Q9: 6 | R9: 6 | S9: 6 | T9: 6 | U9: 6 | V9: 6 | W9: 6 | X9: 6 | Y9: 6 | Z9: 6 | AA9: 6 | AB9: 6 | AC9: 6 | AD9: 6
D10: Nº De Equipes | E10: 6 | F10: 6 | G10: 6 | H10: 6 | I10: 6 | J10: 6 | K10: 6 | L10: 6 | M10: 6 | N10: 6 | O10: 6 | P10: 6 | Q10: 6 | R10: 6 | S10: 6 | T10: 6 | U10: 6 | V10: 6 | W10: 6 | X10: 6 | Y10: 6 | Z10: 6 | AA10: 6 | AB10: 6 | AC10: 6 | AD10: 6
D11: Qtd. Planejada | E11: 86395.68 | F11: 100800 | G11: 86395.68 | H11: 72001.44 | I11: 86395.68 | J11: 72001.44 | K11: 86395.68 | L11: 57597.12 | M11: 72001.44 | N11: 57597.12 | O11: 86395.68 | P11: 57597.12 | Q11: 57597.12 | R11: 86395.68 | S11: 100800 | T11: 86395.68 | U11: 86395.68 | V11: 86395.68 | W11: 86395.68 | X11: 100800 | Y11: 72001.44 | Z11: 100800 | AA11: 100800 | AB11: 100800 | AC11: 49361.31
D12: Qtd Plan. Acumulada | E12: 86395.68 | F12: 187195.68 | G12: 273591.36 | H12: 345592.8 | I12: 431988.48 | J12: 503989.92 | K12: 590385.6 | L12: 647982.72 | M12: 719984.16 | N12: 777581.28 | O12: 863976.96 | P12: 921574.08 | Q12: 979171.2 | R12: 1065566.9 | S12: 1166366.9 | T12: 1252762.6 | U12: 1339158.2 | V12: 1425553.9 | W12: 1511949.6 | X12: 1612749.6 | Y12: 1684751 | Z12: 1785551 | AA12: 1886351 | AB12: 1987151 | AC12: 2036512.4 | AD12: 2036512.4 | AE12: 2036512.4
D13: Eficiência | E13: 0.8571 | F13: 1 | G13: 0.8571 | H13: 0.7143 | I13: 0.8571 | J13: 0.7143 | K13: 0.8571 | L13: 0.5714 | M13: 0.7143 | N13: 0.5714 | O13: 0.8571 | P13: 0.5714 | Q13: 0.5714 | R13: 0.8571 | S13: 1 | T13: 0.8571 | U13: 0.8571 | V13: 0.8571 | W13: 0.8571 | X13: 1 | Y13: 0.7143 | Z13: 1 | AA13: 1 | AB13: 1 | AC13: 1 | AD13: 1
A14: eap-1_1 | B14: Supressão vegetal com ou sem destocamento de vegetação com Ø =< 30cm, assim como remoção de arbustos, vegetação rasteira e limpeza para a área de depósito - DMT até 350m - ALTA | C14: M2 | D14: Dias Trabalhados | E14: 6 | F14: 6 | G14: 6 | H14: 6 | I14: 6 | J14: 6 | K14: 6 | L14: 6 | M14: 6 | N14: 6 | O14: 6 | P14: 6 | Q14: 6 | R14: 6 | S14: 6 | T14: 6 | U14: 6 | V14: 6 | W14: 6 | X14: 6 | Y14: 6 | Z14: 6 | AA14: 6 | AB14: 6 | AC14: 6 | AD14: 6
D15: Nº De Equipes | E15: 2 | F15: 2 | G15: 2 | H15: 2 | I15: 2 | J15: 2 | K15: 2 | L15: 2 | M15: 2 | N15: 2 | O15: 2 | P15: 2 | Q15: 2 | R15: 2 | S15: 2 | T15: 2 | U15: 2 | V15: 2 | W15: 2 | X15: 2 | Y15: 2 | Z15: 2 | AA15: 2 | AB15: 2 | AC15: 2 | AD15: 2
D16: Qtd. Planejada | E16: 28798.56 | F16: 33600 | G16: 28798.56 | H16: 24000.48 | I16: 28798.56 | J16: 24000.48 | K16: 28798.56 | L16: 19199.04 | M16: 24000.48 | N16: 19199.04 | O16: 28798.56 | P16: 19199.04 | Q16: 19199.04 | R16: 28798.56 | S16: 28403.59
D17: Qtd Plan. Acumulada | E17: 28798.56 | F17: 62398.56 | G17: 91197.12 | H17: 115197.6 | I17: 143996.16 | J17: 167996.64 | K17: 196795.2 | L17: 215994.24 | M17: 239994.72 | N17: 259193.76 | O17: 287992.32 | P17: 307191.36 | Q17: 326390.4 | R17: 355188.96 | S17: 383592.55 | T17: 383592.55 | U17: 383592.55 | V17: 383592.55 | W17: 383592.55 | X17: 383592.55 | Y17: 383592.55 | Z17: 383592.55 | AA17: 383592.55 | AB17: 383592.55 | AC17: 383592.55 | AD17: 383592.55 | AE17: 383592.55
D18: Eficiência | E18: 0.8571 | F18: 1 | G18: 0.8571 | H18: 0.7143 | I18: 0.8571 | J18: 0.7143 | K18: 0.8571 | L18: 0.5714 | M18: 0.7143 | N18: 0.5714 | O18: 0.8571 | P18: 0.5714 | Q18: 0.5714 | R18: 0.8571 | S18: 1 | T18: 0.8571 | U18: 0.8571 | V18: 0.8571 | W18: 0.8571 | X18: 1 | Y18: 0.7143 | Z18: 1 | AA18: 1 | AB18: 1 | AC18: 1 | AD18: 1
A19: eap-1_3 | B19: Corte com destocamento de árvores com Ø > 30cm e remoção para a área de depósito - DMT até 1000m | C19: UNIDADE | D19: Dias Trabalhados | E19: 6 | F19: 6 | G19: 6 | H19: 6 | I19: 6 | J19: 6 | K19: 6 | L19: 6 | M19: 6 | N19: 6 | O19: 6 | P19: 6 | Q19: 6 | R19: 6 | S19: 6 | T19: 6 | U19: 6 | V19: 6 | W19: 6 | X19: 6 | Y19: 6 | Z19: 6 | AA19: 6 | AB19: 6 | AC19: 6 | AD19: 6
D20: Nº De Equipes | E20: 3 | F20: 3 | G20: 3 | H20: 3 | I20: 3 | J20: 3 | K20: 3 | L20: 3 | M20: 3 | N20: 3 | O20: 3 | P20: 3 | Q20: 3 | R20: 3 | S20: 3 | T20: 3 | U20: 3 | V20: 3 | W20: 3 | X20: 3 | Y20: 3 | Z20: 3 | AA20: 3 | AB20: 3 | AC20: 3 | AD20: 3
D21: Qtd. Planejada | E21: 740.53 | F21: 864 | G21: 740.53 | H21: 617.16 | I21: 740.53 | J21: 617.16 | K21: 740.53 | L21: 493.69 | M21: 617.16 | N21: 493.69 | O21: 740.53 | P21: 493.69 | Q21: 493.69 | R21: 740.53 | S21: 864 | T21: 740.53 | U21: 740.53 | V21: 740.53 | W21: 21.17
D22: Qtd Plan. Acumulada | E22: 740.53 | F22: 1604.53 | G22: 2345.07 | H22: 2962.22 | I22: 3702.76 | J22: 4319.91 | K22: 5060.45 | L22: 5554.14 | M22: 6171.29 | N22: 6664.98 | O22: 7405.52 | P22: 7899.21 | Q22: 8392.9 | R22: 9133.43 | S22: 9997.43 | T22: 10737.96 | U22: 11478.5 | V22: 12219.03 | W22: 12240.2 | X22: 12240.2 | Y22: 12240.2 | Z22: 12240.2 | AA22: 12240.2 | AB22: 12240.2 | AC22: 12240.2 | AD22: 12240.2 | AE22: 12240.2
D23: Eficiência | E23: 0.8571 | F23: 1 | G23: 0.8571 | H23: 0.7143 | I23: 0.8571 | J23: 0.7143 | K23: 0.8571 | L23: 0.5714 | M23: 0.7143 | N23: 0.5714 | O23: 0.8571 | P23: 0.5714 | Q23: 0.5714 | R23: 0.8571 | S23: 1 | T23: 0.8571 | U23: 0.8571 | V23: 0.8571 | W23: 0.8571 | X23: 1 | Y23: 0.7143 | Z23: 1 | AA23: 1 | AB23: 1 | AC23: 1 | AD23: 1
A24: eap-2_1 | B24: Fornecimento e Instalação de Mata burro (padrão VALEC) | C24: UNIDADE | D24: Dias Trabalhados | E24: 6 | F24: 6 | G24: 6 | H24: 6 | I24: 6 | J24: 6 | K24: 6 | L24: 6 | M24: 6 | N24: 6 | O24: 6 | P24: 6 | Q24: 6 | R24: 6 | S24: 6 | T24: 6 | U24: 6 | V24: 6 | W24: 6 | X24: 6 | Y24: 6 | Z24: 6 | AA24: 6 | AB24: 6 | AC24: 6 | AD24: 6
D25: Nº De Equipes | E25: 2 | F25: 2 | G25: 2 | H25: 2 | I25: 2 | J25: 2 | K25: 2 | L25: 2 | M25: 2 | N25: 2 | O25: 2 | P25: 2 | Q25: 2 | R25: 2 | S25: 2 | T25: 2 | U25: 2 | V25: 2 | W25: 2 | X25: 2 | Y25: 2 | Z25: 2 | AA25: 2 | AB25: 2 | AC25: 2 | AD25: 2
D26: Qtd. Planejada | E26: 4.11 | F26: 4.8 | G26: 4.11 | H26: 3.43 | I26: 4.11 | J26: 3.43 | K26: 4.11 | L26: 2.74 | M26: 3.43 | N26: 2.74 | O26: 4.11 | P26: 2.74 | Q26: 2.74 | R26: 4.11 | S26: 4.8 | T26: 3.46
D27: Qtd Plan. Acumulada | E27: 4.11 | F27: 8.91 | G27: 13.03 | H27: 16.46 | I27: 20.57 | J27: 24 | K27: 28.11 | L27: 30.86 | M27: 34.28 | N27: 37.03 | O27: 41.14 | P27: 43.88 | Q27: 46.63 | R27: 50.74 | S27: 55.54 | T27: 59 | U27: 59 | V27: 59 | W27: 59 | X27: 59 | Y27: 59 | Z27: 59 | AA27: 59 | AB27: 59 | AC27: 59 | AD27: 59 | AE27: 59
D28: Eficiência | E28: 0.8571 | F28: 1 | G28: 0.8571 | H28: 0.7143 | I28: 0.8571 | J28: 0.7143 | K28: 0.8571 | L28: 0.5714 | M28: 0.7143 | N28: 0.5714 | O28: 0.8571 | P28: 0.5714 | Q28: 0.5714 | R28: 0.8571 | S28: 1 | T28: 0.8571 | U28: 0.8571 | V28: 0.8571 | W28: 0.8571 | X28: 1 | Y28: 0.7143 | Z28: 1 | AA28: 1 | AB28: 1 | AC28: 1 | AD28: 1
A29: eap-3_3 | B29: Cerca arame liso (5 fios) com mourão de eucalipto e mourão de madeira a cada 4,0 m e esticador a cada 50 m executada em solos compostos por material de 1ª e 2ª categoria | C29: M | D29: Dias Trabalhados | E29: 6 | F29: 6 | G29: 6 | H29: 6 | I29: 6 | J29: 6 | K29: 6 | L29: 6 | M29: 6 | N29: 6 | O29: 6 | P29: 6 | Q29: 6 | R29: 6 | S29: 6 | T29: 6 | U29: 6 | V29: 6 | W29: 6 | X29: 6 | Y29: 6 | Z29: 6 | AA29: 6 | AB29: 6 | AC29: 6 | AD29: 6
D30: Nº De Equipes | E30: 1 | F30: 1 | G30: 1 | H30: 1 | I30: 1 | J30: 1 | K30: 1 | L30: 1 | M30: 1 | N30: 1 | O30: 1 | P30: 1 | Q30: 1 | R30: 1 | S30: 1 | T30: 1 | U30: 1 | V30: 1 | W30: 1 | X30: 1 | Y30: 1 | Z30: 1 | AA30: 1 | AB30: 1 | AC30: 1 | AD30: 1
D31: Qtd. Planejada | E31: 1542.78 | F31: 1800 | G31: 1542.78 | H31: 1285.74 | I31: 1542.78 | J31: 1285.74 | K31: 1542.78 | L31: 1028.52 | M31: 1285.74 | N31: 1028.52 | O31: 1542.78 | P31: 1023.03
D32: Qtd Plan. Acumulada | E32: 1542.78 | F32: 3342.78 | G32: 4885.56 | H32: 6171.3 | I32: 7714.08 | J32: 8999.82 | K32: 10542.6 | L32: 11571.12 | M32: 12856.86 | N32: 13885.38 | O32: 15428.16 | P32: 16451.19 | Q32: 16451.19 | R32: 16451.19 | S32: 16451.19 | T32: 16451.19 | U32: 16451.19 | V32: 16451.19 | W32: 16451.19 | X32: 16451.19 | Y32: 16451.19 | Z32: 16451.19 | AA32: 16451.19 | AB32: 16451.19 | AC32: 16451.19 | AD32: 16451.19 | AE32: 16451.19
D33: Eficiência | E33: 0.8571 | F33: 1 | G33: 0.8571 | H33: 0.7143 | I33: 0.8571 | J33: 0.7143 | K33: 0.8571 | L33: 0.5714 | M33: 0.7143 | N33: 0.5714 | O33: 0.8571 | P33: 0.5714 | Q33: 0.5714 | R33: 0.8571 | S33: 1 | T33: 0.8571 | U33: 0.8571 | V33: 0.8571 | W33: 0.8571 | X33: 1 | Y33: 0.7143 | Z33: 1 | AA33: 1 | AB33: 1 | AC33: 1 | AD33: 1
A34: eap-3_6 | B34: Remoção de cerca de mourão de madeira | C34: M | D34: Dias Trabalhados | E34: 6 | F34: 6 | G34: 6 | H34: 6 | I34: 6 | J34: 6 | K34: 6 | L34: 6 | M34: 6 | N34: 6 | O34: 6 | P34: 6 | Q34: 6 | R34: 6 | S34: 6 | T34: 6 | U34: 6 | V34: 6 | W34: 6 | X34: 6 | Y34: 6 | Z34: 6 | AA34: 6 | AB34: 6 | AC34: 6 | AD34: 6
D35: Nº De Equipes | E35: 1 | F35: 1 | G35: 1 | H35: 1 | I35: 1 | J35: 1 | K35: 1 | L35: 1 | M35: 1 | N35: 1 | O35: 1 | P35: 1 | Q35: 1 | R35: 1 | S35: 1 | T35: 1 | U35: 1 | V35: 1 | W35: 1 | X35: 1 | Y35: 1 | Z35: 1 | AA35: 1 | AB35: 1 | AC35: 1 | AD35: 1
D36: Qtd. Planejada | E36: 1763.29 | F36: 2057.28 | G36: 1763.29 | H36: 1469.52 | I36: 1763.29 | J36: 1469.52 | K36: 1763.29 | L36: 1175.53 | M36: 1469.52 | N36: 1175.53 | O36: 1763.29 | P36: 1175.53 | Q36: 1175.53 | R36: 1763.29 | S36: 2057.28 | T36: 1763.29 | U36: 1763.29 | V36: 1763.29 | W36: 1763.29 | X36: 2057.28 | Y36: 1469.52 | Z36: 2057.28 | AA36: 701.5
D37: Qtd Plan. Acumulada | E37: 1763.29 | F37: 3820.57 | G37: 5583.87 | H37: 7053.38 | I37: 8816.68 | J37: 10286.19 | K37: 12049.49 | L37: 13225.02 | M37: 14694.53 | N37: 15870.06 | O37: 17633.36 | P37: 18808.89 | Q37: 19984.42 | R37: 21747.71 | S37: 23804.99 | T37: 25568.29 | U37: 27331.58 | V37: 29094.88 | W37: 30858.17 | X37: 32915.45 | Y37: 34384.97 | Z37: 36442.25 | AA37: 37143.75 | AB37: 37143.75 | AC37: 37143.75 | AD37: 37143.75 | AE37: 37143.75
D38: Eficiência | E38: 0.8571 | F38: 1 | G38: 0.8571 | H38: 0.7143 | I38: 0.8571 | J38: 0.7143 | K38: 0.8571 | L38: 0.5714 | M38: 0.7143 | N38: 0.5714 | O38: 0.8571 | P38: 0.5714 | Q38: 0.5714 | R38: 0.8571 | S38: 1 | T38: 0.8571 | U38: 0.8571 | V38: 0.8571 | W38: 0.8571 | X38: 1 | Y38: 0.7143 | Z38: 1 | AA38: 1 | AB38: 1 | AC38: 1 | AD38: 1
A39: eap-5_1 | B39: Abertura de acesso para implantação de cerca | C39: M | D39: Dias Trabalhados | E39: 6 | F39: 6 | G39: 6 | H39: 6 | I39: 6 | J39: 6 | K39: 6 | L39: 6 | M39: 6 | N39: 6 | O39: 6 | P39: 6 | Q39: 6 | R39: 6 | S39: 6 | T39: 6 | U39: 6 | V39: 6 | W39: 6 | X39: 6 | Y39: 6 | Z39: 6 | AA39: 6 | AB39: 6 | AC39: 6 | AD39: 6
D40: Nº De Equipes | E40: 2 | F40: 2 | G40: 2 | H40: 2 | I40: 2 | J40: 2 | K40: 2 | L40: 2 | M40: 2 | N40: 2 | O40: 2 | P40: 2 | Q40: 2 | R40: 2 | S40: 2 | T40: 2 | U40: 2 | V40: 2 | W40: 2 | X40: 2 | Y40: 2 | Z40: 2 | AA40: 2 | AB40: 2 | AC40: 2 | AD40: 2
...

Sheet CRONOGRAMA.RES
A1: CRONOGRAMA RESUMIDO — PRODUÇÃO MENSAL POR EAP
A2: Item ID | B2: Descrição | C2: Un. | D2: Total Qtd | E2: Dez/24 | F2: Jan/25 | G2: Fev/25 | H2: Mar/25 | I2: Abr/25 | J2: Mai/25 | K2: Jun/25
A3: eap-3_1 | B3: Cerca arame liso (5 fios) com mourões de concreto, seção quadrada 10 x 10 cm (padrão VALEC) executada em solos compostos por material de 1ª e 2ª categoria | C3: M | D3: 77928.38 | E3: 4114.08 | F3: 16456.8 | G3: 13714.08 | H3: 16456.32 | I3: 17142.24 | J3: 10044.86
A4: eap-1_2 | B4: Supressão vegetal, destocamento e limpeza de árvores, arbustos, vegetação rasteira e entulhos com remoção para área de depósito - DMT até 350m | C4: M2 | D4: 2036512.4 | E4: 86395.68 | F4: 345592.8 | G4: 287995.68 | H4: 345582.72 | I4: 359987.04 | J4: 359997.12 | K4: 250961.31
A5: eap-1_1 | B5: Supressão vegetal com ou sem destocamento de vegetação com Ø =< 30cm, assim como remoção de arbustos, vegetação rasteira e limpeza para a área de depósito - DMT até 350m - ALTA | C5: M2 | D5: 383592.55 | E5: 28798.56 | F5: 115197.6 | G5: 95998.56 | H5: 115194.24 | I5: 28403.59
A6: eap-1_3 | B6: Corte com destocamento de árvores com Ø > 30cm e remoção para a área de depósito - DMT até 1000m | C6: UNIDADE | D6: 12240.2 | E6: 740.53 | F6: 2962.22 | G6: 2468.54 | H6: 2962.13 | I6: 3085.59 | J6: 21.17
A7: eap-2_1 | B7: Fornecimento e Instalação de Mata burro (padrão VALEC) | C7: UNIDADE | D7: 59 | E7: 4.11 | F7: 16.45 | G7: 13.71 | H7: 16.44 | I7: 8.26
A8: eap-3_3 | B8: Cerca arame liso (5 fios) com mourão de eucalipto e mourão de madeira a cada 4,0 m e esticador a cada 50 m executada em solos compostos por material de 1ª e 2ª categoria | C8: M | D8: 16451.19 | E8: 1542.78 | F8: 6171.3 | G8: 5142.78 | H8: 3594.33
A9: eap-3_6 | B9: Remoção de cerca de mourão de madeira | C9: M | D9: 37143.75 | E9: 1763.29 | F9: 7053.38 | G9: 5877.86 | H9: 7053.17 | I9: 7347.15 | J9: 7347.37 | K9: 701.5
A10: eap-5_1 | B10: Abertura de acesso para implantação de cerca | C10: M | D10: 57000 | E10: 3085.56 | F10: 12342.6 | G10: 10285.56 | H10: 12342.24 | I10: 12856.68 | J10: 6087.36
A11: eap-2_3 | B11: Fornecimento e Instalação de Porteira Metálica (padrão VALEC) | C11: UNIDADE | D11: 44 | E11: 5.14 | F11: 20.57 | G11: 17.15 | H11: 1.14
A12: eap-4_1 | B12: Implantação do eixo | C12: KM | D12: 57 | E12: 5.76 | F12: 23.04 | G12: 19.2 | H12: 9
A13: eap-3_5 | B13: Cerca arame liso (5 fios) com mourão de eucalipto e mourão de madeira a cada 4,0 m e esticador a cada 50 m executada em solos alagadas | C13: M | D13: 1827.91 | E13: 1542.78 | F13: 285.13
A14: eap-3_2 | B14: Cerca arame liso (5 fios) com mourões de concreto, seção quadrada 10 x 10 cm (padrão VALEC) executada em solos alagáveis | C14: M | D14: 575 | E14: 575
A15: eap-2_2 | B15: Fornecimento e Instalação de Porteira de Madeira (padrão VALEC) | C15: UNIDADE | D15: 19 | E15: 5.14 | F15: 13.85
A16: eap-3_4 | B16: Cerca arame liso (5 fios) com mourão de eucalipto e mourão de madeira a cada 2,5 m e esticador a cada 50 m executada em solos compostos por material de 1ª e 2ª categoria | C16: M | D16: 700 | E16: 700

Sheet EQUIPE
A1: EQUIPE — COMPOSIÇÃO DE RECURSOS DIRETOS POR ATIVIDADE
A2: Item ID | B2: CPU ID | C2: Nome / Tipo | D2: Papel | E2: Qtd | F2: Custo Mensal (R$) | G2: Perm. (m) | H2: Nº Eq. | I2: Custo Total (R$)
A3: eap-3_1 — Cerca arame liso (5 fios) com mourões de concreto, seção quadrada 10 x 10 cm (padrão VALEC) executada em solos compostos por material de 1ª e 2ª categoria
A4: eap-3_1 | B4: CPU-DIVER-ATI-066 | C4: Encarregado de Terraplenagem | D4: DIRETO | E4: 1 | F4: 11549.8 | G4: 5.98 | H4: 1 | I4: 69067.8
A5: eap-3_1 | B5: CPU-DIVER-ATI-066 | C5: Cerqueiro | D5: DIRETO | E5: 3 | F5: 29703.51 | G5: 5.98 | H5: 1 | I5: 177626.99
A6: eap-3_1 | B6: EQ-E0001 | C6: Automóvel (veículo leve) [EQ] | D6: EQ | E6: 1 | F6: 3872 | G6: 5.98 | H6: 1 | I6: 23154.56
A7: eap-3_1 | B7: EQ-E0001 | C7: Diesel — Automóvel (veículo leve) | D7: COMB | E7: 1 | F7: 1020.34 | G7: 5.98 | H7: 1 | I7: 6101.63
A8: Subtotal eap-3_1 | I8: 551879.9
A9: eap-1_2 — Supressão vegetal, destocamento e limpeza de árvores, arbustos, vegetação rasteira e entulhos com remoção para área de depósito - DMT até 350m
A10: eap-1_2 | B10: CPU-TERRA-ATI-003 | C10: Operador de Escavadeira | D10: DIRETO | E10: 1 | F10: 12875 | G10: 5.98 | H10: 1 | I10: 76992.5
A11: eap-1_2 | B11: CPU-TERRA-ATI-003 | C11: Operador de Trator de Esteiras | D11: DIRETO | E11: 1 | F11: 12875 | G11: 5.98 | H11: 1 | I11: 76992.5
A12: eap-1_2 | B12: CPU-TERRA-ATI-003 | C12: Ajudante | D12: DIRETO | E12: 3 | F12: 15784.95 | G12: 5.98 | H12: 1 | I12: 94394
A13: eap-1_2 | B13: EQ-E0016 | C13: Escavadeira Hidráulica 22t [EQ] | D13: EQ | E13: 1 | F13: 35639.3 | G13: 5.98 | H13: 1 | I13: 213123.01
A14: eap-1_2 | B14: EQ-E0024 | C14: Trator de Esteiras 20t (300HP) [EQ] | D14: EQ | E14: 1 | F14: 49477.12 | G14: 5.98 | H14: 1 | I14: 295873.18
A15: eap-1_2 | B15: EQ-E0024 | C15: Diesel — Trator de Esteiras 20t (300HP) | D15: COMB | E15: 1 | F15: 22957.71 | G15: 5.98 | H15: 1 | I15: 137287.11
A16: Subtotal eap-1_2 | I16: 5367759.1
A17: eap-1_1 — Supressão vegetal com ou sem destocamento de vegetação com Ø =< 30cm, assim como remoção de arbustos, vegetação rasteira e limpeza para a área de depósito - DMT até 350m - ALTA
A18: eap-1_1 | B18: CPU-TERRA-ATI-003 | C18: Operador de Escavadeira | D18: DIRETO | E18: 1 | F18: 12875 | G18: 5.98 | H18: 1 | I18: 76992.5
A19: eap-1_1 | B19: CPU-TERRA-ATI-003 | C19: Operador de Trator de Esteiras | D19: DIRETO | E19: 1 | F19: 12875 | G19: 5.98 | H19: 1 | I19: 76992.5
A20: eap-1_1 | B20: CPU-TERRA-ATI-003 | C20: Ajudante | D20: DIRETO | E20: 3 | F20: 15784.95 | G20: 5.98 | H20: 1 | I20: 94394
A21: eap-1_1 | B21: EQ-E0016 | C21: Escavadeira Hidráulica 22t [EQ] | D21: EQ | E21: 1 | F21: 35639.3 | G21: 5.98 | H21: 1 | I21: 213123.01
A22: eap-1_1 | B22: EQ-E0024 | C22: Trator de Esteiras 20t (300HP) [EQ] | D22: EQ | E22: 1 | F22: 49477.12 | G22: 5.98 | H22: 1 | I22: 295873.18
A23: eap-1_1 | B23: EQ-E0024 | C23: Diesel — Trator de Esteiras 20t (300HP) | D23: COMB | E23: 1 | F23: 22957.71 | G23: 5.98 | H23: 1 | I23: 137287.11
A24: Subtotal eap-1_1 | I24: 1789253
A25: eap-1_3 — Corte com destocamento de árvores com Ø > 30cm e remoção para a área de depósito - DMT até 1000m
A26: eap-1_3 | B26: CPU-TERRA-ATI-001 | C26: Operador de Motoscraper | D26: DIRETO | E26: 1 | F26: 13892.78 | G26: 5.98 | H26: 1 | I26: 83078.82
A27: eap-1_3 | B27: CPU-TERRA-ATI-001 | C27: Ajudante | D27: DIRETO | E27: 3 | F27: 15784.95 | G27: 5.98 | H27: 1 | I27: 94394
A28: eap-1_3 | B28: EQ-E0031 | C28: Spread [EQ] | D28: EQ | E28: 2 | F28: 6336 | G28: 5.98 | H28: 1 | I28: 37889.28
A29: eap-1_3 | B29: EQ-E0031 | C29: Diesel — Spread | D29: COMB | E29: 2 | F29: 2550.86 | G29: 5.98 | H29: 1 | I29: 15254.14
A30: Subtotal eap-1_3 | I30: 851244.96
A31: eap-2_1 — Fornecimento e Instalação de Mata burro (padrão VALEC)
A32: eap-2_1 | B32: CPU-DIVER-ATI-090 | C32: Oficial | D32: DIRETO | E32: 2 | F32: 15852.94 | G32: 5.98 | H32: 1 | I32: 94800.58
A33: eap-2_1 | B33: CPU-DIVER-ATI-090 | C33: Ajudante | D33: DIRETO | E33: 4 | F33: 21046.6 | G33: 5.98 | H33: 1 | I33: 125858.67
A34: eap-2_1 | B34: EQ-CAM-MUNCK-23T | C34: Caminhão munck 23T [EQ] | D34: EQ | E34: 1 | F34: 30800 | G34: 5.98 | H34: 1 | I34: 184184
A35: eap-2_1 | B35: EQ-CAM-MUNCK-23T | C35: Diesel — Caminhão munck 23T | D35: COMB | E35: 1 | F35: 3826.29 | G35: 5.98 | H35: 1 | I35: 22881.21
A36: Subtotal eap-2_1 | I36: 855414.71
A37: eap-3_3 — Cerca arame liso (5 fios) com mourão de eucalipto e mourão de madeira a cada 4,0 m e esticador a cada 50 m executada em solos compostos por material de 1ª e 2ª categoria
A38: eap-3_3 | B38: CPU-DIVER-ATI-065 | C38: Encarregado de Terraplenagem | D38: DIRETO | E38: 1 | F38: 11549.8 | G38: 5.98 | H38: 1 | I38: 69067.8
A39: eap-3_3 | B39: CPU-DIVER-ATI-065 | C39: Cerqueiro | D39: DIRETO | E39: 3 | F39: 29703.51 | G39: 5.98 | H39: 1 | I39: 177626.99
A40: eap-3_3 | B40: EQ-E0001 | C40: Automóvel (veículo leve) [EQ] | D40: EQ | E40: 1 | F40: 3872 | G40: 5.98 | H40: 1 | I40: 23154.56
...

Sheet EQUILIBRIO
A1: PONTO DE EQUILÍBRIO — CUSTO FIXO vs PREÇO DE VENDA (CPU)
A2: Item ID | B2: CPU ID | C2: Custo Fixo Equipe (R$) | D2: Preço Venda CPU (R$) | E2: Delta (R$) | F2: Status
A3: eap-3_1 | B3: CPU-DIVER-ATI-066 | C3: 275950.99 | D3: 371141.66 | E3: 95190.67 | F3: OK
A4: eap-1_2 | B4: CPU-TERRA-ATI-003 | C4: 894662.3 | D4: 1950500.6 | E4: 1055838.3 | F4: OK
A5: eap-1_1 | B5: CPU-TERRA-ATI-003 | C5: 894662.3 | D5: 1344025.1 | E5: 449362.8 | F5: OK
A6: eap-1_3 | B6: CPU-TERRA-ATI-001 | C6: 283759.67 | D6: 409062.04 | E6: 125302.37 | F6: OK
A7: eap-2_1 | B7: CPU-DIVER-ATI-090 | C7: 427724.46 | D7: 575270.16 | E7: 147545.7 | F7: OK
A8: eap-3_3 | B8: CPU-DIVER-ATI-065 | C8: 275950.99 | D8: 371141.66 | E8: 95190.67 | F8: OK
A9: eap-3_6 | B9: CPU-DIVER-ATI-067 | C9: 161253.33 | D9: 216878.47 | E9: 55625.14 | F9: OK
A10: eap-5_1 | B10: CPU-DIVER-ATI-065 | C10: 275950.99 | D10: 371141.66 | E10: 95190.67 | F10: OK
A11: eap-2_3 | B11: CPU-DIVER-ATI-091 | C11: 110329.62 | D11: 148388.38 | E11: 38058.76 | F11: OK
A12: eap-4_1 | B12: CPU-TERRA-ATI-005 | C12: 191722.63 | D12: 257858.31 | E12: 66135.68 | F12: OK
A13: eap-3_5 | B13: CPU-DIVER-ATI-065 | C13: 275950.99 | D13: 371141.66 | E13: 95190.67 | F13: OK
A14: eap-3_2 | B14: CPU-DIVER-ATI-066 | C14: 275950.99 | D14: 371141.66 | E14: 95190.67 | F14: OK
... A16: eap-3_4 | B16: CPU-DIVER-ATI-065 | C16: 275950.99 | D16: 371141.66 | E16: 95190.67 | F16: OK

Sheet RESULTADO
A1: RESULTADO FINANCEIRO — MENDESLOBO CONSTRUTORA
A3: PROJETO
A4: Nome | B4: LUNDIN
A5: Tipo de obra | B5: terraplenagem
A6: Localização | B6: Brasil
A7: Período | B7: 2025-01-01 -> 2025-06-30
A8: Regime | B8: 6 dias/sem · 8 h/dia
A10: RECEITA CONTRATUAL (COM BDI)
A11: Preço de venda s/ BDI | B11: =PLANEJAMENTO!$I$18
A12: Preço de venda c/ BDI | B12: =PLANEJAMENTO!$N$18
A14: CUSTOS
A15: Custo direto (equipes) | B15: ='DIRETOS.DET'!$I$87
A16: ADM | B16: ='INDIRETOS.DET'!$H$5
A17: TOP | B17: ='INDIRETOS.DET'!$H$8
A18: LAB | B18: ='INDIRETOS.DET'!$H$11
A19: QSMS | B19: ='INDIRETOS.DET'!$H$14
A20: MOB | B20: ='INDIRETOS.DET'!$H$17
A21: Custo indireto (subtotal) | B21: ='INDIRETOS.DET'!$H$19
A22: CUSTO TOTAL | B22: =B15+B21
A24: RESULTADO
A25: Resultado bruto (R$) | B25: =B12-B22
A26: Margem bruta (%) | B26: =IF(B12>0, B25/B12, 0)
A28: STATUS: VERMELHO
A30: COMPOSIÇÃO DE CUSTO
A31: Total Direto (catálogo s/BDI) | B31: =PLANEJAMENTO!$I$18
A32: Total Direto (c/BDI) | B32: =PLANEJAMENTO!$N$18
A33: RAZÃO CI / CD (%) | B33: 258.97
A34: CI / PVT (%) | B34: 195.48
A36: CAPITAL DE GIRO
A37: Exposição máxima | B37: 19631789
A38: Parcela mensal (meses 2 a n) | B38: 1039603
A39: Resíduo (mês n+1) | B39: 1039603.4
A40: Duração da execução (meses) | B40: 7

Sheet ANALISE.FC_CAIXA
A1: FLUXO DE CAIXA — ACOMPANHAMENTO MENSAL
A2: Mês | B2: Despesa (R$) | C2: Receita (R$) | D2: Rec. Acumulada (R$) | E2: Saldo do Mês (R$) | F2: Saldo Atual (R$) | G2: Exposição Acum. (R$)
A3: Dez/24 | B3: 2818717.9 | C3: 0 | D3: 0 | E3: -2818717.9 | F3: -2818717.9 | G3: 2818717.9
A4: Jan/25 | B4: 4162282.9 | C4: 1039603 | D4: 1039603 | E4: -3122679.9 | F4: -5941397.9 | G4: 5941397.9
A5: Fev/25 | B5: 4162282.9 | C5: 1039603 | D5: 2079206 | E5: -3122679.9 | F5: -9064077.8 | G5: 9064077.8
A6: Mar/25 | B6: 4610137.9 | C6: 1039603 | D6: 3118809 | E6: -3570534.9 | F6: -12634613 | G6: 12634613
A7: Abr/25 | B7: 4162282.9 | C7: 1039603 | D7: 4158412 | E7: -3122679.9 | F7: -15757293 | G7: 15757293
A8: Mai/25 | B8: 4162282.9 | C8: 1039603 | D8: 5198015 | E8: -3122679.9 | F8: -18879973 | G8: 18879973
A9: Jun/25 | B9: 1791420 | C9: 1039603 | D9: 6237618 | E9: -751816.96 | F9: -19631789 | G9: 19631789
A10: Jul/25 | B10: 0 | C10: 1039603.4 | D10: 7277221.4 | E10: 1039603.4 | F10: -18592186 | G10: 18592186
A12: TOTAL | B12: 25869407 | C12: 7277221.4 | D12: 7277221.4 | E12: -18592186 | F12: -18592186
A15: MÉTRICAS DO FLUXO DE CAIXA
A16: Duração da execução (meses) | C16: 7
A17: Parcela mensal (meses 2 a n) | C17: 1039603
A18: Resíduo (mês n+1) | C18: 1039603.4
A19: Exposição máxima | C19: 19631789
A20: Mês da exposição máxima | C20: Jun/25
A21: Saldo final do projeto | C21: -18592186
A23: Mês 1: receita = 0. Meses 2..n: ⌊M/n⌋ cada. Mês n+1: resíduo M − ⌊M/n⌋×(n−1). Saldo Atual = Rec. Acumulada − Desp. Acumulada. Exposição Acum. = −Saldo Atual (positivo = empresa precisa de capital de giro).

Sheet HIST.EQUIPAMENTOS
A1: HISTOGRAMA DE EQUIPAMENTOS — DEMANDA SEMANAL (UN.)
A2: Equip. ID | B2: Descrição | C2: Un. | D2: 30/Dez | E2: 06/Jan | F2: 13/Jan | G2: 20/Jan | H2: 27/Jan | I2: 03/Fev | J2: 10/Fev | K2: 17/Fev | L2: 24/Fev | M2: 03/Mar | N2: 10/Mar | O2: 17/Mar | P2: 24/Mar | Q2: 31/Mar | R2: 07/Abr | S2: 14/Abr | T2: 21/Abr | U2: 28/Abr | V2: 05/Mai | W2: 12/Mai | X2: 19/Mai | Y2: 26/Mai | Z2: 02/Jun | AA2: 09/Jun | AB2: 16/Jun | AC2: 23/Jun | AD2: 30/Jun
A3: EQ-CAM-MUNCK-23T | B3: Caminhão munck 23T | C3: un | D3: 2 | E3: 2 | F3: 2 | G3: 2 | H3: 2 | I3: 2 | J3: 2 | K3: 2 | L3: 2 | M3: 2 | N3: 2 | O3: 2 | P3: 2 | Q3: 2 | R3: 2 | S3: 2 | T3: 2 | U3: 2 | V3: 2 | W3: 2 | X3: 2 | Y3: 2 | Z3: 2 | AA3: 2 | AB3: 2 | AC3: 2
A4: EQ-E0001 | B4: Automóvel (veículo leve) | C4: un | D4: 9 | E4: 9 | F4: 9 | G4: 9 | H4: 9 | I4: 9 | J4: 9 | K4: 9 | L4: 9 | M4: 9 | N4: 9 | O4: 9 | P4: 9 | Q4: 9 | R4: 9 | S4: 9 | T4: 9 | U4: 9 | V4: 9 | W4: 9 | X4: 9 | Y4: 9 | Z4: 9 | AA4: 9 | AB4: 9 | AC4: 9
A5: EQ-E0016 | B5: Escavadeira Hidráulica 22t | C5: un | D5: 8 | E5: 8 | F5: 8 | G5: 8 | H5: 8 | I5: 8 | J5: 8 | K5: 8 | L5: 8 | M5: 8 | N5: 8 | O5: 8 | P5: 8 | Q5: 8 | R5: 8 | S5: 8 | T5: 8 | U5: 8 | V5: 8 | W5: 8 | X5: 8 | Y5: 8 | Z5: 8 | AA5: 8 | AB5: 8 | AC5: 8
A6: EQ-E0024 | B6: Trator de Esteiras 20t (300HP) | C6: un | D6: 8 | E6: 8 | F6: 8 | G6: 8 | H6: 8 | I6: 8 | J6: 8 | K6: 8 | L6: 8 | M6: 8 | N6: 8 | O6: 8 | P6: 8 | Q6: 8 | R6: 8 | S6: 8 | T6: 8 | U6: 8 | V6: 8 | W6: 8 | X6: 8 | Y6: 8 | Z6: 8 | AA6: 8 | AB6: 8 | AC6: 8
A7: EQ-E0031 | B7: Spread | C7: un | D7: 6 | E7: 6 | F7: 6 | G7: 6 | H7: 6 | I7: 6 | J7: 6 | K7: 6 | L7: 6 | M7: 6 | N7: 6 | O7: 6 | P7: 6 | Q7: 6 | R7: 6 | S7: 6 | T7: 6 | U7: 6 | V7: 6 | W7: 6 | X7: 6 | Y7: 6 | Z7: 6 | AA7: 6 | AB7: 6 | AC7: 6
A8: EQ-ESTACAO-TOTAL | B8: Estação Total | C8: un | D8: 1 | E8: 1 | F8: 1 | G8: 1 | H8: 1 | I8: 1 | J8: 1 | K8: 1 | L8: 1 | M8: 1 | N8: 1 | O8: 1 | P8: 1 | Q8: 1 | R8: 1 | S8: 1 | T8: 1 | U8: 1 | V8: 1 | W8: 1 | X8: 1 | Y8: 1 | Z8: 1 | AA8: 1 | AB8: 1 | AC8: 1
A10: TOTAL SEMANAL | D10: 34 | E10: 34 | F10: 34 | G10: 34 | H10: 34 | I10: 34 | J10: 34 | K10: 34 | L10: 34 | M10: 34 | N10: 34 | O10: 34 | P10: 34 | Q10: 34 | R10: 34 | S10: 34 | T10: 34 | U10: 34 | V10: 34 | W10: 34 | X10: 34 | Y10: 34 | Z10: 34 | AA10: 34 | AB10: 34 | AC10: 34

Sheet HIST.MAO_OBRA
A1: HISTOGRAMA DE MÃO DE OBRA — DEMANDA SEMANAL (PESSOAS)
A2: Função ID | B2: Descrição | C2: Un. | D2: 30/Dez | E2: 06/Jan | F2: 13/Jan | G2: 20/Jan | H2: 27/Jan | I2: 03/Fev | J2: 10/Fev | K2: 17/Fev | L2: 24/Fev | M2: 03/Mar | N2: 10/Mar | O2: 17/Mar | P2: 24/Mar | Q2: 31/Mar | R2: 07/Abr | S2: 14/Abr | T2: 21/Abr | U2: 28/Abr | V2: 05/Mai | W2: 12/Mai | X2: 19/Mai | Y2: 26/Mai | Z2: 02/Jun | AA2: 09/Jun | AB2: 16/Jun | AC2: 23/Jun | AD2: 30/Jun
A3: MO-AJUDANTE | B3: Ajudante | C3: pax | D3: 47 | E3: 47 | F3: 47 | G3: 47 | H3: 47 | I3: 47 | J3: 47 | K3: 47 | L3: 47 | M3: 47 | N3: 47 | O3: 47 | P3: 47 | Q3: 47 | R3: 47 | S3: 47 | T3: 47 | U3: 47 | V3: 47 | W3: 47 | X3: 47 | Y3: 47 | Z3: 47 | AA3: 47 | AB3: 47 | AC3: 47
A4: MO-AUX-TOPO | B4: Auxiliar de topografia | C4: pax | D4: 2 | E4: 2 | F4: 2 | G4: 2 | H4: 2 | I4: 2 | J4: 2 | K4: 2 | L4: 2 | M4: 2 | N4: 2 | O4: 2 | P4: 2 | Q4: 2 | R4: 2 | S4: 2 | T4: 2 | U4: 2 | V4: 2 | W4: 2 | X4: 2 | Y4: 2 | Z4: 2 | AA4: 2 | AB4: 2 | AC4: 2
A5: MO-CERQUEIRO | B5: Cerqueiro | C5: pax | D5: 24 | E5: 24 | F5: 24 | G5: 24 | H5: 24 | I5: 24 | J5: 24 | K5: 24 | L5: 24 | M5: 24 | N5: 24 | O5: 24 | P5: 24 | Q5: 24 | R5: 24 | S5: 24 | T5: 24 | U5: 24 | V5: 24 | W5: 24 | X5: 24 | Y5: 24 | Z5: 24 | AA5: 24 | AB5: 24 | AC5: 24
A6: MO-ENCARREG-TERRA | B6: Encarregado de Terraplenagem | C6: pax | D6: 9 | E6: 9 | F6: 9 | G6: 9 | H6: 9 | I6: 9 | J6: 9 | K6: 9 | L6: 9 | M6: 9 | N6: 9 | O6: 9 | P6: 9 | Q6: 9 | R6: 9 | S6: 9 | T6: 9 | U6: 9 | V6: 9 | W6: 9 | X6: 9 | Y6: 9 | Z6: 9 | AA6: 9 | AB6: 9 | AC6: 9
A7: MO-OFICIAL | B7: Oficial | C7: pax | D7: 6 | E7: 6 | F7: 6 | G7: 6 | H7: 6 | I7: 6 | J7: 6 | K7: 6 | L7: 6 | M7: 6 | N7: 6 | O7: 6 | P7: 6 | Q7: 6 | R7: 6 | S7: 6 | T7: 6 | U7: 6 | V7: 6 | W7: 6 | X7: 6 | Y7: 6 | Z7: 6 | AA7: 6 | AB7: 6 | AC7: 6
A8: MO-OPER-ESCAV | B8: Operador de Escavadeira | C8: pax | D8: 8 | E8: 8 | F8: 8 | G8: 8 | H8: 8 | I8: 8 | J8: 8 | K8: 8 | L8: 8 | M8: 8 | N8: 8 | O8: 8 | P8: 8 | Q8: 8 | R8: 8 | S8: 8 | T8: 8 | U8: 8 | V8: 8 | W8: 8 | X8: 8 | Y8: 8 | Z8: 8 | AA8: 8 | AB8: 8 | AC8: 8
A9: MO-OPER-TRATOR-EST | B9: Operador de Trator de Esteiras | C9: pax | D9: 8 | E9: 8 | F9: 8 | G9: 8 | H9: 8 | I9: 8 | J9: 8 | K9: 8 | L9: 8 | M9: 8 | N9: 8 | O9: 8 | P9: 8 | Q9: 8 | R9: 8 | S9: 8 | T9: 8 | U9: 8 | V9: 8 | W9: 8 | X9: 8 | Y9: 8 | Z9: 8 | AA9: 8 | AB9: 8 | AC9: 8
A10: MO-OPERADOR-DE-MOTOSCRA | B10: Operador de Motoscraper | C10: pax | D10: 3 | E10: 3 | F10: 3 | G10: 3 | H10: 3 | I10: 3 | J10: 3 | K10: 3 | L10: 3 | M10: 3 | N10: 3 | O10: 3 | P10: 3 | Q10: 3 | R10: 3 | S10: 3 | T10: 3 | U10: 3 | V10: 3 | W10: 3 | X10: 3 | Y10: 3 | Z10: 3 | AA10: 3 | AB10: 3 | AC10: 3
A11: MO-TOPOGRAFO | B11: Topógrafo | C11: pax | D11: 1 | E11: 1 | F11: 1 | G11: 1 | H11: 1 | I11: 1 | J11: 1 | K11: 1 | L11: 1 | M11: 1 | N11: 1 | O11: 1 | P11: 1 | Q11: 1 | R11: 1 | S11: 1 | T11: 1 | U11: 1 | V11: 1 | W11: 1 | X11: 1 | Y11: 1 | Z11: 1 | AA11: 1 | AB11: 1 | AC11: 1
A13: TOTAL SEMANAL | D13: 108 | E13: 108 | F13: 108 | G13: 108 | H13: 108 | I13: 108 | J13: 108 | K13: 108 | L13: 108 | M13: 108 | N13: 108 | O13: 108 | P13: 108 | Q13: 108 | R13: 108 | S13: 108 | T13: 108 | U13: 108 | V13: 108 | W13: 108 | X13: 108 | Y13: 108 | Z13: 108 | AA13: 108 | AB13: 108 | AC13: 108

Sheet ANALISE.CURVA_ABC
A1: CURVA ABC — ANÁLISE PARETO POR ITEM EAP (S/ BDI)
A2: Item ID | B2: Descrição | C2: Un. | D2: Quantitativo | E2: Subtotal s/ BDI (R$) | F2: % do Total | G2: % Acumulado | H2: Criticidade | I2: Destaque
A3: eap-1_2 | B3: Supressão vegetal, destocamento e limpeza de árvores, arbustos, vegetação rasteira e entulhos com remoção para área de depósito - DMT até 350m | C3: M2 | D3: 2036512.4 | E3: 1517345.7 | F3: 27.6234 | G3: 27.6234 | H3: A
A4: eap-1_1 | B4: Supressão vegetal com ou sem destocamento de vegetação com Ø =< 30cm, assim como remoção de arbustos, vegetação rasteira e limpeza para a área de depósito - DMT até 350m - ALTA | C4: M2 | D4: 383592.55 | E4: 1011949.4 | F4: 18.4226 | G4: 46.046 | H4: A
A5: eap-2_1 | B5: Fornecimento e Instalação de Mata burro (padrão VALEC) | C5: UNIDADE | D5: 59 | E5: 427724.46 | F5: 7.7868 | G5: 53.8328 | H5: A
A6: eap-1_3 | B6: Corte com destocamento de árvores com Ø > 30cm e remoção para a área de depósito - DMT até 1000m | C6: UNIDADE | D6: 12240.2 | E6: 306608.04 | F6: 5.5818 | G6: 59.4146 | H6: B
A7: eap-3_1 | B7: Cerca arame liso (5 fios) com mourões de concreto, seção quadrada 10 x 10 cm (padrão VALEC) executada em solos compostos por material de 1ª e 2ª categoria | C7: M | D7: 77928.38 | E7: 275950.99 | F7: 5.0237 | G7: 64.4384 | H7: B
A8: eap-5_1 | B8: Abertura de acesso para implantação de cerca | C8: M | D8: 57000 | E8: 275950.99 | F8: 5.0237 | G8: 69.4621 | H8: B
A9: eap-3_3 | B9: Cerca arame liso (5 fios) com mourão de eucalipto e mourão de madeira a cada 4,0 m e esticador a cada 50 m executada em solos compostos por material de 1ª e 2ª categoria | C9: M | D9: 16451.19 | E9: 275950.99 | F9: 5.0237 | G9: 74.4858 | H9: C
A10: eap-3_5 | B10: Cerca arame liso (5 fios) com mourão de eucalipto e mourão de madeira a cada 4,0 m e esticador a cada 50 m executada em solos alagadas | C10: M | D10: 1827.91 | E10: 275950.99 | F10: 5.0237 | G10: 79.5095 | H10: C
A11: eap-3_2 | B11: Cerca arame liso (5 fios) com mourões de concreto, seção quadrada 10 x 10 cm (padrão VALEC) executada em solos alagáveis | C11: M | D11: 575 | E11: 275950.99 | F11: 5.0237 | G11: 84.5332 | H11: C
A12: eap-3_4 | B12: Cerca arame liso (5 fios) com mourão de eucalipto e mourão de madeira a cada 2,5 m e esticador a cada 50 m executada em solos compostos por material de 1ª e 2ª categoria | C12: M | D12: 700 | E12: 275950.99 | F12: 5.0237 | G12: 89.5569 | H12: C
A13: eap-4_1 | B13: Implantação do eixo | C13: KM | D13: 57 | E13: 191722.63 | F13: 3.4903 | G13: 93.0472 | H13: C
A14: eap-3_6 | B14: Remoção de cerca de mourão de madeira | C14: M | D14: 37143.75 | E14: 161253.33 | F14: 2.9356 | G14: 95.9829 | H14: C
... A16: eap-2_2 | B16: Fornecimento e Instalação de Porteira de Madeira (padrão VALEC) | C16: UNIDADE | D16: 19 | E16: 110329.62 | F16: 2.0086 | G16: 100 | H16: C
A18: TOTAL | E18: =SUM(E3:E17)
