Workbook

Sheet PARÂMETROS
A1: PARÂMETROS — ÚNICA FONTE DE VERDADE
A3: REGIME DE TRABALHO
A4: Horas trabalhadas/dia (H) | B4: 8
A5: Dias trabalhados/semana (D) | B5: 6
A6: Preço Diesel (R$/L) | B6: 6.99
A8: BDI POR CATEGORIA
A9: BDI Diesel / Combustível (= BDI Material) | B9: 0.04
A10: BDI Mão de Obra (TER) | B10: 0.290573
A11: BDI Equipamentos | B11: 0.290573
A12: BDI Indiretos | B12: 0.25205
A14: ITENS EAP — QUANTITATIVOS, PRODUTIVIDADES E COMPOSIÇÃO
A15: Item ID | B15: Descrição | C15: Un. | D15: Quantitativo | E15: P (un/h) | F15: P.U.Diesel (R$/un) | G15: P.U.MO (R$/un) | H15: nEq médio | I15: Duração calc. (sem.)
A16: eap-1_0 | B16: Desmatamento e limpeza de area vegetada | C16: m2 | D16: 2400000 | E16: 714.2857 | F16: 0.2942 | G16: 0.5794 | H16: 1 | I16: =IF(AND(E16>0,H16>0),CEILING(D16/(E16*PARÂMETROS!$B$4*PARÂMETROS!$B$5*AVERAGE(PARÂMETROS!$B$40:$B$91)*H16),1),"N/D")
A17: eap-1_1 | B17: Esc/carg/transp 1aCat DMT<=2000m | C17: m3 | D17: 107463.11 | E17: 223.8815 | F17: 4.7099 | G17: 2.9484 | H17: 1 | I17: =IF(AND(E17>0,H17>0),CEILING(D17/(E17*PARÂMETROS!$B$4*PARÂMETROS!$B$5*AVERAGE(PARÂMETROS!$B$40:$B$91)*H17),1),"N/D")
A18: eap-1_2 | B18: Esc/carg/transp 1aCat DMT<=3000m | C18: m3 | D18: 336915.09 | E18: 226.7957 | F18: 5.1763 | G18: 3.2848 | H18: 1 | I18: =IF(AND(E18>0,H18>0),CEILING(D18/(E18*PARÂMETROS!$B$4*PARÂMETROS!$B$5*AVERAGE(PARÂMETROS!$B$40:$B$91)*H18),1),"N/D")
A19: eap-1_3 | B19: Esc/carg/transp 2aCat DMT<=2000m | C19: m3 | D19: 105311.33 | E19: 156.7133 | F19: 6.2476 | G19: 3.8464 | H19: 1 | I19: =IF(AND(E19>0,H19>0),CEILING(D19/(E19*PARÂMETROS!$B$4*PARÂMETROS!$B$5*AVERAGE(PARÂMETROS!$B$40:$B$91)*H19),1),"N/D")
A20: eap-1_4 | B20: Esc/carg/transp 2aCat DMT<=3000m | C20: m3 | D20: 585945.77 | E20: 156.4746 | F20: 6.6284 | G20: 4.0173 | H20: 1 | I20: =IF(AND(E20>0,H20>0),CEILING(D20/(E20*PARÂMETROS!$B$4*PARÂMETROS!$B$5*AVERAGE(PARÂMETROS!$B$40:$B$91)*H20),1),"N/D")
A21: eap-1_5 | B21: Esc/carg/transp 3aCat DMT<=2000m | C21: m3 | D21: 304634.46 | E21: 144.2398 | F21: 9.6856 | G21: 5.1859 | H21: 1 | I21: =IF(AND(E21>0,H21>0),CEILING(D21/(E21*PARÂMETROS!$B$4*PARÂMETROS!$B$5*AVERAGE(PARÂMETROS!$B$40:$B$91)*H21),1),"N/D")
A22: eap-1_6 | B22: Esc/carg/transp 3aCat DMT<=3000m | C22: m3 | D22: 676519.04 | E22: 143.9367 | F22: 11.7945 | G22: 6.4299 | H22: 1 | I22: =IF(AND(E22>0,H22>0),CEILING(D22/(E22*PARÂMETROS!$B$4*PARÂMETROS!$B$5*AVERAGE(PARÂMETROS!$B$40:$B$91)*H22),1),"N/D")
A23: eap-1_7 | B23: Compactacao aterros 100% Proctor Normal | C23: m3 | D23: 1135635.3 | E23: 189.0899 | F23: 6.1967 | G23: 2.935 | H23: 1 | I23: =IF(AND(E23>0,H23>0),CEILING(D23/(E23*PARÂMETROS!$B$4*PARÂMETROS!$B$5*AVERAGE(PARÂMETROS!$B$40:$B$91)*H23),1),"N/D")
A24: eap-1_8 | B24: Compactacao aterros 100% Proctor Intermediario | C24: m3 | D24: 29411 | E24: 102.1215 | F24: 8.1022 | G24: 3.8375 | H24: 1 | I24: =IF(AND(E24>0,H24>0),CEILING(D24/(E24*PARÂMETROS!$B$4*PARÂMETROS!$B$5*AVERAGE(PARÂMETROS!$B$40:$B$91)*H24),1),"N/D")
A25: eap-1_9 | B25: Construcao corpo aterro material 3a categoria | C25: m3 | D25: 981153.5 | E25: 235.0682 | F25: 4.0706 | G25: 1.8024 | H25: 1 | I25: =IF(AND(E25>0,H25>0),CEILING(D25/(E25*PARÂMETROS!$B$4*PARÂMETROS!$B$5*AVERAGE(PARÂMETROS!$B$40:$B$91)*H25),1),"N/D")
A26: eap-1_10 | B26: Compactacao camada final aterro sobre rocha | C26: m3 | D26: 24721.17 | E26: 85.8374 | F26: 5.6619 | G26: 8.7753 | H26: 1 | I26: =IF(AND(E26>0,H26>0),CEILING(D26/(E26*PARÂMETROS!$B$4*PARÂMETROS!$B$5*AVERAGE(PARÂMETROS!$B$40:$B$91)*H26),1),"N/D")
A29: INDIRETOS — CUSTO FIXO MENSAL E PERMANÊNCIA
A30: Categoria | B30: Custo Fixo Mensal (R$) | C30: Permanência (meses)
A31: ADM | B31: 1059228.6 | C31: 12.93
A32: TOP | B32: 66415.96 | C32: 12.93
A33: LAB | B33: 10794.14 | C33: 12.93
A34: QSMS | B34: 58451.48 | C34: 12.93
A35: MOB | B35: 311892.34 | C35: 13
A38: PRATICABILIDADE SEMANAL (p_j) — VALORES REAIS
A39: Semana ISO | B39: Fator [0,1]
A40: 2026-W24 | B40: 1
A41: 2026-W25 | B41: 1
A42: 2026-W26 | B42: 1
A43: 2026-W27 | B43: 1
A44: 2026-W28 | B44: 1
A45: 2026-W29 | B45: 1
A46: 2026-W30 | B46: 1
A47: 2026-W31 | B47: 1
...

Sheet RECURSOS
A1: RECURSOS — TAXAS E COMPOSIÇÃO DAS EQUIPES
A3: MÃO DE OBRA — TAXAS MENSAIS
A4: ID Função | B4: Descrição | C4: Custo Mensal Unitário (R$)
A5: P0040 | B5: Operador de Escavadeira | C5: 10300
A6: P0048 | B6: Operador de Trator de Esteiras | C6: 10300
A7: P0062 | B7: Operador de motosserra | C7: 7307.65
A8: P0001 | B8: Ajudante | C8: 4209.32
A9: P0079 | B9: SINALEIRO | C9: 6341.17
A10: P0065 | B10: Encarregado de Frente | C10: 7500
A11: P0072 | B11: Apontador | C11: 6341.17
A12: P0032 | B12: Motorista de Caminhão Basculante | C12: 6341.17
A13: P0043 | B13: Operador de Motoniveladora | C13: 10300
A14: P0049 | B14: Operador de Trator de Pneu | C14: 6341.17
A15: P0033 | B15: Motorista de Caminhão Pipa | C15: 6341.17
A16: P0046 | B16: Operador de Rolo Compactador | C16: 6341.17
A17: P0029 | B17: Gredista | C17: 6341.17
A20: EQUIPAMENTOS — TAXAS MENSAIS
A21: ID Equip. | B21: Descrição | C21: Aluguel Mensal (R$) | D21: Comb. Mensal (R$) (por unidade)
A22: EQ-E0016 | B22: Escavadeira Hidráulica 22t | C22: 35639.3 | D22: 0
A23: EQ-E0035 | B23: Trator de esteiras 20T | C23: 21683.2 | D23: 22957.71
A24: EQ-E0028 | B24: Motoniveladora 120HP | C24: 36664.32 | D24: 11478.86
A25: EQ-E0034 | B25: Trator de pneus com grade | C25: 7744 | D25: 10203.43
A26: EQ-E0037 | B26: Trator de esteiras 40T | C26: 20421.63 | D26: 30610.29
A29: COMPOSIÇÃO DAS EQUIPES — nº PESSOAS / UNIDADES POR ITEM
A30: Item ID | B30: Descrição | C30: P0040 | D30: P0048 | E30: P0062 | F30: P0001 | G30: P0079 | H30: P0065 | I30: P0072 | J30: P0032 | K30: P0043 | L30: P0049 | M30: P0033 | N30: P0046 | O30: P0029 | P30: EQ-E0016 | Q30: EQ-E0035 | R30: EQ-E0028 | S30: EQ-E0034 | T30: EQ-E0037
A31: eap-1_0 | B31: Desmatamento e limpeza de | C31: 1 | D31: 6 | E31: 6 | F31: 6 | G31: 6 | H31: 1 | I31: 1 | P31: 1 | Q31: 6
A32: eap-1_1 | B32: Esc/carg/transp 1aCat DMT | C32: 1 | F32: 1 | H32: 1 | J32: 7 | P32: 1
A33: eap-1_2 | B33: Esc/carg/transp 1aCat DMT | C33: 1 | F33: 1 | H33: 1 | J33: 7 | P33: 1
A34: eap-1_3 | B34: Esc/carg/transp 2aCat DMT | C34: 2 | F34: 2 | H34: 1 | J34: 11 | P34: 2
A35: eap-1_4 | B35: Esc/carg/transp 2aCat DMT | C35: 2 | F35: 2 | H35: 1 | J35: 11 | P35: 2
A36: eap-1_5 | B36: Esc/carg/transp 3aCat DMT | C36: 4 | F36: 4 | J36: 25 | P36: 4
A37: eap-1_6 | B37: Esc/carg/transp 3aCat DMT | C37: 4 | F37: 4 | J37: 25 | P37: 4
A38: eap-1_7 | B38: Compactacao aterros 100% | F38: 6 | H38: 2 | K38: 3 | L38: 3 | M38: 3 | N38: 6 | O38: 3 | R38: 3 | S38: 3
A39: eap-1_8 | B39: Compactacao aterros 100% | F39: 6 | H39: 2 | K39: 3 | L39: 3 | M39: 3 | N39: 6 | O39: 3 | R39: 3 | S39: 3
A40: eap-1_9 | B40: Construcao corpo aterro m | D40: 2 | F40: 4 | H40: 1 | N40: 4 | O40: 2 | T40: 2
A41: eap-1_10 | B41: Compactacao camada final | D41: 1 | F41: 2 | M41: 1 | N41: 3 | Q41: 1

Sheet CUSTOS DIR.
A1: CUSTOS DIRETOS — EQUIPES POR ITEM (FÓRMULAS SOBRE RECURSOS)
A2: Item ID | B2: Desc. | C2: MO Mensal (R$) | D2: EQ Mensal (R$) | E2: Comb. Mensal (R$) | F2: Total Fixo/Mês (R$) | G2: Permanência (sem.) | H2: Permanência (mes.) | I2: Custo Total (R$)
A3: eap-1_0 | B3: Desmatamento e limpeza | C3: =RECURSOS!C31*RECURSOS!$C$5+RECURSOS!D31*RECURSOS!$C$6+RECURSOS!E31*RECURSOS!$C$7+RECURSOS!F31*RECURSOS!$C$8+RECURSOS!G31*RECURSOS!$C$9+RECURSOS!H31*RECURSOS!$C$10+RECURSOS!I31*RECURSOS!$C$11+RECURSOS!J31*RECURSOS!$C$12+RECURSOS!K31*RECURSOS!$C$13+RECURSOS!L31*RECURSOS!$C$14+RECURSOS!M31*RECURSOS!$C$15+RECURSOS!N31*RECURSOS!$C$16+RECURSOS!O31*RECURSOS!$C$17 | D3: =RECURSOS!P31*RECURSOS!$C$22+RECURSOS!Q31*RECURSOS!$C$23+RECURSOS!R31*RECURSOS!$C$24+RECURSOS!S31*RECURSOS!$C$25+RECURSOS!T31*RECURSOS!$C$26 | E3: =RECURSOS!P31*RECURSOS!$D$22+RECURSOS!Q31*RECURSOS!$D$23+RECURSOS!R31*RECURSOS!$D$24+RECURSOS!S31*RECURSOS!$D$25+RECURSOS!T31*RECURSOS!$D$26 | F3: =C3+D3+E3 | G3: =PARÂMETROS!I16 | H3: =G3/4.348 | I3: =F3*H3
A4: eap-1_1 | B4: Esc/carg/transp 1aCat | C4: =RECURSOS!C32*RECURSOS!$C$5+RECURSOS!D32*RECURSOS!$C$6+RECURSOS!E32*RECURSOS!$C$7+RECURSOS!F32*RECURSOS!$C$8+RECURSOS!G32*RECURSOS!$C$9+RECURSOS!H32*RECURSOS!$C$10+RECURSOS!I32*RECURSOS!$C$11+RECURSOS!J32*RECURSOS!$C$12+RECURSOS!K32*RECURSOS!$C$13+RECURSOS!L32*RECURSOS!$C$14+RECURSOS!M32*RECURSOS!$C$15+RECURSOS!N32*RECURSOS!$C$16+RECURSOS!O32*RECURSOS!$C$17 | D4: =RECURSOS!P32*RECURSOS!$C$22+RECURSOS!Q32*RECURSOS!$C$23+RECURSOS!R32*RECURSOS!$C$24+RECURSOS!S32*RECURSOS!$C$25+RECURSOS!T32*RECURSOS!$C$26 | E4: =RECURSOS!P32*RECURSOS!$D$22+RECURSOS!Q32*RECURSOS!$D$23+RECURSOS!R32*RECURSOS!$D$24+RECURSOS!S32*RECURSOS!$D$25+RECURSOS!T32*RECURSOS!$D$26 | F4: =C4+D4+E4 | G4: =PARÂMETROS!I17 | H4: =G4/4.348 | I4: =F4*H4
A5: eap-1_2 | B5: Esc/carg/transp 1aCat | C5: =RECURSOS!C33*RECURSOS!$C$5+RECURSOS!D33*RECURSOS!$C$6+RECURSOS!E33*RECURSOS!$C$7+RECURSOS!F33*RECURSOS!$C$8+RECURSOS!G33*RECURSOS!$C$9+RECURSOS!H33*RECURSOS!$C$10+RECURSOS!I33*RECURSOS!$C$11+RECURSOS!J33*RECURSOS!$C$12+RECURSOS!K33*RECURSOS!$C$13+RECURSOS!L33*RECURSOS!$C$14+RECURSOS!M33*RECURSOS!$C$15+RECURSOS!N33*RECURSOS!$C$16+RECURSOS!O33*RECURSOS!$C$17 | D5: =RECURSOS!P33*RECURSOS!$C$22+RECURSOS!Q33*RECURSOS!$C$23+RECURSOS!R33*RECURSOS!$C$24+RECURSOS!S33*RECURSOS!$C$25+RECURSOS!T33*RECURSOS!$C$26 | E5: =RECURSOS!P33*RECURSOS!$D$22+RECURSOS!Q33*RECURSOS!$D$23+RECURSOS!R33*RECURSOS!$D$24+RECURSOS!S33*RECURSOS!$D$25+RECURSOS!T33*RECURSOS!$D$26 | F5: =C5+D5+E5 | G5: =PARÂMETROS!I18 | H5: =G5/4.348 | I5: =F5*H5
A6: eap-1_3 | B6: Esc/carg/transp 2aCat | C6: =RECURSOS!C34*RECURSOS!$C$5+RECURSOS!D34*RECURSOS!$C$6+RECURSOS!E34*RECURSOS!$C$7+RECURSOS!F34*RECURSOS!$C$8+RECURSOS!G34*RECURSOS!$C$9+RECURSOS!H34*RECURSOS!$C$10+RECURSOS!I34*RECURSOS!$C$11+RECURSOS!J34*RECURSOS!$C$12+RECURSOS!K34*RECURSOS!$C$13+RECURSOS!L34*RECURSOS!$C$14+RECURSOS!M34*RECURSOS!$C$15+RECURSOS!N34*RECURSOS!$C$16+RECURSOS!O34*RECURSOS!$C$17 | D6: =RECURSOS!P34*RECURSOS!$C$22+RECURSOS!Q34*RECURSOS!$C$23+RECURSOS!R34*RECURSOS!$C$24+RECURSOS!S34*RECURSOS!$C$25+RECURSOS!T34*RECURSOS!$C$26 | E6: =RECURSOS!P34*RECURSOS!$D$22+RECURSOS!Q34*RECURSOS!$D$23+RECURSOS!R34*RECURSOS!$D$24+RECURSOS!S34*RECURSOS!$D$25+RECURSOS!T34*RECURSOS!$D$26 | F6: =C6+D6+E6 | G6: =PARÂMETROS!I19 | H6: =G6/4.348 | I6: =F6*H6
A7: eap-1_4 | B7: Esc/carg/transp 2aCat | C7: =RECURSOS!C35*RECURSOS!$C$5+RECURSOS!D35*RECURSOS!$C$6+RECURSOS!E35*RECURSOS!$C$7+RECURSOS!F35*RECURSOS!$C$8+RECURSOS!G35*RECURSOS!$C$9+RECURSOS!H35*RECURSOS!$C$10+RECURSOS!I35*RECURSOS!$C$11+RECURSOS!J35*RECURSOS!$C$12+RECURSOS!K35*RECURSOS!$C$13+RECURSOS!L35*RECURSOS!$C$14+RECURSOS!M35*RECURSOS!$C$15+RECURSOS!N35*RECURSOS!$C$16+RECURSOS!O35*RECURSOS!$C$17 | D7: =RECURSOS!P35*RECURSOS!$C$22+RECURSOS!Q35*RECURSOS!$C$23+RECURSOS!R35*RECURSOS!$C$24+RECURSOS!S35*RECURSOS!$C$25+RECURSOS!T35*RECURSOS!$C$26 | E7: =RECURSOS!P35*RECURSOS!$D$22+RECURSOS!Q35*RECURSOS!$D$23+RECURSOS!R35*RECURSOS!$D$24+RECURSOS!S35*RECURSOS!$D$25+RECURSOS!T35*RECURSOS!$D$26 | F7: =C7+D7+E7 | G7: =PARÂMETROS!I20 | H7: =G7/4.348 | I7: =F7*H7
A8: eap-1_5 | B8: Esc/carg/transp 3aCat | C8: =RECURSOS!C36*RECURSOS!$C$5+RECURSOS!D36*RECURSOS!$C$6+RECURSOS!E36*RECURSOS!$C$7+RECURSOS!F36*RECURSOS!$C$8+RECURSOS!G36*RECURSOS!$C$9+RECURSOS!H36*RECURSOS!$C$10+RECURSOS!I36*RECURSOS!$C$11+RECURSOS!J36*RECURSOS!$C$12+RECURSOS!K36*RECURSOS!$C$13+RECURSOS!L36*RECURSOS!$C$14+RECURSOS!M36*RECURSOS!$C$15+RECURSOS!N36*RECURSOS!$C$16+RECURSOS!O36*RECURSOS!$C$17 | D8: =RECURSOS!P36*RECURSOS!$C$22+RECURSOS!Q36*RECURSOS!$C$23+RECURSOS!R36*RECURSOS!$C$24+RECURSOS!S36*RECURSOS!$C$25+RECURSOS!T36*RECURSOS!$C$26 | E8: =RECURSOS!P36*RECURSOS!$D$22+RECURSOS!Q36*RECURSOS!$D$23+RECURSOS!R36*RECURSOS!$D$24+RECURSOS!S36*RECURSOS!$D$25+RECURSOS!T36*RECURSOS!$D$26 | F8: =C8+D8+E8 | G8: =PARÂMETROS!I21 | H8: =G8/4.348 | I8: =F8*H8
A9: eap-1_6 | B9: Esc/carg/transp 3aCat | C9: =RECURSOS!C37*RECURSOS!$C$5+RECURSOS!D37*RECURSOS!$C$6+RECURSOS!E37*RECURSOS!$C$7+RECURSOS!F37*RECURSOS!$C$8+RECURSOS!G37*RECURSOS!$C$9+RECURSOS!H37*RECURSOS!$C$10+RECURSOS!I37*RECURSOS!$C$11+RECURSOS!J37*RECURSOS!$C$12+RECURSOS!K37*RECURSOS!$C$13+RECURSOS!L37*RECURSOS!$C$14+RECURSOS!M37*RECURSOS!$C$15+RECURSOS!N37*RECURSOS!$C$16+RECURSOS!O37*RECURSOS!$C$17 | D9: =RECURSOS!P37*RECURSOS!$C$22+RECURSOS!Q37*RECURSOS!$C$23+RECURSOS!R37*RECURSOS!$C$24+RECURSOS!S37*RECURSOS!$C$25+RECURSOS!T37*RECURSOS!$C$26 | E9: =RECURSOS!P37*RECURSOS!$D$22+RECURSOS!Q37*RECURSOS!$D$23+RECURSOS!R37*RECURSOS!$D$24+RECURSOS!S37*RECURSOS!$D$25+RECURSOS!T37*RECURSOS!$D$26 | F9: =C9+D9+E9 | G9: =PARÂMETROS!I22 | H9: =G9/4.348 | I9: =F9*H9
A10: eap-1_7 | B10: Compactacao aterros 10 | C10: =RECURSOS!C38*RECURSOS!$C$5+RECURSOS!D38*RECURSOS!$C$6+RECURSOS!E38*RECURSOS!$C$7+RECURSOS!F38*RECURSOS!$C$8+RECURSOS!G38*RECURSOS!$C$9+RECURSOS!H38*RECURSOS!$C$10+RECURSOS!I38*RECURSOS!$C$11+RECURSOS!J38*RECURSOS!$C$12+RECURSOS!K38*RECURSOS!$C$13+RECURSOS!L38*RECURSOS!$C$14+RECURSOS!M38*RECURSOS!$C$15+RECURSOS!N38*RECURSOS!$C$16+RECURSOS!O38*RECURSOS!$C$17 | D10: =RECURSOS!P38*RECURSOS!$C$22+RECURSOS!Q38*RECURSOS!$C$23+RECURSOS!R38*RECURSOS!$C$24+RECURSOS!S38*RECURSOS!$C$25+RECURSOS!T38*RECURSOS!$C$26 | E10: =RECURSOS!P38*RECURSOS!$D$22+RECURSOS!Q38*RECURSOS!$D$23+RECURSOS!R38*RECURSOS!$D$24+RECURSOS!S38*RECURSOS!$D$25+RECURSOS!T38*RECURSOS!$D$26 | F10: =C10+D10+E10 | G10: =PARÂMETROS!I23 | H10: =G10/4.348 | I10: =F10*H10
A11: eap-1_8 | B11: Compactacao aterros 10 | C11: =RECURSOS!C39*RECURSOS!$C$5+RECURSOS!D39*RECURSOS!$C$6+RECURSOS!E39*RECURSOS!$C$7+RECURSOS!F39*RECURSOS!$C$8+RECURSOS!G39*RECURSOS!$C$9+RECURSOS!H39*RECURSOS!$C$10+RECURSOS!I39*RECURSOS!$C$11+RECURSOS!J39*RECURSOS!$C$12+RECURSOS!K39*RECURSOS!$C$13+RECURSOS!L39*RECURSOS!$C$14+RECURSOS!M39*RECURSOS!$C$15+RECURSOS!N39*RECURSOS!$C$16+RECURSOS!O39*RECURSOS!$C$17 | D11: =RECURSOS!P39*RECURSOS!$C$22+RECURSOS!Q39*RECURSOS!$C$23+RECURSOS!R39*RECURSOS!$C$24+RECURSOS!S39*RECURSOS!$C$25+RECURSOS!T39*RECURSOS!$C$26 | E11: =RECURSOS!P39*RECURSOS!$D$22+RECURSOS!Q39*RECURSOS!$D$23+RECURSOS!R39*RECURSOS!$D$24+RECURSOS!S39*RECURSOS!$D$25+RECURSOS!T39*RECURSOS!$D$26 | F11: =C11+D11+E11 | G11: =PARÂMETROS!I24 | H11: =G11/4.348 | I11: =F11*H11
A12: eap-1_9 | B12: Construcao corpo aterr | C12: =RECURSOS!C40*RECURSOS!$C$5+RECURSOS!D40*RECURSOS!$C$6+RECURSOS!E40*RECURSOS!$C$7+RECURSOS!F40*RECURSOS!$C$8+RECURSOS!G40*RECURSOS!$C$9+RECURSOS!H40*RECURSOS!$C$10+RECURSOS!I40*RECURSOS!$C$11+RECURSOS!J40*RECURSOS!$C$12+RECURSOS!K40*RECURSOS!$C$13+RECURSOS!L40*RECURSOS!$C$14+RECURSOS!M40*RECURSOS!$C$15+RECURSOS!N40*RECURSOS!$C$16+RECURSOS!O40*RECURSOS!$C$17 | D12: =RECURSOS!P40*RECURSOS!$C$22+RECURSOS!Q40*RECURSOS!$C$23+RECURSOS!R40*RECURSOS!$C$24+RECURSOS!S40*RECURSOS!$C$25+RECURSOS!T40*RECURSOS!$C$26 | E12: =RECURSOS!P40*RECURSOS!$D$22+RECURSOS!Q40*RECURSOS!$D$23+RECURSOS!R40*RECURSOS!$D$24+RECURSOS!S40*RECURSOS!$D$25+RECURSOS!T40*RECURSOS!$D$26 | F12: =C12+D12+E12 | G12: =PARÂMETROS!I25 | H12: =G12/4.348 | I12: =F12*H12
A13: eap-1_10 | B13: Compactacao camada fin | C13: =RECURSOS!C41*RECURSOS!$C$5+RECURSOS!D41*RECURSOS!$C$6+RECURSOS!E41*RECURSOS!$C$7+RECURSOS!F41*RECURSOS!$C$8+RECURSOS!G41*RECURSOS!$C$9+RECURSOS!H41*RECURSOS!$C$10+RECURSOS!I41*RECURSOS!$C$11+RECURSOS!J41*RECURSOS!$C$12+RECURSOS!K41*RECURSOS!$C$13+RECURSOS!L41*RECURSOS!$C$14+RECURSOS!M41*RECURSOS!$C$15+RECURSOS!N41*RECURSOS!$C$16+RECURSOS!O41*RECURSOS!$C$17 | D13: =RECURSOS!P41*RECURSOS!$C$22+RECURSOS!Q41*RECURSOS!$C$23+RECURSOS!R41*RECURSOS!$C$24+RECURSOS!S41*RECURSOS!$C$25+RECURSOS!T41*RECURSOS!$C$26 | E13: =RECURSOS!P41*RECURSOS!$D$22+RECURSOS!Q41*RECURSOS!$D$23+RECURSOS!R41*RECURSOS!$D$24+RECURSOS!S41*RECURSOS!$D$25+RECURSOS!T41*RECURSOS!$D$26 | F13: =C13+D13+E13 | G13: =PARÂMETROS!I26 | H13: =G13/4.348 | I13: =F13*H13
A14: TOTAL | C14: =SUM(C3:C13) | D14: =SUM(D3:D13) | E14: =SUM(E3:E13) | F14: =SUM(F3:F13) | I14: =SUM(I3:I13)

Sheet ORÇAMENTO
A1: ORÇAMENTO — PREÇOS UNITÁRIOS E SUBTOTAIS (FÓRMULAS)
A2: Item ID | B2: Descrição | C2: Un. | D2: Quantitativo | E2: P.U. Diesel | F2: P.U. MO | G2: P.U. s/BDI | H2: P.U. c/BDI | I2: Subtotal s/BDI | J2: Subtotal c/BDI | K2: Δ Cronograma
A3: =PARÂMETROS!A16 | B3: =PARÂMETROS!B16 | C3: =PARÂMETROS!C16 | D3: =PARÂMETROS!D16 | E3: =PARÂMETROS!F16 | F3: =PARÂMETROS!G16 | G3: =E3+F3 | H3: =E3*(1+PARÂMETROS!$B$9)+F3*(1+PARÂMETROS!$B$10) | I3: =D3*G3 | J3: =D3*H3 | K3: (ver CRONOGRAMA)
A4: =PARÂMETROS!A17 | B4: =PARÂMETROS!B17 | C4: =PARÂMETROS!C17 | D4: =PARÂMETROS!D17 | E4: =PARÂMETROS!F17 | F4: =PARÂMETROS!G17 | G4: =E4+F4 | H4: =E4*(1+PARÂMETROS!$B$9)+F4*(1+PARÂMETROS!$B$10) | I4: =D4*G4 | J4: =D4*H4 | K4: (ver CRONOGRAMA)
A5: =PARÂMETROS!A18 | B5: =PARÂMETROS!B18 | C5: =PARÂMETROS!C18 | D5: =PARÂMETROS!D18 | E5: =PARÂMETROS!F18 | F5: =PARÂMETROS!G18 | G5: =E5+F5 | H5: =E5*(1+PARÂMETROS!$B$9)+F5*(1+PARÂMETROS!$B$10) | I5: =D5*G5 | J5: =D5*H5 | K5: (ver CRONOGRAMA)
A6: =PARÂMETROS!A19 | B6: =PARÂMETROS!B19 | C6: =PARÂMETROS!C19 | D6: =PARÂMETROS!D19 | E6: =PARÂMETROS!F19 | F6: =PARÂMETROS!G19 | G6: =E6+F6 | H6: =E6*(1+PARÂMETROS!$B$9)+F6*(1+PARÂMETROS!$B$10) | I6: =D6*G6 | J6: =D6*H6 | K6: (ver CRONOGRAMA)
A7: =PARÂMETROS!A20 | B7: =PARÂMETROS!B20 | C7: =PARÂMETROS!C20 | D7: =PARÂMETROS!D20 | E7: =PARÂMETROS!F20 | F7: =PARÂMETROS!G20 | G7: =E7+F7 | H7: =E7*(1+PARÂMETROS!$B$9)+F7*(1+PARÂMETROS!$B$10) | I7: =D7*G7 | J7: =D7*H7 | K7: (ver CRONOGRAMA)
A8: =PARÂMETROS!A21 | B8: =PARÂMETROS!B21 | C8: =PARÂMETROS!C21 | D8: =PARÂMETROS!D21 | E8: =PARÂMETROS!F21 | F8: =PARÂMETROS!G21 | G8: =E8+F8 | H8: =E8*(1+PARÂMETROS!$B$9)+F8*(1+PARÂMETROS!$B$10) | I8: =D8*G8 | J8: =D8*H8 | K8: (ver CRONOGRAMA)
A9: =PARÂMETROS!A22 | B9: =PARÂMETROS!B22 | C9: =PARÂMETROS!C22 | D9: =PARÂMETROS!D22 | E9: =PARÂMETROS!F22 | F9: =PARÂMETROS!G22 | G9: =E9+F9 | H9: =E9*(1+PARÂMETROS!$B$9)+F9*(1+PARÂMETROS!$B$10) | I9: =D9*G9 | J9: =D9*H9 | K9: (ver CRONOGRAMA)
A10: =PARÂMETROS!A23 | B10: =PARÂMETROS!B23 | C10: =PARÂMETROS!C23 | D10: =PARÂMETROS!D23 | E10: =PARÂMETROS!F23 | F10: =PARÂMETROS!G23 | G10: =E10+F10 | H10: =E10*(1+PARÂMETROS!$B$9)+F10*(1+PARÂMETROS!$B$10) | I10: =D10*G10 | J10: =D10*H10 | K10: (ver CRONOGRAMA)
A11: =PARÂMETROS!A24 | B11: =PARÂMETROS!B24 | C11: =PARÂMETROS!C24 | D11: =PARÂMETROS!D24 | E11: =PARÂMETROS!F24 | F11: =PARÂMETROS!G24 | G11: =E11+F11 | H11: =E11*(1+PARÂMETROS!$B$9)+F11*(1+PARÂMETROS!$B$10) | I11: =D11*G11 | J11: =D11*H11 | K11: (ver CRONOGRAMA)
A12: =PARÂMETROS!A25 | B12: =PARÂMETROS!B25 | C12: =PARÂMETROS!C25 | D12: =PARÂMETROS!D25 | E12: =PARÂMETROS!F25 | F12: =PARÂMETROS!G25 | G12: =E12+F12 | H12: =E12*(1+PARÂMETROS!$B$9)+F12*(1+PARÂMETROS!$B$10) | I12: =D12*G12 | J12: =D12*H12 | K12: (ver CRONOGRAMA)
A13: =PARÂMETROS!A26 | B13: =PARÂMETROS!B26 | C13: =PARÂMETROS!C26 | D13: =PARÂMETROS!D26 | E13: =PARÂMETROS!F26 | F13: =PARÂMETROS!G26 | G13: =E13+F13 | H13: =E13*(1+PARÂMETROS!$B$9)+F13*(1+PARÂMETROS!$B$10) | I13: =D13*G13 | J13: =D13*H13 | K13: (ver CRONOGRAMA)
A14: TOTAL | I14: =SUM(I3:I13) | J14: =SUM(J3:J13)

Sheet CRONOGRAMA
A1: CRONOGRAMA — PRODUÇÃO E COMPLETUDE (E×P×H×D×p_j)
A2: Item ID | B2: Descrição | C2: Qtd. planif. | D2: Qtd. prog. total | E2: Δ fech. (%) | F2: Métrica | G2: 2026-W2 | H2: 2026-W2 | I2: 2026-W2 | J2: 2026-W2 | K2: 2026-W2 | L2: 2026-W2 | M2: 2026-W3 | N2: 2026-W3 | O2: 2026-W3 | P2: 2026-W3 | Q2: 2026-W3 | R2: 2026-W3 | S2: 2026-W3 | T2: 2026-W3 | U2: 2026-W3 | V2: 2026-W3 | W2: 2026-W4 | X2: 2026-W4 | Y2: 2026-W4 | Z2: 2026-W4 | AA2: 2026-W4 | AB2: 2026-W4 | AC2: 2026-W4 | AD2: 2026-W4 | AE2: 2026-W4 | AF2: 2026-W4 | AG2: 2026-W5 | AH2: 2026-W5 | AI2: 2026-W5 | AJ2: 2026-W5 | AK2: 2027-W0 | AL2: 2027-W0 | AM2: 2027-W0 | AN2: 2027-W0 | AO2: 2027-W0 | AP2: 2027-W0 | AQ2: 2027-W0 | AR2: 2027-W0 | AS2: 2027-W0 | AT2: 2027-W1 | AU2: 2027-W1 | AV2: 2027-W1 | AW2: 2027-W1 | AX2: 2027-W1 | AY2: 2027-W1 | AZ2: 2027-W1 | BA2: 2027-W1 | BB2: 2027-W1 | BC2: 2027-W1 | BD2: 2027-W2 | BE2: 2027-W2 | BF2: 2027-W2
A3: Praticabilidade (p_j) | G3: =PARÂMETROS!$B$40 | H3: =PARÂMETROS!$B$41 | I3: =PARÂMETROS!$B$42 | J3: =PARÂMETROS!$B$43 | K3: =PARÂMETROS!$B$44 | L3: =PARÂMETROS!$B$45 | M3: =PARÂMETROS!$B$46 | N3: =PARÂMETROS!$B$47 | O3: =PARÂMETROS!$B$48 | P3: =PARÂMETROS!$B$49 | Q3: =PARÂMETROS!$B$50 | R3: =PARÂMETROS!$B$51 | S3: =PARÂMETROS!$B$52 | T3: =PARÂMETROS!$B$53 | U3: =PARÂMETROS!$B$54 | V3: =PARÂMETROS!$B$55 | W3: =PARÂMETROS!$B$56 | X3: =PARÂMETROS!$B$57 | Y3: =PARÂMETROS!$B$58 | Z3: =PARÂMETROS!$B$59 | AA3: =PARÂMETROS!$B$60 | AB3: =PARÂMETROS!$B$61 | AC3: =PARÂMETROS!$B$62 | AD3: =PARÂMETROS!$B$63 | AE3: =PARÂMETROS!$B$64 | AF3: =PARÂMETROS!$B$65 | AG3: =PARÂMETROS!$B$66 | AH3: =PARÂMETROS!$B$67 | AI3: =PARÂMETROS!$B$68 | AJ3: =PARÂMETROS!$B$69 | AK3: =PARÂMETROS!$B$70 | AL3: =PARÂMETROS!$B$71 | AM3: =PARÂMETROS!$B$72 | AN3: =PARÂMETROS!$B$73 | AO3: =PARÂMETROS!$B$74 | AP3: =PARÂMETROS!$B$75 | AQ3: =PARÂMETROS!$B$76 | AR3: =PARÂMETROS!$B$77 | AS3: =PARÂMETROS!$B$78 | AT3: =PARÂMETROS!$B$79 | AU3: =PARÂMETROS!$B$80 | AV3: =PARÂMETROS!$B$81 | AW3: =PARÂMETROS!$B$82 | AX3: =PARÂMETROS!$B$83 | AY3: =PARÂMETROS!$B$84 | AZ3: =PARÂMETROS!$B$85 | BA3: =PARÂMETROS!$B$86 | BB3: =PARÂMETROS!$B$87 | BC3: =PARÂMETROS!$B$88 | BD3: =PARÂMETROS!$B$89 | BE3: =PARÂMETROS!$B$90 | BF3: =PARÂMETROS!$B$91
A4: eap-1_0 | B4: Desmatamento e limpeza de | C4: =PARÂMETROS!D16 | D4: =SUM(G4:BF4) | E4: =IF(C4>0,(D4-C4)/C4,0) | F4: Produção semanal | G4: =IFERROR(PARÂMETROS!D95*PARÂMETROS!E16*PARÂMETROS!$B$4*PARÂMETROS!$B$5*PARÂMETROS!$B$40,0) | H4: =IFERROR(PARÂMETROS!E95*PARÂMETROS!E16*PARÂMETROS!$B$4*PARÂMETROS!$B$5*PARÂMETROS!$B$41,0) | I4: =IFERROR(PARÂMETROS!F95*PARÂMETROS!E16*PARÂMETROS!$B$4*PARÂMETROS!$B$5*PARÂMETROS!$B$42,0) | J4: =IFERROR(PARÂMETROS!G95*PARÂMETROS!E16*PARÂMETROS!$B$4*PARÂMETROS!$B$5*PARÂMETROS!$B$43,0) | K4: =IFERROR(PARÂMETROS!H95*PARÂMETROS!E16*PARÂMETROS!$B$4*PARÂMETROS!$B$5*PARÂMETROS!$B$44,0) | L4: =IFERROR(PARÂMETROS!I95*PARÂMETROS!E16*PARÂMETROS!$B$4*PARÂMETROS!$B$5*PARÂMETROS!$B$45,0) | M4: =IFERROR(PARÂMETROS!J95*PARÂMETROS!E16*PARÂMETROS!$B$4*PARÂMETROS!$B$5*PARÂMETROS!$B$46,0) | N4: =IFERROR(PARÂMETROS!K95*PARÂMETROS!E16*PARÂMETROS!$B$4*PARÂMETROS!$B$5*PARÂMETROS!$B$47,0) | O4: =IFERROR(PARÂMETROS!L95*PARÂMETROS!E16*PARÂMETROS!$B$4*PARÂMETROS!$B$5*PARÂMETROS!$B$48,0) | P4: =IFERROR(PARÂMETROS!M95*PARÂMETROS!E16*PARÂMETROS!$B$4*PARÂMETROS!$B$5*PARÂMETROS!$B$49,0) | Q4: =IFERROR(PARÂMETROS!N95*PARÂMETROS!E16*PARÂMETROS!$B$4*PARÂMETROS!$B$5*PARÂMETROS!$B$50,0) | R4: =IFERROR(PARÂMETROS!O95*PARÂMETROS!E16*PARÂMETROS!$B$4*PARÂMETROS!$B$5*PARÂMETROS!$B$51,0) | S4: =IFERROR(PARÂMETROS!P95*PARÂMETROS!E16*PARÂMETROS!$B$4*PARÂMETROS!$B$5*PARÂMETROS!$B$52,0) | T4: =IFERROR(PARÂMETROS!Q95*PARÂMETROS!E16*PARÂMETROS!$B$4*PARÂMETROS!$B$5*PARÂMETROS!$B$53,0) | U4: =IFERROR(PARÂMETROS!R95*PARÂMETROS!E16*PARÂMETROS!$B$4*PARÂMETROS!$B$5*PARÂMETROS!$B$54,0) | V4: =IFERROR(PARÂMETROS!S95*PARÂMETROS!E16*PARÂMETROS!$B$4*PARÂMETROS!$B$5*PARÂMETROS!$B$55,0) | W4: =IFERROR(PARÂMETROS!T95*PARÂMETROS!E16*PARÂMETROS!$B$4*PARÂMETROS!$B$5*PARÂMETROS!$B$56,0) | X4: =IFERROR(PARÂMETROS!U95*PARÂMETROS!E16*PARÂMETROS!$B$4*PARÂMETROS!$B$5*PARÂMETROS!$B$57,0) | Y4: =IFERROR(PARÂMETROS!V95*PARÂMETROS!E16*PARÂMETROS!$B$4*PARÂMETROS!$B$5*PARÂMETROS!$B$58,0) | Z4: =IFERROR(PARÂMETROS!W95*PARÂMETROS!E16*PARÂMETROS!$B$4*PARÂMETROS!$B$5*PARÂMETROS!$B$59,0) | AA4: =IFERROR(PARÂMETROS!X95*PARÂMETROS!E16*PARÂMETROS!$B$4*PARÂMETROS!$B$5*PARÂMETROS!$B$60,0) | AB4: =IFERROR(PARÂMETROS!Y95*PARÂMETROS!E16*PARÂMETROS!$B$4*PARÂMETROS!$B$5*PARÂMETROS!$B$61,0) | AC4: =IFERROR(PARÂMETROS!Z95*PARÂMETROS!E16*PARÂMETROS!$B$4*PARÂMETROS!$B$5*PARÂMETROS!$B$62,0) | AD4: =IFERROR(PARÂMETROS!AA95*PARÂMETROS!E16*PARÂMETROS!$B$4*PARÂMETROS!$B$5*PARÂMETROS!$B$63,0) | AE4: =IFERROR(PARÂMETROS!AB95*PARÂMETROS!E16*PARÂMETROS!$B$4*PARÂMETROS!$B$5*PARÂMETROS!$B$64,0) | AF4: =IFERROR(PARÂMETROS!AC95*PARÂMETROS!E16*PARÂMETROS!$B$4*PARÂMETROS!$B$5*PARÂMETROS!$B$65,0) | AG4: =IFERROR(PARÂMETROS!AD95*PARÂMETROS!E16*PARÂMETROS!$B$4*PARÂMETROS!$B$5*PARÂMETROS!$B$66,0) | AH4: =IFERROR(PARÂMETROS!AE95*PARÂMETROS!E16*PARÂMETROS!$B$4*PARÂMETROS!$B$5*PARÂMETROS!$B$67,0) | AI4: =IFERROR(PARÂMETROS!AF95*PARÂMETROS!E16*PARÂMETROS!$B$4*PARÂMETROS!$B$5*PARÂMETROS!$B$68,0) | AJ4: =IFERROR(PARÂMETROS!AG95*PARÂMETROS!E16*PARÂMETROS!$B$4*PARÂMETROS!$B$5*PARÂMETROS!$B$69,0) | AK4: =IFERROR(PARÂMETROS!AH95*PARÂMETROS!E16*PARÂMETROS!$B$4*PARÂMETROS!$B$5*PARÂMETROS!$B$70,0) | AL4: =IFERROR(PARÂMETROS!AI95*PARÂMETROS!E16*PARÂMETROS!$B$4*PARÂMETROS!$B$5*PARÂMETROS!$B$71,0) | AM4: =IFERROR(PARÂMETROS!AJ95*PARÂMETROS!E16*PARÂMETROS!$B$4*PARÂMETROS!$B$5*PARÂMETROS!$B$72,0) | AN4: =IFERROR(PARÂMETROS!AK95*PARÂMETROS!E16*PARÂMETROS!$B$4*PARÂMETROS!$B$5*PARÂMETROS!$B$73,0) | AO4: =IFERROR(PARÂMETROS!AL95*PARÂMETROS!E16*PARÂMETROS!$B$4*PARÂMETROS!$B$5*PARÂMETROS!$B$74,0) | AP4: =IFERROR(PARÂMETROS!AM95*PARÂMETROS!E16*PARÂMETROS!$B$4*PARÂMETROS!$B$5*PARÂMETROS!$B$75,0) | AQ4: =IFERROR(PARÂMETROS!AN95*PARÂMETROS!E16*PARÂMETROS!$B$4*PARÂMETROS!$B$5*PARÂMETROS!$B$76,0) | AR4: =IFERROR(PARÂMETROS!AO95*PARÂMETROS!E16*PARÂMETROS!$B$4*PARÂMETROS!$B$5*PARÂMETROS!$B$77,0) | AS4: =IFERROR(PARÂMETROS!AP95*PARÂMETROS!E16*PARÂMETROS!$B$4*PARÂMETROS!$B$5*PARÂMETROS!$B$78,0) | AT4: =IFERROR(PARÂMETROS!AQ95*PARÂMETROS!E16*PARÂMETROS!$B$4*PARÂMETROS!$B$5*PARÂMETROS!$B$79,0) | AU4: =IFERROR(PARÂMETROS!AR95*PARÂMETROS!E16*PARÂMETROS!$B$4*PARÂMETROS!$B$5*PARÂMETROS!$B$80,0) | AV4: =IFERROR(PARÂMETROS!AS95*PARÂMETROS!E16*PARÂMETROS!$B$4*PARÂMETROS!$B$5*PARÂMETROS!$B$81,0) | AW4: =IFERROR(PARÂMETROS!AT95*PARÂMETROS!E16*PARÂMETROS!$B$4*PARÂMETROS!$B$5*PARÂMETROS!$B$82,0) | AX4: =IFERROR(PARÂMETROS!AU95*PARÂMETROS!E16*PARÂMETROS!$B$4*PARÂMETROS!$B$5*PARÂMETROS!$B$83,0) | AY4: =IFERROR(PARÂMETROS!AV95*PARÂMETROS!E16*PARÂMETROS!$B$4*PARÂMETROS!$B$5*PARÂMETROS!$B$84,0) | AZ4: =IFERROR(PARÂMETROS!AW95*PARÂMETROS!E16*PARÂMETROS!$B$4*PARÂMETROS!$B$5*PARÂMETROS!$B$85,0) | BA4: =IFERROR(PARÂMETROS!AX95*PARÂMETROS!E16*PARÂMETROS!$B$4*PARÂMETROS!$B$5*PARÂMETROS!$B$86,0) | BB4: =IFERROR(PARÂMETROS!AY95*PARÂMETROS!E16*PARÂMETROS!$B$4*PARÂMETROS!$B$5*PARÂMETROS!$B$87,0) | BC4: =IFERROR(PARÂMETROS!AZ95*PARÂMETROS!E16*PARÂMETROS!$B$4*PARÂMETROS!$B$5*PARÂMETROS!$B$88,0) | BD4: =IFERROR(PARÂMETROS!BA95*PARÂMETROS!E16*PARÂMETROS!$B$4*PARÂMETROS!$B$5*PARÂMETROS!$B$89,0) | BE4: =IFERROR(PARÂMETROS!BB95*PARÂMETROS!E16*PARÂMETROS!$B$4*PARÂMETROS!$B$5*PARÂMETROS!$B$90,0) | BF4: =IFERROR(PARÂMETROS!BC95*PARÂMETROS!E16*PARÂMETROS!$B$4*PARÂMETROS!$B$5*PARÂMETROS!$B$91,0)
F5: Acumulado | G5: =G4 | H5: =G5+H4 | I5: =H5+I4 | J5: =I5+J4 | K5: =J5+K4 | L5: =K5+L4 | M5: =L5+M4 | N5: =M5+N4 | O5: =N5+O4 | ... BF5: =BE5+BF4
F6: % Completude | G6: =IF(PARÂMETROS!D16>0,G5/PARÂMETROS!D16,0) | H6: =IF(PARÂMETROS!D16>0,H5/PARÂMETROS!D16,0) | I6: =IF(PARÂMETROS!D16>0,I5/PARÂMETROS!D16,0) | J6: =IF(PARÂMETROS!D16>0,J5/PARÂMETROS!D16,0) | K6: =IF(PARÂMETROS!D16>0,K5/PARÂMETROS!D16,0) | L6: =IF(PARÂMETROS!D16>0,L5/PARÂMETROS!D16,0) | M6: =IF(PARÂMETROS!D16>0,M5/PARÂMETROS!D16,0) | N6: =IF(PARÂMETROS!D16>0,N5/PARÂMETROS!D16,0) | O6: =IF(PARÂMETROS!D16>0,O5/PARÂMETROS!D16,0) | P6: =IF(PARÂMETROS!D16>0,P5/PARÂMETROS!D16,0) | Q6: =IF(PARÂMETROS!D16>0,Q5/PARÂMETROS!D16,0) | R6: =IF(PARÂMETROS!D16>0,R5/PARÂMETROS!D16,0) | S6: =IF(PARÂMETROS!D16>0,S5/PARÂMETROS!D16,0) | T6: =IF(PARÂMETROS!D16>0,T5/PARÂMETROS!D16,0) | U6: =IF(PARÂMETROS!D16>0,U5/PARÂMETROS!D16,0) | V6: =IF(PARÂMETROS!D16>0,V5/PARÂMETROS!D16,0) | W6: =IF(PARÂMETROS!D16>0,W5/PARÂMETROS!D16,0) | X6: =IF(PARÂMETROS!D16>0,X5/PARÂMETROS!D16,0) | Y6: =IF(PARÂMETROS!D16>0,Y5/PARÂMETROS!D16,0) | Z6: =IF(PARÂMETROS!D16>0,Z5/PARÂMETROS!D16,0) | AA6: =IF(PARÂMETROS!D16>0,AA5/PARÂMETROS!D16,0) | AB6: =IF(PARÂMETROS!D16>0,AB5/PARÂMETROS!D16,0) | AC6: =IF(PARÂMETROS!D16>0,AC5/PARÂMETROS!D16,0) | AD6: =IF(PARÂMETROS!D16>0,AD5/PARÂMETROS!D16,0) | AE6: =IF(PARÂMETROS!D16>0,AE5/PARÂMETROS!D16,0) | AF6: =IF(PARÂMETROS!D16>0,AF5/PARÂMETROS!D16,0) | AG6: =IF(PARÂMETROS!D16>0,AG5/PARÂMETROS!D16,0) | AH6: =IF(PARÂMETROS!D16>0,AH5/PARÂMETROS!D16,0) | AI6: =IF(PARÂMETROS!D16>0,AI5/PARÂMETROS!D16,0) | AJ6: =IF(PARÂMETROS!D16>0,AJ5/PARÂMETROS!D16,0) | AK6: =IF(PARÂMETROS!D16>0,AK5/PARÂMETROS!D16,0) | AL6: =IF(PARÂMETROS!D16>0,AL5/PARÂMETROS!D16,0) | AM6: =IF(PARÂMETROS!D16>0,AM5/PARÂMETROS!D16,0) | AN6: =IF(PARÂMETROS!D16>0,AN5/PARÂMETROS!D16,0) | AO6: =IF(PARÂMETROS!D16>0,AO5/PARÂMETROS!D16,0) | AP6: =IF(PARÂMETROS!D16>0,AP5/PARÂMETROS!D16,0) | AQ6: =IF(PARÂMETROS!D16>0,AQ5/PARÂMETROS!D16,0) | AR6: =IF(PARÂMETROS!D16>0,AR5/PARÂMETROS!D16,0) | AS6: =IF(PARÂMETROS!D16>0,AS5/PARÂMETROS!D16,0) | AT6: =IF(PARÂMETROS!D16>0,AT5/PARÂMETROS!D16,0) | AU6: =IF(PARÂMETROS!D16>0,AU5/PARÂMETROS!D16,0) | AV6: =IF(PARÂMETROS!D16>0,AV5/PARÂMETROS!D16,0) | AW6: =IF(PARÂMETROS!D16>0,AW5/PARÂMETROS!D16,0) | AX6: =IF(PARÂMETROS!D16>0,AX5/PARÂMETROS!D16,0) | AY6: =IF(PARÂMETROS!D16>0,AY5/PARÂMETROS!D16,0) | AZ6: =IF(PARÂMETROS!D16>0,AZ5/PARÂMETROS!D16,0) | BA6: =IF(PARÂMETROS!D16>0,BA5/PARÂMETROS!D16,0) | BB6: =IF(PARÂMETROS!D16>0,BB5/PARÂMETROS!D16,0) | BC6: =IF(PARÂMETROS!D16>0,BC5/PARÂMETROS!D16,0) | BD6: =IF(PARÂMETROS!D16>0,BD5/PARÂMETROS!D16,0) | BE6: =IF(PARÂMETROS!D16>0,BE5/PARÂMETROS!D16,0) | BF6: =IF(PARÂMETROS!D16>0,BF5/PARÂMETROS!D16,0)
A7: eap-1_1 | B7: Esc/carg/transp 1aCat DMT | C7: =PARÂMETROS!D17 | D7: =SUM(G7:BF7) | E7: =IF(C7>0,(D7-C7)/C7,0) | F7: Produção semanal | G7: =IFERROR(PARÂMETROS!D96*PARÂMETROS!E17*PARÂMETROS!$B$4*PARÂMETROS!$B$5*PARÂMETROS!$B$40,0) | H7: =IFERROR(PARÂMETROS!E96*PARÂMETROS!E17*PARÂMETROS!$B$4*PARÂMETROS!$B$5*PARÂMETROS!$B$41,0) | I7: =IFERROR(PARÂMETROS!F96*PARÂMETROS!E17*PARÂMETROS!$B$4*PARÂMETROS!$B$5*PARÂMETROS!$B$42,0) | J7: =IFERROR(PARÂMETROS!G96*PARÂMETROS!E17*PARÂMETROS!$B$4*PARÂMETROS!$B$5*PARÂMETROS!$B$43,0) | K7: =IFERROR(PARÂMETROS!H96*PARÂMETROS!E17*PARÂMETROS!$B$4*PARÂMETROS!$B$5*PARÂMETROS!$B$44,0) | L7: =IFERROR(PARÂMETROS!I96*PARÂMETROS!E17*PARÂMETROS!$B$4*PARÂMETROS!$B$5*PARÂMETROS!$B$45,0) | M7: =IFERROR(PARÂMETROS!J96*PARÂMETROS!E17*PARÂMETROS!$B$4*PARÂMETROS!$B$5*PARÂMETROS!$B$46,0) | N7: =IFERROR(PARÂMETROS!K96*PARÂMETROS!E17*PARÂMETROS!$B$4*PARÂMETROS!$B$5*PARÂMETROS!$B$47,0) | O7: =IFERROR(PARÂMETROS!L96*PARÂMETROS!E17*PARÂMETROS!$B$4*PARÂMETROS!$B$5*PARÂMETROS!$B$48,0) | P7: =IFERROR(PARÂMETROS!M96*PARÂMETROS!E17*PARÂMETROS!$B$4*PARÂMETROS!$B$5*PARÂMETROS!$B$49,0) | Q7: =IFERROR(PARÂMETROS!N96*PARÂMETROS!E17*PARÂMETROS!$B$4*PARÂMETROS!$B$5*PARÂMETROS!$B$50,0) | R7: =IFERROR(PARÂMETROS!O96*PARÂMETROS!E17*PARÂMETROS!$B$4*PARÂMETROS!$B$5*PARÂMETROS!$B$51,0) | S7: =IFERROR(PARÂMETROS!P96*PARÂMETROS!E17*PARÂMETROS!$B$4*PARÂMETROS!$B$5*PARÂMETROS!$B$52,0) | T7: =IFERROR(PARÂMETROS!Q96*PARÂMETROS!E17*PARÂMETROS!$B$4*PARÂMETROS!$B$5*PARÂMETROS!$B$53,0) | U7: =IFERROR(PARÂMETROS!R96*PARÂMETROS!E17*PARÂMETROS!$B$4*PARÂMETROS!$B$5*PARÂMETROS!$B$54,0) | V7: =IFERROR(PARÂMETROS!S96*PARÂMETROS!E17*PARÂMETROS!$B$4*PARÂMETROS!$B$5*PARÂMETROS!$B$55,0) | W7: =IFERROR(PARÂMETROS!T96*PARÂMETROS!E17*PARÂMETROS!$B$4*PARÂMETROS!$B$5*PARÂMETROS!$B$56,0) | X7: =IFERROR(PARÂMETROS!U96*PARÂMETROS!E17*PARÂMETROS!$B$4*PARÂMETROS!$B$5*PARÂMETROS!$B$57,0) | Y7: =IFERROR(PARÂMETROS!V96*PARÂMETROS!E17*PARÂMETROS!$B$4*PARÂMETROS!$B$5*PARÂMETROS!$B$58,0) | Z7: =IFERROR(PARÂMETROS!W96*PARÂMETROS!E17*PARÂMETROS!$B$4*PARÂMETROS!$B$5*PARÂMETROS!$B$59,0) | AA7: =IFERROR(PARÂMETROS!X96*PARÂMETROS!E17*PARÂMETROS!$B$4*PARÂMETROS!$B$5*PARÂMETROS!$B$60,0) | AB7: =IFERROR(PARÂMETROS!Y96*PARÂMETROS!E17*PARÂMETROS!$B$4*PARÂMETROS!$B$5*PARÂMETROS!$B$61,0) | AC7: =IFERROR(PARÂMETROS!Z96*PARÂMETROS!E17*PARÂMETROS!$B$4*PARÂMETROS!$B$5*PARÂMETROS!$B$62,0) | AD7: =IFERROR(PARÂMETROS!AA96*PARÂMETROS!E17*PARÂMETROS!$B$4*PARÂMETROS!$B$5*PARÂMETROS!$B$63,0) | AE7: =IFERROR(PARÂMETROS!AB96*PARÂMETROS!E17*PARÂMETROS!$B$4*PARÂMETROS!$B$5*PARÂMETROS!$B$64,0) | AF7: =IFERROR(PARÂMETROS!AC96*PARÂMETROS!E17*PARÂMETROS!$B$4*PARÂMETROS!$B$5*PARÂMETROS!$B$65,0) | AG7: =IFERROR(PARÂMETROS!AD96*PARÂMETROS!E17*PARÂMETROS!$B$4*PARÂMETROS!$B$5*PARÂMETROS!$B$66,0) | AH7: =IFERROR(PARÂMETROS!AE96*PARÂMETROS!E17*PARÂMETROS!$B$4*PARÂMETROS!$B$5*PARÂMETROS!$B$67,0) | AI7: =IFERROR(PARÂMETROS!AF96*PARÂMETROS!E17*PARÂMETROS!$B$4*PARÂMETROS!$B$5*PARÂMETROS!$B$68,0) | AJ7: =IFERROR(PARÂMETROS!AG96*PARÂMETROS!E17*PARÂMETROS!$B$4*PARÂMETROS!$B$5*PARÂMETROS!$B$69,0) | AK7: =IFERROR(PARÂMETROS!AH96*PARÂMETROS!E17*PARÂMETROS!$B$4*PARÂMETROS!$B$5*PARÂMETROS!$B$70,0) | AL7: =IFERROR(PARÂMETROS!AI96*PARÂMETROS!E17*PARÂMETROS!$B$4*PARÂMETROS!$B$5*PARÂMETROS!$B$71,0) | AM7: =IFERROR(PARÂMETROS!AJ96*PARÂMETROS!E17*PARÂMETROS!$B$4*PARÂMETROS!$B$5*PARÂMETROS!$B$72,0) | AN7: =IFERROR(PARÂMETROS!AK96*PARÂMETROS!E17*PARÂMETROS!$B$4*PARÂMETROS!$B$5*PARÂMETROS!$B$73,0) | AO7: =IFERROR(PARÂMETROS!AL96*PARÂMETROS!E17*PARÂMETROS!$B$4*PARÂMETROS!$B$5*PARÂMETROS!$B$74,0) | AP7: =IFERROR(PARÂMETROS!AM96*PARÂMETROS!E17*PARÂMETROS!$B$4*PARÂMETROS!$B$5*PARÂMETROS!$B$75,0) | AQ7: =IFERROR(PARÂMETROS!AN96*PARÂMETROS!E17*PARÂMETROS!$B$4*PARÂMETROS!$B$5*PARÂMETROS!$B$76,0) | AR7: =IFERROR(PARÂMETROS!AO96*PARÂMETROS!E17*PARÂMETROS!$B$4*PARÂMETROS!$B$5*PARÂMETROS!$B$77,0) | AS7: =IFERROR(PARÂMETROS!AP96*PARÂMETROS!E17*PARÂMETROS!$B$4*PARÂMETROS!$B$5*PARÂMETROS!$B$78,0) | AT7: =IFERROR(PARÂMETROS!AQ96*PARÂMETROS!E17*PARÂMETROS!$B$4*PARÂMETROS!$B$5*PARÂMETROS!$B$79,0) | AU7: =IFERROR(PARÂMETROS!AR96*PARÂMETROS!E17*PARÂMETROS!$B$4*PARÂMETROS!$B$5*PARÂMETROS!$B$80,0) | AV7: =IFERROR(PARÂMETROS!AS96*PARÂMETROS!E17*PARÂMETROS!$B$4*PARÂMETROS!$B$5*PARÂMETROS!$B$81,0) | AW7: =IFERROR(PARÂMETROS!AT96*PARÂMETROS!E17*PARÂMETROS!$B$4*PARÂMETROS!$B$5*PARÂMETROS!$B$82,0) | AX7: =IFERROR(PARÂMETROS!AU96*PARÂMETROS!E17*PARÂMETROS!$B$4*PARÂMETROS!$B$5*PARÂMETROS!$B$83,0) | AY7: =IFERROR(PARÂMETROS!AV96*PARÂMETROS!E17*PARÂMETROS!$B$4*PARÂMETROS!$B$5*PARÂMETROS!$B$84,0) | AZ7: =IFERROR(PARÂMETROS!AW96*PARÂMETROS!E17*PARÂMETROS!$B$4*PARÂMETROS!$B$5*PARÂMETROS!$B$85,0) | BA7: =IFERROR(PARÂMETROS!AX96*PARÂMETROS!E17*PARÂMETROS!$B$4*PARÂMETROS!$B$5*PARÂMETROS!$B$86,0) | BB7: =IFERROR(PARÂMETROS!AY96*PARÂMETROS!E17*PARÂMETROS!$B$4*PARÂMETROS!$B$5*PARÂMETROS!$B$87,0) | BC7: =IFERROR(PARÂMETROS!AZ96*PARÂMETROS!E17*PARÂMETROS!$B$4*PARÂMETROS!$B$5*PARÂMETROS!$B$88,0) | BD7: =IFERROR(PARÂMETROS!BA96*PARÂMETROS!E17*PARÂMETROS!$B$4*PARÂMETROS!$B$5*PARÂMETROS!$B$89,0) | BE7: =IFERROR(PARÂMETROS!BB96*PARÂMETROS!E17*PARÂMETROS!$B$4*PARÂMETROS!$B$5*PARÂMETROS!$B$90,0) | BF7: =IFERROR(PARÂMETROS!BC96*PARÂMETROS!E17*PARÂMETROS!$B$4*PARÂMETROS!$B$5*PARÂMETROS!$B$91,0)
F8: Acumulado | G8: =G7 | H8: =G8+H7 | I8: =H8+I7 | J8: =I8+J7 | K8: =J8+K7 | L8: =K8+L7 | M8: =L8+M7 | N8: =M8+N7 | O8: =N8+O7 | ... BF8: =BE8+BF7
F9: % Completude | G9: =IF(PARÂMETROS!D17>0,G8/PARÂMETROS!D17,0) | H9: =IF(PARÂMETROS!D17>0,H8/PARÂMETROS!D17,0) | I9: =IF(PARÂMETROS!D17>0,I8/PARÂMETROS!D17,0) | J9: =IF(PARÂMETROS!D17>0,J8/PARÂMETROS!D17,0) | K9: =IF(PARÂMETROS!D17>0,K8/PARÂMETROS!D17,0) | L9: =IF(PARÂMETROS!D17>0,L8/PARÂMETROS!D17,0) | M9: =IF(PARÂMETROS!D17>0,M8/PARÂMETROS!D17,0) | N9: =IF(PARÂMETROS!D17>0,N8/PARÂMETROS!D17,0) | O9: =IF(PARÂMETROS!D17>0,O8/PARÂMETROS!D17,0) | P9: =IF(PARÂMETROS!D17>0,P8/PARÂMETROS!D17,0) | Q9: =IF(PARÂMETROS!D17>0,Q8/PARÂMETROS!D17,0) | R9: =IF(PARÂMETROS!D17>0,R8/PARÂMETROS!D17,0) | S9: =IF(PARÂMETROS!D17>0,S8/PARÂMETROS!D17,0) | T9: =IF(PARÂMETROS!D17>0,T8/PARÂMETROS!D17,0) | U9: =IF(PARÂMETROS!D17>0,U8/PARÂMETROS!D17,0) | V9: =IF(PARÂMETROS!D17>0,V8/PARÂMETROS!D17,0) | W9: =IF(PARÂMETROS!D17>0,W8/PARÂMETROS!D17,0) | X9: =IF(PARÂMETROS!D17>0,X8/PARÂMETROS!D17,0) | Y9: =IF(PARÂMETROS!D17>0,Y8/PARÂMETROS!D17,0) | Z9: =IF(PARÂMETROS!D17>0,Z8/PARÂMETROS!D17,0) | AA9: =IF(PARÂMETROS!D17>0,AA8/PARÂMETROS!D17,0) | AB9: =IF(PARÂMETROS!D17>0,AB8/PARÂMETROS!D17,0) | AC9: =IF(PARÂMETROS!D17>0,AC8/PARÂMETROS!D17,0) | AD9: =IF(PARÂMETROS!D17>0,AD8/PARÂMETROS!D17,0) | AE9: =IF(PARÂMETROS!D17>0,AE8/PARÂMETROS!D17,0) | AF9: =IF(PARÂMETROS!D17>0,AF8/PARÂMETROS!D17,0) | AG9: =IF(PARÂMETROS!D17>0,AG8/PARÂMETROS!D17,0) | AH9: =IF(PARÂMETROS!D17>0,AH8/PARÂMETROS!D17,0) | AI9: =IF(PARÂMETROS!D17>0,AI8/PARÂMETROS!D17,0) | AJ9: =IF(PARÂMETROS!D17>0,AJ8/PARÂMETROS!D17,0) | AK9: =IF(PARÂMETROS!D17>0,AK8/PARÂMETROS!D17,0) | AL9: =IF(PARÂMETROS!D17>0,AL8/PARÂMETROS!D17,0) | AM9: =IF(PARÂMETROS!D17>0,AM8/PARÂMETROS!D17,0) | AN9: =IF(PARÂMETROS!D17>0,AN8/PARÂMETROS!D17,0) | AO9: =IF(PARÂMETROS!D17>0,AO8/PARÂMETROS!D17,0) | AP9: =IF(PARÂMETROS!D17>0,AP8/PARÂMETROS!D17,0) | AQ9: =IF(PARÂMETROS!D17>0,AQ8/PARÂMETROS!D17,0) | AR9: =IF(PARÂMETROS!D17>0,AR8/PARÂMETROS!D17,0) | AS9: =IF(PARÂMETROS!D17>0,AS8/PARÂMETROS!D17,0) | AT9: =IF(PARÂMETROS!D17>0,AT8/PARÂMETROS!D17,0) | AU9: =IF(PARÂMETROS!D17>0,AU8/PARÂMETROS!D17,0) | AV9: =IF(PARÂMETROS!D17>0,AV8/PARÂMETROS!D17,0) | AW9: =IF(PARÂMETROS!D17>0,AW8/PARÂMETROS!D17,0) | AX9: =IF(PARÂMETROS!D17>0,AX8/PARÂMETROS!D17,0) | AY9: =IF(PARÂMETROS!D17>0,AY8/PARÂMETROS!D17,0) | AZ9: =IF(PARÂMETROS!D17>0,AZ8/PARÂMETROS!D17,0) | BA9: =IF(PARÂMETROS!D17>0,BA8/PARÂMETROS!D17,0) | BB9: =IF(PARÂMETROS!D17>0,BB8/PARÂMETROS!D17,0) | BC9: =IF(PARÂMETROS!D17>0,BC8/PARÂMETROS!D17,0) | BD9: =IF(PARÂMETROS!D17>0,BD8/PARÂMETROS!D17,0) | BE9: =IF(PARÂMETROS!D17>0,BE8/PARÂMETROS!D17,0) | BF9: =IF(PARÂMETROS!D17>0,BF8/PARÂMETROS!D17,0)
A10: eap-1_2 | B10: Esc/carg/transp 1aCat DMT | C10: =PARÂMETROS!D18 | D10: =SUM(G10:BF10) | E10: =IF(C10>0,(D10-C10)/C10,0) | F10: Produção semanal | G10: =IFERROR(PARÂMETROS!D97*PARÂMETROS!E18*PARÂMETROS!$B$4*PARÂMETROS!$B$5*PARÂMETROS!$B$40,0) | H10: =IFERROR(PARÂMETROS!E97*PARÂMETROS!E18*PARÂMETROS!$B$4*PARÂMETROS!$B$5*PARÂMETROS!$B$41,0) | I10: =IFERROR(PARÂMETROS!F97*PARÂMETROS!E18*PARÂMETROS!$B$4*PARÂMETROS!$B$5*PARÂMETROS!$B$42,0) | J10: =IFERROR(PARÂMETROS!G97*PARÂMETROS!E18*PARÂMETROS!$B$4*PARÂMETROS!$B$5*PARÂMETROS!$B$43,0) | K10: =IFERROR(PARÂMETROS!H97*PARÂMETROS!E18*PARÂMETROS!$B$4*PARÂMETROS!$B$5*PARÂMETROS!$B$44,0) | L10: =IFERROR(PARÂMETROS!I97*PARÂMETROS!E18*PARÂMETROS!$B$4*PARÂMETROS!$B$5*PARÂMETROS!$B$45,0) | M10: =IFERROR(PARÂMETROS!J97*PARÂMETROS!E18*PARÂMETROS!$B$4*PARÂMETROS!$B$5*PARÂMETROS!$B$46,0) | N10: =IFERROR(PARÂMETROS!K97*PARÂMETROS!E18*PARÂMETROS!$B$4*PARÂMETROS!$B$5*PARÂMETROS!$B$47,0) | O10: =IFERROR(PARÂMETROS!L97*PARÂMETROS!E18*PARÂMETROS!$B$4*PARÂMETROS!$B$5*PARÂMETROS!$B$48,0) | P10: =IFERROR(PARÂMETROS!M97*PARÂMETROS!E18*PARÂMETROS!$B$4*PARÂMETROS!$B$5*PARÂMETROS!$B$49,0) | Q10: =IFERROR(PARÂMETROS!N97*PARÂMETROS!E18*PARÂMETROS!$B$4*PARÂMETROS!$B$5*PARÂMETROS!$B$50,0) | R10: =IFERROR(PARÂMETROS!O97*PARÂMETROS!E18*PARÂMETROS!$B$4*PARÂMETROS!$B$5*PARÂMETROS!$B$51,0) | S10: =IFERROR(PARÂMETROS!P97*PARÂMETROS!E18*PARÂMETROS!$B$4*PARÂMETROS!$B$5*PARÂMETROS!$B$52,0) | T10: =IFERROR(PARÂMETROS!Q97*PARÂMETROS!E18*PARÂMETROS!$B$4*PARÂMETROS!$B$5*PARÂMETROS!$B$53,0) | U10: =IFERROR(PARÂMETROS!R97*PARÂMETROS!E18*PARÂMETROS!$B$4*PARÂMETROS!$B$5*PARÂMETROS!$B$54,0) | V10: =IFERROR(PARÂMETROS!S97*PARÂMETROS!E18*PARÂMETROS!$B$4*PARÂMETROS!$B$5*PARÂMETROS!$B$55,0) | W10: =IFERROR(PARÂMETROS!T97*PARÂMETROS!E18*PARÂMETROS!$B$4*PARÂMETROS!$B$5*PARÂMETROS!$B$56,0) | X10: =IFERROR(PARÂMETROS!U97*PARÂMETROS!E18*PARÂMETROS!$B$4*PARÂMETROS!$B$5*PARÂMETROS!$B$57,0) | Y10: =IFERROR(PARÂMETROS!V97*PARÂMETROS!E18*PARÂMETROS!$B$4*PARÂMETROS!$B$5*PARÂMETROS!$B$58,0) | Z10: =IFERROR(PARÂMETROS!W97*PARÂMETROS!E18*PARÂMETROS!$B$4*PARÂMETROS!$B$5*PARÂMETROS!$B$59,0) | AA10: =IFERROR(PARÂMETROS!X97*PARÂMETROS!E18*PARÂMETROS!$B$4*PARÂMETROS!$B$5*PARÂMETROS!$B$60,0) | AB10: =IFERROR(PARÂMETROS!Y97*PARÂMETROS!E18*PARÂMETROS!$B$4*PARÂMETROS!$B$5*PARÂMETROS!$B$61,0) | AC10: =IFERROR(PARÂMETROS!Z97*PARÂMETROS!E18*PARÂMETROS!$B$4*PARÂMETROS!$B$5*PARÂMETROS!$B$62,0) | AD10: =IFERROR(PARÂMETROS!AA97*PARÂMETROS!E18*PARÂMETROS!$B$4*PARÂMETROS!$B$5*PARÂMETROS!$B$63,0) | AE10: =IFERROR(PARÂMETROS!AB97*PARÂMETROS!E18*PARÂMETROS!$B$4*PARÂMETROS!$B$5*PARÂMETROS!$B$64,0) | AF10: =IFERROR(PARÂMETROS!AC97*PARÂMETROS!E18*PARÂMETROS!$B$4*PARÂMETROS!$B$5*PARÂMETROS!$B$65,0) | AG10: =IFERROR(PARÂMETROS!AD97*PARÂMETROS!E18*PARÂMETROS!$B$4*PARÂMETROS!$B$5*PARÂMETROS!$B$66,0) | AH10: =IFERROR(PARÂMETROS!AE97*PARÂMETROS!E18*PARÂMETROS!$B$4*PARÂMETROS!$B$5*PARÂMETROS!$B$67,0) | AI10: =IFERROR(PARÂMETROS!AF97*PARÂMETROS!E18*PARÂMETROS!$B$4*PARÂMETROS!$B$5*PARÂMETROS!$B$68,0) | AJ10: =IFERROR(PARÂMETROS!AG97*PARÂMETROS!E18*PARÂMETROS!$B$4*PARÂMETROS!$B$5*PARÂMETROS!$B$69,0) | AK10: =IFERROR(PARÂMETROS!AH97*PARÂMETROS!E18*PARÂMETROS!$B$4*PARÂMETROS!$B$5*PARÂMETROS!$B$70,0) | AL10: =IFERROR(PARÂMETROS!AI97*PARÂMETROS!E18*PARÂMETROS!$B$4*PARÂMETROS!$B$5*PARÂMETROS!$B$71,0) | AM10: =IFERROR(PARÂMETROS!AJ97*PARÂMETROS!E18*PARÂMETROS!$B$4*PARÂMETROS!$B$5*PARÂMETROS!$B$72,0) | AN10: =IFERROR(PARÂMETROS!AK97*PARÂMETROS!E18*PARÂMETROS!$B$4*PARÂMETROS!$B$5*PARÂMETROS!$B$73,0) | AO10: =IFERROR(PARÂMETROS!AL97*PARÂMETROS!E18*PARÂMETROS!$B$4*PARÂMETROS!$B$5*PARÂMETROS!$B$74,0) | AP10: =IFERROR(PARÂMETROS!AM97*PARÂMETROS!E18*PARÂMETROS!$B$4*PARÂMETROS!$B$5*PARÂMETROS!$B$75,0) | AQ10: =IFERROR(PARÂMETROS!AN97*PARÂMETROS!E18*PARÂMETROS!$B$4*PARÂMETROS!$B$5*PARÂMETROS!$B$76,0) | AR10: =IFERROR(PARÂMETROS!AO97*PARÂMETROS!E18*PARÂMETROS!$B$4*PARÂMETROS!$B$5*PARÂMETROS!$B$77,0) | AS10: =IFERROR(PARÂMETROS!AP97*PARÂMETROS!E18*PARÂMETROS!$B$4*PARÂMETROS!$B$5*PARÂMETROS!$B$78,0) | AT10: =IFERROR(PARÂMETROS!AQ97*PARÂMETROS!E18*PARÂMETROS!$B$4*PARÂMETROS!$B$5*PARÂMETROS!$B$79,0) | AU10: =IFERROR(PARÂMETROS!AR97*PARÂMETROS!E18*PARÂMETROS!$B$4*PARÂMETROS!$B$5*PARÂMETROS!$B$80,0) | AV10: =IFERROR(PARÂMETROS!AS97*PARÂMETROS!E18*PARÂMETROS!$B$4*PARÂMETROS!$B$5*PARÂMETROS!$B$81,0) | AW10: =IFERROR(PARÂMETROS!AT97*PARÂMETROS!E18*PARÂMETROS!$B$4*PARÂMETROS!$B$5*PARÂMETROS!$B$82,0) | AX10: =IFERROR(PARÂMETROS!AU97*PARÂMETROS!E18*PARÂMETROS!$B$4*PARÂMETROS!$B$5*PARÂMETROS!$B$83,0) | AY10: =IFERROR(PARÂMETROS!AV97*PARÂMETROS!E18*PARÂMETROS!$B$4*PARÂMETROS!$B$5*PARÂMETROS!$B$84,0) | AZ10: =IFERROR(PARÂMETROS!AW97*PARÂMETROS!E18*PARÂMETROS!$B$4*PARÂMETROS!$B$5*PARÂMETROS!$B$85,0) | BA10: =IFERROR(PARÂMETROS!AX97*PARÂMETROS!E18*PARÂMETROS!$B$4*PARÂMETROS!$B$5*PARÂMETROS!$B$86,0) | BB10: =IFERROR(PARÂMETROS!AY97*PARÂMETROS!E18*PARÂMETROS!$B$4*PARÂMETROS!$B$5*PARÂMETROS!$B$87,0) | BC10: =IFERROR(PARÂMETROS!AZ97*PARÂMETROS!E18*PARÂMETROS!$B$4*PARÂMETROS!$B$5*PARÂMETROS!$B$88,0) | BD10: =IFERROR(PARÂMETROS!BA97*PARÂMETROS!E18*PARÂMETROS!$B$4*PARÂMETROS!$B$5*PARÂMETROS!$B$89,0) | BE10: =IFERROR(PARÂMETROS!BB97*PARÂMETROS!E18*PARÂMETROS!$B$4*PARÂMETROS!$B$5*PARÂMETROS!$B$90,0) | BF10: =IFERROR(PARÂMETROS!BC97*PARÂMETROS!E18*PARÂMETROS!$B$4*PARÂMETROS!$B$5*PARÂMETROS!$B$91,0)
F11: Acumulado | G11: =G10 | H11: =G11+H10 | I11: =H11+I10 | J11: =I11+J10 | K11: =J11+K10 | L11: =K11+L10 | M11: =L11+M10 | N11: =M11+N10 | O11: =N11+O10 | ... BF11: =BE11+BF10
F12: % Completude | G12: =IF(PARÂMETROS!D18>0,G11/PARÂMETROS!D18,0) | H12: =IF(PARÂMETROS!D18>0,H11/PARÂMETROS!D18,0) | I12: =IF(PARÂMETROS!D18>0,I11/PARÂMETROS!D18,0) | J12: =IF(PARÂMETROS!D18>0,J11/PARÂMETROS!D18,0) | K12: =IF(PARÂMETROS!D18>0,K11/PARÂMETROS!D18,0) | L12: =IF(PARÂMETROS!D18>0,L11/PARÂMETROS!D18,0) | M12: =IF(PARÂMETROS!D18>0,M11/PARÂMETROS!D18,0) | N12: =IF(PARÂMETROS!D18>0,N11/PARÂMETROS!D18,0) | O12: =IF(PARÂMETROS!D18>0,O11/PARÂMETROS!D18,0) | P12: =IF(PARÂMETROS!D18>0,P11/PARÂMETROS!D18,0) | Q12: =IF(PARÂMETROS!D18>0,Q11/PARÂMETROS!D18,0) | R12: =IF(PARÂMETROS!D18>0,R11/PARÂMETROS!D18,0) | S12: =IF(PARÂMETROS!D18>0,S11/PARÂMETROS!D18,0) | T12: =IF(PARÂMETROS!D18>0,T11/PARÂMETROS!D18,0) | U12: =IF(PARÂMETROS!D18>0,U11/PARÂMETROS!D18,0) | V12: =IF(PARÂMETROS!D18>0,V11/PARÂMETROS!D18,0) | W12: =IF(PARÂMETROS!D18>0,W11/PARÂMETROS!D18,0) | X12: =IF(PARÂMETROS!D18>0,X11/PARÂMETROS!D18,0) | Y12: =IF(PARÂMETROS!D18>0,Y11/PARÂMETROS!D18,0) | Z12: =IF(PARÂMETROS!D18>0,Z11/PARÂMETROS!D18,0) | AA12: =IF(PARÂMETROS!D18>0,AA11/PARÂMETROS!D18,0) | AB12: =IF(PARÂMETROS!D18>0,AB11/PARÂMETROS!D18,0) | AC12: =IF(PARÂMETROS!D18>0,AC11/PARÂMETROS!D18,0) | AD12: =IF(PARÂMETROS!D18>0,AD11/PARÂMETROS!D18,0) | AE12: =IF(PARÂMETROS!D18>0,AE11/PARÂMETROS!D18,0) | AF12: =IF(PARÂMETROS!D18>0,AF11/PARÂMETROS!D18,0) | AG12: =IF(PARÂMETROS!D18>0,AG11/PARÂMETROS!D18,0) | AH12: =IF(PARÂMETROS!D18>0,AH11/PARÂMETROS!D18,0) | AI12: =IF(PARÂMETROS!D18>0,AI11/PARÂMETROS!D18,0) | AJ12: =IF(PARÂMETROS!D18>0,AJ11/PARÂMETROS!D18,0) | AK12: =IF(PARÂMETROS!D18>0,AK11/PARÂMETROS!D18,0) | AL12: =IF(PARÂMETROS!D18>0,AL11/PARÂMETROS!D18,0) | AM12: =IF(PARÂMETROS!D18>0,AM11/PARÂMETROS!D18,0) | AN12: =IF(PARÂMETROS!D18>0,AN11/PARÂMETROS!D18,0) | AO12: =IF(PARÂMETROS!D18>0,AO11/PARÂMETROS!D18,0) | AP12: =IF(PARÂMETROS!D18>0,AP11/PARÂMETROS!D18,0) | AQ12: =IF(PARÂMETROS!D18>0,AQ11/PARÂMETROS!D18,0) | AR12: =IF(PARÂMETROS!D18>0,AR11/PARÂMETROS!D18,0) | AS12: =IF(PARÂMETROS!D18>0,AS11/PARÂMETROS!D18,0) | AT12: =IF(PARÂMETROS!D18>0,AT11/PARÂMETROS!D18,0) | AU12: =IF(PARÂMETROS!D18>0,AU11/PARÂMETROS!D18,0) | AV12: =IF(PARÂMETROS!D18>0,AV11/PARÂMETROS!D18,0) | AW12: =IF(PARÂMETROS!D18>0,AW11/PARÂMETROS!D18,0) | AX12: =IF(PARÂMETROS!D18>0,AX11/PARÂMETROS!D18,0) | AY12: =IF(PARÂMETROS!D18>0,AY11/PARÂMETROS!D18,0) | AZ12: =IF(PARÂMETROS!D18>0,AZ11/PARÂMETROS!D18,0) | BA12: =IF(PARÂMETROS!D18>0,BA11/PARÂMETROS!D18,0) | BB12: =IF(PARÂMETROS!D18>0,BB11/PARÂMETROS!D18,0) | BC12: =IF(PARÂMETROS!D18>0,BC11/PARÂMETROS!D18,0) | BD12: =IF(PARÂMETROS!D18>0,BD11/PARÂMETROS!D18,0) | BE12: =IF(PARÂMETROS!D18>0,BE11/PARÂMETROS!D18,0) | BF12: =IF(PARÂMETROS!D18>0,BF11/PARÂMETROS!D18,0)
A13: eap-1_3 | B13: Esc/carg/transp 2aCat DMT | C13: =PARÂMETROS!D19 | D13: =SUM(G13:BF13) | E13: =IF(C13>0,(D13-C13)/C13,0) | F13: Produção semanal | G13: =IFERROR(PARÂMETROS!D98*PARÂMETROS!E19*PARÂMETROS!$B$4*PARÂMETROS!$B$5*PARÂMETROS!$B$40,0) | H13: =IFERROR(PARÂMETROS!E98*PARÂMETROS!E19*PARÂMETROS!$B$4*PARÂMETROS!$B$5*PARÂMETROS!$B$41,0) | I13: =IFERROR(PARÂMETROS!F98*PARÂMETROS!E19*PARÂMETROS!$B$4*PARÂMETROS!$B$5*PARÂMETROS!$B$42,0) | J13: =IFERROR(PARÂMETROS!G98*PARÂMETROS!E19*PARÂMETROS!$B$4*PARÂMETROS!$B$5*PARÂMETROS!$B$43,0) | K13: =IFERROR(PARÂMETROS!H98*PARÂMETROS!E19*PARÂMETROS!$B$4*PARÂMETROS!$B$5*PARÂMETROS!$B$44,0) | L13: =IFERROR(PARÂMETROS!I98*PARÂMETROS!E19*PARÂMETROS!$B$4*PARÂMETROS!$B$5*PARÂMETROS!$B$45,0) | M13: =IFERROR(PARÂMETROS!J98*PARÂMETROS!E19*PARÂMETROS!$B$4*PARÂMETROS!$B$5*PARÂMETROS!$B$46,0) | N13: =IFERROR(PARÂMETROS!K98*PARÂMETROS!E19*PARÂMETROS!$B$4*PARÂMETROS!$B$5*PARÂMETROS!$B$47,0) | O13: =IFERROR(PARÂMETROS!L98*PARÂMETROS!E19*PARÂMETROS!$B$4*PARÂMETROS!$B$5*PARÂMETROS!$B$48,0) | P13: =IFERROR(PARÂMETROS!M98*PARÂMETROS!E19*PARÂMETROS!$B$4*PARÂMETROS!$B$5*PARÂMETROS!$B$49,0) | Q13: =IFERROR(PARÂMETROS!N98*PARÂMETROS!E19*PARÂMETROS!$B$4*PARÂMETROS!$B$5*PARÂMETROS!$B$50,0) | R13: =IFERROR(PARÂMETROS!O98*PARÂMETROS!E19*PARÂMETROS!$B$4*PARÂMETROS!$B$5*PARÂMETROS!$B$51,0) | S13: =IFERROR(PARÂMETROS!P98*PARÂMETROS!E19*PARÂMETROS!$B$4*PARÂMETROS!$B$5*PARÂMETROS!$B$52,0) | T13: =IFERROR(PARÂMETROS!Q98*PARÂMETROS!E19*PARÂMETROS!$B$4*PARÂMETROS!$B$5*PARÂMETROS!$B$53,0) | U13: =IFERROR(PARÂMETROS!R98*PARÂMETROS!E19*PARÂMETROS!$B$4*PARÂMETROS!$B$5*PARÂMETROS!$B$54,0) | V13: =IFERROR(PARÂMETROS!S98*PARÂMETROS!E19*PARÂMETROS!$B$4*PARÂMETROS!$B$5*PARÂMETROS!$B$55,0) | W13: =IFERROR(PARÂMETROS!T98*PARÂMETROS!E19*PARÂMETROS!$B$4*PARÂMETROS!$B$5*PARÂMETROS!$B$56,0) | X13: =IFERROR(PARÂMETROS!U98*PARÂMETROS!E19*PARÂMETROS!$B$4*PARÂMETROS!$B$5*PARÂMETROS!$B$57,0) | Y13: =IFERROR(PARÂMETROS!V98*PARÂMETROS!E19*PARÂMETROS!$B$4*PARÂMETROS!$B$5*PARÂMETROS!$B$58,0) | Z13: =IFERROR(PARÂMETROS!W98*PARÂMETROS!E19*PARÂMETROS!$B$4*PARÂMETROS!$B$5*PARÂMETROS!$B$59,0) | AA13: =IFERROR(PARÂMETROS!X98*PARÂMETROS!E19*PARÂMETROS!$B$4*PARÂMETROS!$B$5*PARÂMETROS!$B$60,0) | AB13: =IFERROR(PARÂMETROS!Y98*PARÂMETROS!E19*PARÂMETROS!$B$4*PARÂMETROS!$B$5*PARÂMETROS!$B$61,0) | AC13: =IFERROR(PARÂMETROS!Z98*PARÂMETROS!E19*PARÂMETROS!$B$4*PARÂMETROS!$B$5*PARÂMETROS!$B$62,0) | AD13: =IFERROR(PARÂMETROS!AA98*PARÂMETROS!E19*PARÂMETROS!$B$4*PARÂMETROS!$B$5*PARÂMETROS!$B$63,0) | AE13: =IFERROR(PARÂMETROS!AB98*PARÂMETROS!E19*PARÂMETROS!$B$4*PARÂMETROS!$B$5*PARÂMETROS!$B$64,0) | AF13: =IFERROR(PARÂMETROS!AC98*PARÂMETROS!E19*PARÂMETROS!$B$4*PARÂMETROS!$B$5*PARÂMETROS!$B$65,0) | AG13: =IFERROR(PARÂMETROS!AD98*PARÂMETROS!E19*PARÂMETROS!$B$4*PARÂMETROS!$B$5*PARÂMETROS!$B$66,0) | AH13: =IFERROR(PARÂMETROS!AE98*PARÂMETROS!E19*PARÂMETROS!$B$4*PARÂMETROS!$B$5*PARÂMETROS!$B$67,0) | AI13: =IFERROR(PARÂMETROS!AF98*PARÂMETROS!E19*PARÂMETROS!$B$4*PARÂMETROS!$B$5*PARÂMETROS!$B$68,0) | AJ13: =IFERROR(PARÂMETROS!AG98*PARÂMETROS!E19*PARÂMETROS!$B$4*PARÂMETROS!$B$5*PARÂMETROS!$B$69,0) | AK13: =IFERROR(PARÂMETROS!AH98*PARÂMETROS!E19*PARÂMETROS!$B$4*PARÂMETROS!$B$5*PARÂMETROS!$B$70,0) | AL13: =IFERROR(PARÂMETROS!AI98*PARÂMETROS!E19*PARÂMETROS!$B$4*PARÂMETROS!$B$5*PARÂMETROS!$B$71,0) | AM13: =IFERROR(PARÂMETROS!AJ98*PARÂMETROS!E19*PARÂMETROS!$B$4*PARÂMETROS!$B$5*PARÂMETROS!$B$72,0) | AN13: =IFERROR(PARÂMETROS!AK98*PARÂMETROS!E19*PARÂMETROS!$B$4*PARÂMETROS!$B$5*PARÂMETROS!$B$73,0) | AO13: =IFERROR(PARÂMETROS!AL98*PARÂMETROS!E19*PARÂMETROS!$B$4*PARÂMETROS!$B$5*PARÂMETROS!$B$74,0) | AP13: =IFERROR(PARÂMETROS!AM98*PARÂMETROS!E19*PARÂMETROS!$B$4*PARÂMETROS!$B$5*PARÂMETROS!$B$75,0) | AQ13: =IFERROR(PARÂMETROS!AN98*PARÂMETROS!E19*PARÂMETROS!$B$4*PARÂMETROS!$B$5*PARÂMETROS!$B$76,0) | AR13: =IFERROR(PARÂMETROS!AO98*PARÂMETROS!E19*PARÂMETROS!$B$4*PARÂMETROS!$B$5*PARÂMETROS!$B$77,0) | AS13: =IFERROR(PARÂMETROS!AP98*PARÂMETROS!E19*PARÂMETROS!$B$4*PARÂMETROS!$B$5*PARÂMETROS!$B$78,0) | AT13: =IFERROR(PARÂMETROS!AQ98*PARÂMETROS!E19*PARÂMETROS!$B$4*PARÂMETROS!$B$5*PARÂMETROS!$B$79,0) | AU13: =IFERROR(PARÂMETROS!AR98*PARÂMETROS!E19*PARÂMETROS!$B$4*PARÂMETROS!$B$5*PARÂMETROS!$B$80,0) | AV13: =IFERROR(PARÂMETROS!AS98*PARÂMETROS!E19*PARÂMETROS!$B$4*PARÂMETROS!$B$5*PARÂMETROS!$B$81,0) | AW13: =IFERROR(PARÂMETROS!AT98*PARÂMETROS!E19*PARÂMETROS!$B$4*PARÂMETROS!$B$5*PARÂMETROS!$B$82,0) | AX13: =IFERROR(PARÂMETROS!AU98*PARÂMETROS!E19*PARÂMETROS!$B$4*PARÂMETROS!$B$5*PARÂMETROS!$B$83,0) | AY13: =IFERROR(PARÂMETROS!AV98*PARÂMETROS!E19*PARÂMETROS!$B$4*PARÂMETROS!$B$5*PARÂMETROS!$B$84,0) | AZ13: =IFERROR(PARÂMETROS!AW98*PARÂMETROS!E19*PARÂMETROS!$B$4*PARÂMETROS!$B$5*PARÂMETROS!$B$85,0) | BA13: =IFERROR(PARÂMETROS!AX98*PARÂMETROS!E19*PARÂMETROS!$B$4*PARÂMETROS!$B$5*PARÂMETROS!$B$86,0) | BB13: =IFERROR(PARÂMETROS!AY98*PARÂMETROS!E19*PARÂMETROS!$B$4*PARÂMETROS!$B$5*PARÂMETROS!$B$87,0) | BC13: =IFERROR(PARÂMETROS!AZ98*PARÂMETROS!E19*PARÂMETROS!$B$4*PARÂMETROS!$B$5*PARÂMETROS!$B$88,0) | BD13: =IFERROR(PARÂMETROS!BA98*PARÂMETROS!E19*PARÂMETROS!$B$4*PARÂMETROS!$B$5*PARÂMETROS!$B$89,0) | BE13: =IFERROR(PARÂMETROS!BB98*PARÂMETROS!E19*PARÂMETROS!$B$4*PARÂMETROS!$B$5*PARÂMETROS!$B$90,0) | BF13: =IFERROR(PARÂMETROS!BC98*PARÂMETROS!E19*PARÂMETROS!$B$4*PARÂMETROS!$B$5*PARÂMETROS!$B$91,0)
F14: Acumulado | G14: =G13 | H14: =G14+H13 | I14: =H14+I13 | J14: =I14+J13 | K14: =J14+K13 | L14: =K14+L13 | M14: =L14+M13 | N14: =M14+N13 | O14: =N14+O13 | ... BF14: =BE14+BF13
F15: % Completude | G15: =IF(PARÂMETROS!D19>0,G14/PARÂMETROS!D19,0) | H15: =IF(PARÂMETROS!D19>0,H14/PARÂMETROS!D19,0) | I15: =IF(PARÂMETROS!D19>0,I14/PARÂMETROS!D19,0) | J15: =IF(PARÂMETROS!D19>0,J14/PARÂMETROS!D19,0) | K15: =IF(PARÂMETROS!D19>0,K14/PARÂMETROS!D19,0) | L15: =IF(PARÂMETROS!D19>0,L14/PARÂMETROS!D19,0) | M15: =IF(PARÂMETROS!D19>0,M14/PARÂMETROS!D19,0) | N15: =IF(PARÂMETROS!D19>0,N14/PARÂMETROS!D19,0) | O15: =IF(PARÂMETROS!D19>0,O14/PARÂMETROS!D19,0) | P15: =IF(PARÂMETROS!D19>0,P14/PARÂMETROS!D19,0) | Q15: =IF(PARÂMETROS!D19>0,Q14/PARÂMETROS!D19,0) | R15: =IF(PARÂMETROS!D19>0,R14/PARÂMETROS!D19,0) | S15: =IF(PARÂMETROS!D19>0,S14/PARÂMETROS!D19,0) | T15: =IF(PARÂMETROS!D19>0,T14/PARÂMETROS!D19,0) | U15: =IF(PARÂMETROS!D19>0,U14/PARÂMETROS!D19,0) | V15: =IF(PARÂMETROS!D19>0,V14/PARÂMETROS!D19,0) | W15: =IF(PARÂMETROS!D19>0,W14/PARÂMETROS!D19,0) | X15: =IF(PARÂMETROS!D19>0,X14/PARÂMETROS!D19,0) | Y15: =IF(PARÂMETROS!D19>0,Y14/PARÂMETROS!D19,0) | Z15: =IF(PARÂMETROS!D19>0,Z14/PARÂMETROS!D19,0) | AA15: =IF(PARÂMETROS!D19>0,AA14/PARÂMETROS!D19,0) | AB15: =IF(PARÂMETROS!D19>0,AB14/PARÂMETROS!D19,0) | AC15: =IF(PARÂMETROS!D19>0,AC14/PARÂMETROS!D19,0) | AD15: =IF(PARÂMETROS!D19>0,AD14/PARÂMETROS!D19,0) | AE15: =IF(PARÂMETROS!D19>0,AE14/PARÂMETROS!D19,0) | AF15: =IF(PARÂMETROS!D19>0,AF14/PARÂMETROS!D19,0) | AG15: =IF(PARÂMETROS!D19>0,AG14/PARÂMETROS!D19,0) | AH15: =IF(PARÂMETROS!D19>0,AH14/PARÂMETROS!D19,0) | AI15: =IF(PARÂMETROS!D19>0,AI14/PARÂMETROS!D19,0) | AJ15: =IF(PARÂMETROS!D19>0,AJ14/PARÂMETROS!D19,0) | AK15: =IF(PARÂMETROS!D19>0,AK14/PARÂMETROS!D19,0) | AL15: =IF(PARÂMETROS!D19>0,AL14/PARÂMETROS!D19,0) | AM15: =IF(PARÂMETROS!D19>0,AM14/PARÂMETROS!D19,0) | AN15: =IF(PARÂMETROS!D19>0,AN14/PARÂMETROS!D19,0) | AO15: =IF(PARÂMETROS!D19>0,AO14/PARÂMETROS!D19,0) | AP15: =IF(PARÂMETROS!D19>0,AP14/PARÂMETROS!D19,0) | AQ15: =IF(PARÂMETROS!D19>0,AQ14/PARÂMETROS!D19,0) | AR15: =IF(PARÂMETROS!D19>0,AR14/PARÂMETROS!D19,0) | AS15: =IF(PARÂMETROS!D19>0,AS14/PARÂMETROS!D19,0) | AT15: =IF(PARÂMETROS!D19>0,AT14/PARÂMETROS!D19,0) | AU15: =IF(PARÂMETROS!D19>0,AU14/PARÂMETROS!D19,0) | AV15: =IF(PARÂMETROS!D19>0,AV14/PARÂMETROS!D19,0) | AW15: =IF(PARÂMETROS!D19>0,AW14/PARÂMETROS!D19,0) | AX15: =IF(PARÂMETROS!D19>0,AX14/PARÂMETROS!D19,0) | AY15: =IF(PARÂMETROS!D19>0,AY14/PARÂMETROS!D19,0) | AZ15: =IF(PARÂMETROS!D19>0,AZ14/PARÂMETROS!D19,0) | BA15: =IF(PARÂMETROS!D19>0,BA14/PARÂMETROS!D19,0) | BB15: =IF(PARÂMETROS!D19>0,BB14/PARÂMETROS!D19,0) | BC15: =IF(PARÂMETROS!D19>0,BC14/PARÂMETROS!D19,0) | BD15: =IF(PARÂMETROS!D19>0,BD14/PARÂMETROS!D19,0) | BE15: =IF(PARÂMETROS!D19>0,BE14/PARÂMETROS!D19,0) | BF15: =IF(PARÂMETROS!D19>0,BF14/PARÂMETROS!D19,0)
A16: eap-1_4 | B16: Esc/carg/transp 2aCat DMT | C16: =PARÂMETROS!D20 | D16: =SUM(G16:BF16) | E16: =IF(C16>0,(D16-C16)/C16,0) | F16: Produção semanal | G16: =IFERROR(PARÂMETROS!D99*PARÂMETROS!E20*PARÂMETROS!$B$4*PARÂMETROS!$B$5*PARÂMETROS!$B$40,0) | H16: =IFERROR(PARÂMETROS!E99*PARÂMETROS!E20*PARÂMETROS!$B$4*PARÂMETROS!$B$5*PARÂMETROS!$B$41,0) | I16: =IFERROR(PARÂMETROS!F99*PARÂMETROS!E20*PARÂMETROS!$B$4*PARÂMETROS!$B$5*PARÂMETROS!$B$42,0) | J16: =IFERROR(PARÂMETROS!G99*PARÂMETROS!E20*PARÂMETROS!$B$4*PARÂMETROS!$B$5*PARÂMETROS!$B$43,0) | K16: =IFERROR(PARÂMETROS!H99*PARÂMETROS!E20*PARÂMETROS!$B$4*PARÂMETROS!$B$5*PARÂMETROS!$B$44,0) | L16: =IFERROR(PARÂMETROS!I99*PARÂMETROS!E20*PARÂMETROS!$B$4*PARÂMETROS!$B$5*PARÂMETROS!$B$45,0) | M16: =IFERROR(PARÂMETROS!J99*PARÂMETROS!E20*PARÂMETROS!$B$4*PARÂMETROS!$B$5*PARÂMETROS!$B$46,0) | N16: =IFERROR(PARÂMETROS!K99*PARÂMETROS!E20*PARÂMETROS!$B$4*PARÂMETROS!$B$5*PARÂMETROS!$B$47,0) | O16: =IFERROR(PARÂMETROS!L99*PARÂMETROS!E20*PARÂMETROS!$B$4*PARÂMETROS!$B$5*PARÂMETROS!$B$48,0) | P16: =IFERROR(PARÂMETROS!M99*PARÂMETROS!E20*PARÂMETROS!$B$4*PARÂMETROS!$B$5*PARÂMETROS!$B$49,0) | Q16: =IFERROR(PARÂMETROS!N99*PARÂMETROS!E20*PARÂMETROS!$B$4*PARÂMETROS!$B$5*PARÂMETROS!$B$50,0) | R16: =IFERROR(PARÂMETROS!O99*PARÂMETROS!E20*PARÂMETROS!$B$4*PARÂMETROS!$B$5*PARÂMETROS!$B$51,0) | S16: =IFERROR(PARÂMETROS!P99*PARÂMETROS!E20*PARÂMETROS!$B$4*PARÂMETROS!$B$5*PARÂMETROS!$B$52,0) | T16: =IFERROR(PARÂMETROS!Q99*PARÂMETROS!E20*PARÂMETROS!$B$4*PARÂMETROS!$B$5*PARÂMETROS!$B$53,0) | U16: =IFERROR(PARÂMETROS!R99*PARÂMETROS!E20*PARÂMETROS!$B$4*PARÂMETROS!$B$5*PARÂMETROS!$B$54,0) | V16: =IFERROR(PARÂMETROS!S99*PARÂMETROS!E20*PARÂMETROS!$B$4*PARÂMETROS!$B$5*PARÂMETROS!$B$55,0) | W16: =IFERROR(PARÂMETROS!T99*PARÂMETROS!E20*PARÂMETROS!$B$4*PARÂMETROS!$B$5*PARÂMETROS!$B$56,0) | X16: =IFERROR(PARÂMETROS!U99*PARÂMETROS!E20*PARÂMETROS!$B$4*PARÂMETROS!$B$5*PARÂMETROS!$B$57,0) | Y16: =IFERROR(PARÂMETROS!V99*PARÂMETROS!E20*PARÂMETROS!$B$4*PARÂMETROS!$B$5*PARÂMETROS!$B$58,0) | Z16: =IFERROR(PARÂMETROS!W99*PARÂMETROS!E20*PARÂMETROS!$B$4*PARÂMETROS!$B$5*PARÂMETROS!$B$59,0) | AA16: =IFERROR(PARÂMETROS!X99*PARÂMETROS!E20*PARÂMETROS!$B$4*PARÂMETROS!$B$5*PARÂMETROS!$B$60,0) | AB16: =IFERROR(PARÂMETROS!Y99*PARÂMETROS!E20*PARÂMETROS!$B$4*PARÂMETROS!$B$5*PARÂMETROS!$B$61,0) | AC16: =IFERROR(PARÂMETROS!Z99*PARÂMETROS!E20*PARÂMETROS!$B$4*PARÂMETROS!$B$5*PARÂMETROS!$B$62,0) | AD16: =IFERROR(PARÂMETROS!AA99*PARÂMETROS!E20*PARÂMETROS!$B$4*PARÂMETROS!$B$5*PARÂMETROS!$B$63,0) | AE16: =IFERROR(PARÂMETROS!AB99*PARÂMETROS!E20*PARÂMETROS!$B$4*PARÂMETROS!$B$5*PARÂMETROS!$B$64,0) | AF16: =IFERROR(PARÂMETROS!AC99*PARÂMETROS!E20*PARÂMETROS!$B$4*PARÂMETROS!$B$5*PARÂMETROS!$B$65,0) | AG16: =IFERROR(PARÂMETROS!AD99*PARÂMETROS!E20*PARÂMETROS!$B$4*PARÂMETROS!$B$5*PARÂMETROS!$B$66,0) | AH16: =IFERROR(PARÂMETROS!AE99*PARÂMETROS!E20*PARÂMETROS!$B$4*PARÂMETROS!$B$5*PARÂMETROS!$B$67,0) | AI16: =IFERROR(PARÂMETROS!AF99*PARÂMETROS!E20*PARÂMETROS!$B$4*PARÂMETROS!$B$5*PARÂMETROS!$B$68,0) | AJ16: =IFERROR(PARÂMETROS!AG99*PARÂMETROS!E20*PARÂMETROS!$B$4*PARÂMETROS!$B$5*PARÂMETROS!$B$69,0) | AK16: =IFERROR(PARÂMETROS!AH99*PARÂMETROS!E20*PARÂMETROS!$B$4*PARÂMETROS!$B$5*PARÂMETROS!$B$70,0) | AL16: =IFERROR(PARÂMETROS!AI99*PARÂMETROS!E20*PARÂMETROS!$B$4*PARÂMETROS!$B$5*PARÂMETROS!$B$71,0) | AM16: =IFERROR(PARÂMETROS!AJ99*PARÂMETROS!E20*PARÂMETROS!$B$4*PARÂMETROS!$B$5*PARÂMETROS!$B$72,0) | AN16: =IFERROR(PARÂMETROS!AK99*PARÂMETROS!E20*PARÂMETROS!$B$4*PARÂMETROS!$B$5*PARÂMETROS!$B$73,0) | AO16: =IFERROR(PARÂMETROS!AL99*PARÂMETROS!E20*PARÂMETROS!$B$4*PARÂMETROS!$B$5*PARÂMETROS!$B$74,0) | AP16: =IFERROR(PARÂMETROS!AM99*PARÂMETROS!E20*PARÂMETROS!$B$4*PARÂMETROS!$B$5*PARÂMETROS!$B$75,0) | AQ16: =IFERROR(PARÂMETROS!AN99*PARÂMETROS!E20*PARÂMETROS!$B$4*PARÂMETROS!$B$5*PARÂMETROS!$B$76,0) | AR16: =IFERROR(PARÂMETROS!AO99*PARÂMETROS!E20*PARÂMETROS!$B$4*PARÂMETROS!$B$5*PARÂMETROS!$B$77,0) | AS16: =IFERROR(PARÂMETROS!AP99*PARÂMETROS!E20*PARÂMETROS!$B$4*PARÂMETROS!$B$5*PARÂMETROS!$B$78,0) | AT16: =IFERROR(PARÂMETROS!AQ99*PARÂMETROS!E20*PARÂMETROS!$B$4*PARÂMETROS!$B$5*PARÂMETROS!$B$79,0) | AU16: =IFERROR(PARÂMETROS!AR99*PARÂMETROS!E20*PARÂMETROS!$B$4*PARÂMETROS!$B$5*PARÂMETROS!$B$80,0) | AV16: =IFERROR(PARÂMETROS!AS99*PARÂMETROS!E20*PARÂMETROS!$B$4*PARÂMETROS!$B$5*PARÂMETROS!$B$81,0) | AW16: =IFERROR(PARÂMETROS!AT99*PARÂMETROS!E20*PARÂMETROS!$B$4*PARÂMETROS!$B$5*PARÂMETROS!$B$82,0) | AX16: =IFERROR(PARÂMETROS!AU99*PARÂMETROS!E20*PARÂMETROS!$B$4*PARÂMETROS!$B$5*PARÂMETROS!$B$83,0) | AY16: =IFERROR(PARÂMETROS!AV99*PARÂMETROS!E20*PARÂMETROS!$B$4*PARÂMETROS!$B$5*PARÂMETROS!$B$84,0) | AZ16: =IFERROR(PARÂMETROS!AW99*PARÂMETROS!E20*PARÂMETROS!$B$4*PARÂMETROS!$B$5*PARÂMETROS!$B$85,0) | BA16: =IFERROR(PARÂMETROS!AX99*PARÂMETROS!E20*PARÂMETROS!$B$4*PARÂMETROS!$B$5*PARÂMETROS!$B$86,0) | BB16: =IFERROR(PARÂMETROS!AY99*PARÂMETROS!E20*PARÂMETROS!$B$4*PARÂMETROS!$B$5*PARÂMETROS!$B$87,0) | BC16: =IFERROR(PARÂMETROS!AZ99*PARÂMETROS!E20*PARÂMETROS!$B$4*PARÂMETROS!$B$5*PARÂMETROS!$B$88,0) | BD16: =IFERROR(PARÂMETROS!BA99*PARÂMETROS!E20*PARÂMETROS!$B$4*PARÂMETROS!$B$5*PARÂMETROS!$B$89,0) | BE16: =IFERROR(PARÂMETROS!BB99*PARÂMETROS!E20*PARÂMETROS!$B$4*PARÂMETROS!$B$5*PARÂMETROS!$B$90,0) | BF16: =IFERROR(PARÂMETROS!BC99*PARÂMETROS!E20*PARÂMETROS!$B$4*PARÂMETROS!$B$5*PARÂMETROS!$B$91,0)
F17: Acumulado | G17: =G16 | H17: =G17+H16 | I17: =H17+I16 | J17: =I17+J16 | K17: =J17+K16 | L17: =K17+L16 | M17: =L17+M16 | N17: =M17+N16 | O17: =N17+O16 | ... BF17: =BE17+BF16
