Workbook
Name TOTAL_DIRETO: 'DIRETOS.DET'!$I$136
Name DIRETOS_RES_SEM_BDI: 'DIRETOS.RES'!$I$15
Name DIRETOS_RES_COM_BDI: 'DIRETOS.RES'!$N$15
Name TOTAL_ADM: 'INDIRETOS.DET'!$H$26
Name TOTAL_TOP: 'INDIRETOS.DET'!$H$32
Name TOTAL_LAB: 'INDIRETOS.DET'!$H$36
Name TOTAL_QSMS: 'INDIRETOS.DET'!$H$43
Name TOTAL_MOB: 'INDIRETOS.DET'!$H$46
Name TOTAL_INDIRETO: 'INDIRETOS.DET'!$H$48
Name TOTAL_SEM_BDI: PLANEJAMENTO!$M$15
Name TOTAL_COM_BDI: PLANEJAMENTO!$N$15

Sheet MEMORIAL.BDI
A1: MEMORIAL DE CALCULO BDI - AUDITORIA PONTA A PONTA (ADR-057)
A2: Projeto: AGIS - Ferrovia Nova Transnordestina (Supressao e Terraplanagem) | Gerado: 2026-06-01T23:08:44 | Regime: pre_reforma | Vigencia: 2026-04-01
A4: 1. ENCARGOS SOCIAIS - Grupos A-F + Judicial (vigencia abril/2026)
A5: Regime | B5: Grp A | C5: Grp B | D5: Grp C | E5: Grp D | F5: Grp E | G5: Grp F | H5: Judicial | I5: TOTAL
A6: Horista CLT | B6: 37.8 | C6: 47.84 | D6: 40.53 | E6: 19.07 | F6: 10.22 | G6: 19.24 | H6: 3 | I6: 177.7
A7: Mensalista CLT | B7: 37.8 | C7: 9.94 | D7: 40.3 | E7: 4.74 | F7: 10.22 | G7: 0 | H7: 3 | I7: 106
A8: Nota: encargos aplicados ANTES do BDI. Custo MO = Salario x (1 + Encargos)
A10: 2. BDI POR CATEGORIA - Formulacao TCU Ac.2622/2013: BDI=(1+OH)/(1-T)-1
A11: Categoria | B11: AC(%) | C11: DF(%) | D11: R(%) | E11: CR(%) | F11: L(%) | G11: OH(%) | H11: COFINS | I11: ISS | J11: PIS | K11: CSSL | L11: IR | M11: T(%) | N11: BDI(%)
A12: MAO DE OBRA [inputs.tabela_bdi] | B12: 5 | C12: 1.5 | D12: 1 | E12: 0 | F12: 9 | G12: 16.5 | H12: 0 | I12: 5 | J12: 0 | K12: 1.99 | L12: 2.74 | M12: 9.73 | N12: 29.975
A13: MATERIAL [inputs.tabela_bdi] | B13: 0 | C13: 0 | D13: 0 | E13: 0 | F13: 4 | G13: 4 | H13: 0 | I13: 0 | J13: 0 | K13: 0 | L13: 0 | M13: 0 | N13: 4
A14: SERVICOS [inputs.tabela_bdi] | B14: 5 | C14: 1.5 | D14: 1 | E14: 0 | F14: 9 | G14: 16.5 | H14: 0 | I14: 5 | J14: 0 | K14: 1.99 | L14: 2.74 | M14: 9.73 | N14: 29.975
A15: INDIRETO [inputs.tabela_bdi] | B15: 5 | C15: 1.5 | D15: 1 | E15: 0 | F15: 5 | G15: 12.5 | H15: 0 | I15: 5 | J15: 0 | K15: 1.99 | L15: 2.74 | M15: 9.73 | N15: 25.2053
A16: DIESEL [inputs.tabela_bdi] | B16: 0 | C16: 0 | D16: 0 | E16: 0 | F16: 4 | G16: 4 | H16: 0 | I16: 0 | J16: 0 | K16: 0 | L16: 0 | M16: 0 | N16: 4
A18: 3. DECOMPOSICAO NO PRECO DE VENDA - De cada R$1,00 cobrado
A19: Categoria | B19: Custo Dir. | C19: OH-AC | D19: OH-DF | E19: OH-R | F19: OH-CR | G19: Margem L | H19: COFINS | I19: ISS | J19: PIS | K19: CSSL | L19: IR | M19: T Total | N19: SOMA
A20: MAO DE OBRA | B20: 77.48 | C20: 3.87 | D20: 1.16 | E20: 0.77 | F20: 0 | G20: 6.97 | H20: 0 | I20: 5 | J20: 0 | K20: 1.99 | L20: 2.74 | M20: 9.73 | N20: 100
A21: MATERIAL | B21: 96.15 | C21: 0 | D21: 0 | E21: 0 | F21: 0 | G21: 3.85 | H21: 0 | I21: 0 | J21: 0 | K21: 0 | L21: 0 | M21: 0 | N21: 100
A22: SERVICOS | B22: 77.48 | C22: 3.87 | D22: 1.16 | E22: 0.77 | F22: 0 | G22: 6.97 | H22: 0 | I22: 5 | J22: 0 | K22: 1.99 | L22: 2.74 | M22: 9.73 | N22: 100
A23: INDIRETO | B23: 80.24 | C23: 4.01 | D23: 1.2 | E23: 0.8 | F23: 0 | G23: 4.01 | H23: 0 | I23: 5 | J23: 0 | K23: 1.99 | L23: 2.74 | M23: 9.73 | N23: 100
A24: DIESEL | B24: 96.15 | C24: 0 | D24: 0 | E24: 0 | F24: 0 | G24: 3.85 | H24: 0 | I24: 0 | J24: 0 | K24: 0 | L24: 0 | M24: 0 | N24: 100
A26: 4. APLICACAO POR ITEM DA EAP - BDI efetivo x preco unitario
A27: Item | B27: Descricao | C27: CPU | D27: Un. | E27: Qtd. | F27: PU s/BDI | G27: BDI(%) | H27: PU c/BDI | I27: Sub. s/BDI | J27: Sub. c/BDI | K27: MO (R$) | L27: EQ (R$) | M27: MAT (R$) | N27: DIESEL (R$)
A28: eap-1_0 | B28: Desmatamento e limpeza de area vegetada | C28: CPU-TERRA-ATI-003 | D28: m2 | E28: 2400000 | F28: 0.8767 | G28: 17.76 | H28: 1.0324 | I28: 2104003.2 | J28: 2477673.2 | K28: 0.1929 | L28: 0.3879 | M28: 0 | N28: 0.2959
A29: eap-1_1 | B29: Esc/carg/transp 1aCat DMT<=2000m | C29: CPU-TERRA-ESCO-CARGA-1CAT-DMT2000 | D29: m3 | E29: 107463.11 | F29: 7.6583 | G29: 20.59 | H29: 9.2349 | I29: 822980.08 | J29: 992406.46 | K29: 1.4918 | L29: 4.8551 | M29: 0 | N29: 1.3114
A30: eap-1_2 | B30: Esc/carg/transp 1aCat DMT<=3000m | C30: CPU-TERRA-ESCO-CARGA-1CAT-DMT3000 | D30: m3 | E30: 336915.09 | F30: 8.4612 | G30: 20.72 | H30: 10.2145 | I30: 2850705 | J30: 3441418.8 | K30: 1.663 | L30: 5.4057 | M30: 0 | N30: 1.3925
A31: eap-1_3 | B31: Esc/carg/transp 2aCat DMT<=2000m | C31: CPU-TERRA-ESCO-CARGA-2CAT-DMT2000 | D31: m3 | E31: 105311.33 | F31: 10.0939 | G31: 20.42 | H31: 12.1553 | I31: 1063003.6 | J31: 1280092 | K31: 1.9446 | L31: 6.3386 | M31: 0 | N31: 1.8107
A32: eap-1_4 | B32: Esc/carg/transp 2aCat DMT<=3000m | C32: CPU-TERRA-ESCO-CARGA-2CAT-DMT3000 | D32: m3 | E32: 585945.77 | F32: 10.7574 | G32: 20.53 | H32: 12.9657 | I32: 6303250.1 | J32: 7597204.5 | K32: 2.0873 | L32: 6.7969 | M32: 0 | N32: 1.8732
A33: eap-1_5 | B33: Esc/carg/transp 3aCat DMT<=2000m | C33: CPU-TERRA-ESCO-CARGA-3CAT-DMT2000 | D33: m3 | E33: 304634.46 | F33: 14.8713 | G33: 20.37 | H33: 17.9001 | I33: 4530306.1 | J33: 5452981.8 | K33: 2.0472 | L33: 10.4616 | M33: 0 | N33: 2.3625
A34: eap-1_6 | B34: Esc/carg/transp 3aCat DMT<=3000m | C34: CPU-TERRA-ESCO-CARGA-3CAT-DMT3000 | D34: m3 | E34: 676519.04 | F34: 18.2248 | G34: 20.61 | H34: 21.9805 | I34: 12329412 | J34: 14870247 | K34: 2.5128 | L34: 13.0568 | M34: 0 | N34: 2.6552
A35: eap-1_7 | B35: Compactacao aterros 100% Proctor Normal | C35: CPU-TERRA-COMPAC-PN | D35: m3 | E35: 1135635.3 | F35: 9.1313 | G35: 17.23 | H35: 10.7048 | I35: 10369820 | J35: 12156798 | K35: 1.647 | L35: 4.2925 | M35: 0 | N35: 3.1918
A36: eap-1_8 | B36: Compactacao aterros 100% Proctor Intermediario | C36: CPU-TERRA-COMPAC-PI | D36: m3 | E36: 29411 | F36: 11.9393 | G36: 17.23 | H36: 13.9967 | I36: 351146.05 | J36: 411657.26 | K36: 2.1535 | L36: 5.6125 | M36: 0 | N36: 4.1733
A37: eap-1_9 | B37: Construcao corpo aterro material 3a categoria | C37: CPU-TERRA-CORPO-ATERRO-3CAT | D37: m3 | E37: 981153.5 | F37: 5.873 | G37: 17 | H37: 6.8713 | I37: 5762268.4 | J37: 6741771.1 | K37: 0.9499 | L37: 2.8415 | M37: 0 | N37: 2.0815
A38: eap-1_10 | B38: Compactacao camada final aterro sobre rocha | C38: CPU-TERRA-COMPAC-FINAL-ROCHA | D38: m3 | E38: 24721.17 | F38: 14.4369 | G38: 16.31 | H38: 16.7922 | I38: 356897.06 | J38: 415123.69 | K38: 2.34 | L38: 6.435 | M38: 0 | N38: 5.6619

Sheet CURVA.ABC
A1: CURVA ABC POR INSUMO — ANALISE DE PARETO (80/20) — ADR-058
A2: Total custo direto: R$ 12,936,539.03 | Classe A: 17 itens (78.5%) | B: 9 | C: 13
A4: Insumo ID | B4: Descricao | C4: Categoria | D4: Custo Total (R$) | E4: % Custo | F4: % Acumulado | G4: Classe | H4: Atividades
A5: AGIS-FN-MOTOR-BASC | B5: Motorista de Caminhão Basculante | C5: MAO_OBRA | D5: 1918220.7 | E5: 14.8279 | F5: 14.8279 | G5: A | H5: eap-1_1, eap-1_2, eap-1_3, eap-1_4, eap-1_5
A6: AGIS-E0015 | B6: Escavadeira Hidráulica sobre esteira 38T | C6: EQUIPAMENTO | D6: 1181550.5 | E6: 9.1334 | F6: 23.9614 | G6: A | H6: eap-1_1, eap-1_2, eap-1_3, eap-1_4
A7: AGIS-E0016 | B7: Escavadeira Hidráulica sobre esteira 48T | C7: EQUIPAMENTO | D7: 928659.27 | E7: 7.1786 | F7: 31.1399 | G7: A | H7: eap-1_5, eap-1_6
A8: AGIS-E0015__DIESEL | B8: Diesel: Escavadeira Hidráulica sobre esteira 38T | C8: DIESEL | D8: 663554.41 | E8: 5.1293 | F8: 36.2692 | G8: A | H8: eap-1_1, eap-1_2, eap-1_3, eap-1_4
A9: AGIS-TRAT-EST-40T | B9: Trator de Esteiras 40T | C9: EQUIPAMENTO | D9: 632621.44 | E9: 4.8902 | F9: 41.1594 | G9: A | H9: eap-1_9
A10: AGIS-E0002 | B10: Caminhão Basculante 14 m³ | C10: EQUIPAMENTO | D10: 539181.46 | E10: 4.1679 | F10: 45.3273 | G10: A | H10: eap-1_1, eap-1_2, eap-1_3, eap-1_4
A11: AGIS-MOTON-140K | B11: Motoniveladora 140K | C11: EQUIPAMENTO | D11: 489621.79 | E11: 3.7848 | F11: 49.1121 | G11: A | H11: eap-1_7, eap-1_8
A12: AGIS-TRAT-EST-20T | B12: Trator de Esteiras 20T | C12: EQUIPAMENTO | D12: 482724 | E12: 3.7315 | F12: 52.8436 | G12: A | H12: eap-1_0, eap-1_10
A13: AGIS-E0004 | B13: Caminhão Basculante 14 m³ - Rochas | C13: EQUIPAMENTO | D13: 459184.88 | E13: 3.5495 | F13: 56.3931 | G13: A | H13: eap-1_5, eap-1_6
A14: AGIS-E0016__DIESEL | B14: Diesel: Escavadeira Hidráulica sobre esteira 48T | C14: DIESEL | D14: 431222.43 | E14: 3.3334 | F14: 59.7265 | G14: A | H14: eap-1_5, eap-1_6
A15: AGIS-ROLO-PC-10T | B15: Rolo Compactador Pé de Carneiro 10T | C15: EQUIPAMENTO | D15: 423016 | E15: 3.2699 | F15: 62.9964 | G15: A | H15: eap-1_10, eap-1_7, eap-1_8, eap-1_9
A16: AGIS-FN-OPER-ESCAV | B16: Operador de Escavadeira | C16: MAO_OBRA | D16: 367305.4 | E16: 2.8393 | F16: 65.8357 | G16: A | H16: eap-1_0, eap-1_1, eap-1_2, eap-1_3, eap-1_4
... A43: AGIS-MOTOSSERRA__DIESEL | B43: Diesel: Motosserra a Gasolina | C43: DIESEL | D43: 14960.75 | E43: 0.1156 | F43: 100 | G43: C | H43: eap-1_0

Sheet S-CURVE
A1: CURVA S — DESEMBOLSO ACUMULADO PLANEJADO (ADR-058)
A2: Total projeto: R$ 64,505,448.17 | Direto: R$ 47,225,529.25 | Indireto: R$ 17,279,918.92
A4: Semana ISO | B4: Equip. Unicos | C4: Equipes Total | D4: Custo Semana (R$) | E4: Custo Acum. (R$) | F4: % Acumulado | G4: C. Direto | H4: C. Indireto
A5: 2026-W23 | B5: 3 | C5: 2 | D5: 2366319.1 | E5: 2366319.1 | F5: 3.6684 | G5: 61698.54 | H5: 2304620.6
A6: 2026-W24 | B6: 3 | C6: 2 | D6: 339018.88 | E6: 2705338 | F6: 4.194 | G6: 61698.54 | H6: 277320.34
A7: 2026-W25 | B7: 7 | C7: 10 | D7: 1201796.6 | E7: 3907134.6 | F7: 6.0571 | G7: 924476.26 | H7: 277320.34
A8: 2026-W26 | B8: 7 | C8: 10 | D8: 1201796.6 | E8: 5108931.2 | F8: 7.9202 | G8: 924476.26 | H8: 277320.34
A9: 2026-W27 | B9: 7 | C9: 10 | D9: 1201796.6 | E9: 6310727.8 | F9: 9.7832 | G9: 924476.26 | H9: 277320.34
A10: 2026-W28 | B10: 7 | C10: 10 | D10: 1201796.6 | E10: 7512524.4 | F10: 11.6463 | G10: 924476.26 | H10: 277320.34
A11: 2026-W29 | B11: 7 | C11: 10 | D11: 1201796.6 | E11: 8714321 | F11: 13.5094 | G11: 924476.26 | H11: 277320.34
A12: 2026-W30 | B12: 7 | C12: 10 | D12: 1201796.6 | E12: 9916117.6 | F12: 15.3725 | G12: 924476.26 | H12: 277320.34
A13: 2026-W31 | B13: 7 | C13: 10 | D13: 1201796.6 | E13: 11117914 | F13: 17.2356 | G13: 924476.26 | H13: 277320.34
A14: 2026-W32 | B14: 7 | C14: 10 | D14: 1201796.6 | E14: 12319711 | F14: 19.0987 | G14: 924476.26 | H14: 277320.34
A15: 2026-W33 | B15: 7 | C15: 10 | D15: 1201796.6 | E15: 13521507 | F15: 20.9618 | G15: 924476.26 | H15: 277320.34
A16: 2026-W34 | B16: 7 | C16: 10 | D16: 1201796.6 | E16: 14723304 | F16: 22.8249 | G16: 924476.26 | H16: 277320.34
... A59: 2027-W24 | B59: 4 | C59: 1 | D59: 330459.75 | E59: 64505448 | F59: 100 | G59: 53139.41 | H59: 277320.34

Sheet CAMPANHA.FROTA
A1: CAMPANHAS DE PERMANENCIA DE EQUIPAMENTOS (ADR-059)
A2: Campanhas: 0 | Economia vs. dismissal: R$ 0.00 | Standby total: R$ 0.00 | Economia liquida: R$ 0.00
A4: Instancia | B4: Tipo Equip. | C4: Sem. Entrada | D4: Sem. Saida | E4: Sem. Ativas | F4: Sem. Standby | G4: Mob (R$) | H4: Demob (R$) | I4: Standby Total | J4: Custo Camp. | K4: Economia | L4: Atividades

Sheet CUBO.COMP
A1: COMPOSICAO DO PRECO DE VENDA — CUBO 4D (CATEGORIA x ATIVIDADE x TEMPO x BDI)
A2: Regime BDI: pre_reforma | Total PV: R$ 59,931,222.93 | Custo Direto: 80.9% | Margem: 6.4% | Tributos: 8.0%
A4: 1. SUMARIO POR COMPONENTE BDI (total do projeto)
A5: Componente | B5: R$ Total | C5: % PV
A6: Custo Direto | B6: 48468762 | C6: 80.87
A7: Overhead Total | B7: 2850563.3 | C7: 4.76
A8: Margem L | B8: 3839131.9 | C8: 6.41
A9: Tributos Total | B9: 4772766 | C9: 7.96
A11: 2. EXPOSICAO TRIBUTARIA POR TIPO (projeto inteiro)
A12: Tributo | B12: R$ Total | C12: % PV
A13: ISS | B13: 2452603.1 | C13: 4.09
A14: IR | B14: 1344027.2 | C14: 2.24
A15: CSSL | B15: 976135.6 | C15: 1.63
A17: 3. MARGEM (L) POR ATIVIDADE
A18: Atividade | B18: Margem (R$) | C18: % Margem Total
A19: eap-1_6 | B19: 792971.46 | C19: 20.65
A20: eap-1_7 | B20: 785195.95 | C20: 20.45
A21: eap-1_9 | B21: 746326.08 | C21: 19.44
A22: eap-1_4 | B22: 537881.76 | C22: 14.01
A23: eap-1_5 | B23: 349840.35 | C23: 9.11
A24: eap-1_2 | B24: 242942.66 | C24: 6.33
A25: eap-1_0 | B25: 158585.18 | C25: 4.13
A26: eap-1_3 | B26: 96542.88 | C26: 2.51
A27: eap-1_1 | B27: 78368.6 | C27: 2.04
A28: eap-1_10 | B28: 33651.3 | C28: 0.88
A29: eap-1_8 | B29: 16825.65 | C29: 0.44
A31: 4. COMPOSICAO DO PRECO POR SEMANA (custo | overhead | margem | tributos)
A32: Semana ISO | B32: Custo Direto | C32: Overhead | D32: Margem L | E32: Tributos | F32: Total Semana | G32: % Acumulado | H32: % Semana/Total
A33: 2026-W23 | B33: 62006.96 | C33: 3275.98 | D33: 4664.27 | E33: 5485.03 | F33: 75432.24 | G33: 0.13 | H33: 0.13
A34: 2026-W24 | B34: 62006.96 | C34: 3275.98 | D34: 4664.27 | E34: 5485.03 | F34: 75432.24 | G34: 0.25 | H34: 0.13
A35: 2026-W25 | B35: 811901.15 | C35: 48938.04 | D35: 65101.49 | E35: 81938.12 | F35: 1007878.8 | G35: 1.93 | H35: 1.68
A36: 2026-W26 | B36: 811901.15 | C36: 48938.04 | D36: 65101.49 | E36: 81938.12 | F36: 1007878.8 | G36: 3.62 | H36: 1.68
A37: 2026-W27 | B37: 811901.15 | C37: 48938.04 | D37: 65101.49 | E37: 81938.12 | F37: 1007878.8 | G37: 5.3 | H37: 1.68
A38: 2026-W28 | B38: 811901.15 | C38: 48938.04 | D38: 65101.49 | E38: 81938.12 | F38: 1007878.8 | G38: 6.98 | H38: 1.68
A39: 2026-W29 | B39: 811901.15 | C39: 48938.04 | D39: 65101.49 | E39: 81938.12 | F39: 1007878.8 | G39: 8.66 | H39: 1.68
A40: 2026-W30 | B40: 811901.15 | C40: 48938.04 | D40: 65101.49 | E40: 81938.12 | F40: 1007878.8 | G40: 10.34 | H40: 1.68
A41: 2026-W31 | B41: 811901.15 | C41: 48938.04 | D41: 65101.49 | E41: 81938.12 | F41: 1007878.8 | G41: 12.02 | H41: 1.68
A42: 2026-W32 | B42: 811901.15 | C42: 48938.04 | D42: 65101.49 | E42: 81938.12 | F42: 1007878.8 | G42: 13.71 | H42: 1.68
A43: 2026-W33 | B43: 811901.15 | C43: 48938.04 | D43: 65101.49 | E43: 81938.12 | F43: 1007878.8 | G43: 15.39 | H43: 1.68
A44: 2026-W34 | B44: 811901.15 | C44: 48938.04 | D44: 65101.49 | E44: 81938.12 | F44: 1007878.8 | G44: 17.07 | H44: 1.68
...

Sheet DIRETOS.DET
A1: DIRETOS — EQUIPES E RECURSOS
A2: Tipo | B2: Código | C2: Descrição | D2: Papel | E2: Qtd | F2: Custo Unit/Mês (R$) | G2: Custo Total/Mês (R$) | H2: Perm. (meses) | I2: Custo Total (R$)
A3: eap-1_0 — Desmatamento e limpeza de area vegetada
A4: MÃO DE OBRA | B4: AGIS-FN-OPER-TRAT-EST | C4: Operador de Trator de Esteiras | D4: DIRETO | E4: 1 | F4: 9394 | G4: =E4*F4 | H4: 7.82 | I4: =G4*H4
A5: MÃO DE OBRA | B5: AGIS-FN-OPER-ESCAV | C5: Operador de Escavadeira | D5: DIRETO | E5: 1 | F5: 9394 | G5: =E5*F5 | H5: 7.82 | I5: =G5*H5
A6: MÃO DE OBRA | B6: AGIS-FN-OPER-MOTOSSERRA | C6: Operador de Motosserra | D6: DIRETO | E6: 1 | F6: 9394 | G6: =E6*F6 | H6: 7.82 | I6: =G6*H6
A7: MÃO DE OBRA | B7: AGIS-FN-AJUD | C7: Ajudante | D7: DIRETO | E7: 1 | F7: 4279 | G7: =E7*F7 | H7: 7.82 | I7: =G7*H7
A8: MÃO DE OBRA | B8: AGIS-FN-ENCAR | C8: Encarregado de Frente | D8: DIRETO | E8: 1 | F8: 7499.8 | G8: =E8*F8 | H8: 7.82 | I8: =G8*H8
A9: MÃO DE OBRA | B9: AGIS-FN-APONTADOR | C9: Apontador | D9: DIRETO | E9: 1 | F9: 6448.2 | G9: =E9*F9 | H9: 7.82 | I9: =G9*H9
A10: MÃO DE OBRA | B10: AGIS-FN-SINALEIRO | C10: Sinaleiro | D10: DIRETO | E10: 1 | F10: 4279 | G10: =E10*F10 | H10: 7.82 | I10: =G10*H10
A11: EQUIPAMENTO | B11: AGIS-TRAT-EST-20T | C11: Trator de Esteiras 20T | D11: — | E11: 1 | F11: 52470 | G11: =E11*F11 | H11: 7.82 | I11: =G11*H11
A12: COMBUSTÍVEL | B12: AGIS-TRAT-EST-20T | C12: Diesel S-10 (26.0 L/h) | D12: — | E12: 1 | F12: 33161.14 | G12: =E12*F12 | H12: 7.82 | I12: =G12*H12
A13: EQUIPAMENTO | B13: AGIS-ESCAV-22T | C13: Escavadeira Hidráulica sobre esteira 22T | D13: — | E13: 1 | F13: 42416 | G13: =E13*F13 | H13: 7.82 | I13: =G13*H13
A14: COMBUSTÍVEL | B14: AGIS-ESCAV-22T | C14: Diesel S-10 (22.0 L/h) | D14: — | E14: 1 | F14: 28059.43 | G14: =E14*F14 | H14: 7.82 | I14: =G14*H14
A15: EQUIPAMENTO | B15: AGIS-MOTOSSERRA | C15: Motosserra a Gasolina | D15: — | E15: 1 | F15: 3300 | G15: =E15*F15 | H15: 7.82 | I15: =G15*H15
A16: COMBUSTÍVEL | B16: AGIS-MOTOSSERRA | C16: Diesel S-10 (1.5 L/h) | D16: — | E16: 1 | F16: 1913.14 | G16: =E16*F16 | H16: 7.82 | I16: =G16*H16
A17: Subtotal eap-1_0 | G17: =SUM(G4:G16) | H17: 7.82 | I17: =SUM(I4:I16)
A18: eap-1_1 — Esc/carg/transp 1aCat DMT<=2000m
A19: MÃO DE OBRA | B19: AGIS-FN-OPER-ESCAV | C19: Operador de Escavadeira | D19: DIRETO | E19: 1 | F19: 9394 | G19: =E19*F19 | H19: 2.3 | I19: =G19*H19
A20: MÃO DE OBRA | B20: AGIS-FN-AJUD | C20: Ajudante | D20: DIRETO | E20: 1 | F20: 4279 | G20: =E20*F20 | H20: 2.3 | I20: =G20*H20
A21: MÃO DE OBRA | B21: AGIS-FN-ENCAR | C21: Encarregado de Frente | D21: DIRETO | E21: 1 | F21: 7499.8 | G21: =E21*F21 | H21: 2.3 | I21: =G21*H21
A22: MÃO DE OBRA | B22: AGIS-FN-MOTOR-BASC | C22: Motorista de Caminhão Basculante | D22: DIRETO | E22: 7 | F22: 8382 | G22: =E22*F22 | H22: 2.3 | I22: =G22*H22
A23: EQUIPAMENTO | B23: AGIS-E0015 | C23: Escavadeira Hidráulica sobre esteira 38T | D23: — | E23: 1 | F23: 59048 | G23: =E23*F23 | H23: 2.3 | I23: =G23*H23
A24: COMBUSTÍVEL | B24: AGIS-E0015 | C24: Diesel S-10 (26.0 L/h) | D24: — | E24: 1 | F24: 33161.14 | G24: =E24*F24 | H24: 2.3 | I24: =G24*H24
A25: EQUIPAMENTO | B25: AGIS-E0002 | C25: Caminhão Basculante 14 m³ | D25: — | E25: 7 | F25: 26945.6 | G25: =E25*F25 | H25: 2.3 | I25: =G25*H25
A26: COMBUSTÍVEL | B26: AGIS-E0002 | C26: Diesel S-10 (2.5 L/h) | D26: — | E26: 7 | F26: 3188.57 | G26: =E26*F26 | H26: 2.3 | I26: =G26*H26
A27: Subtotal eap-1_1 | G27: =SUM(G19:G26) | H27: 2.3 | I27: =SUM(I19:I26)
A28: eap-1_2 — Esc/carg/transp 1aCat DMT<=3000m
A29: MÃO DE OBRA | B29: AGIS-FN-OPER-ESCAV | C29: Operador de Escavadeira | D29: DIRETO | E29: 1 | F29: 9394 | G29: =E29*F29 | H29: 7.13 | I29: =G29*H29
A30: MÃO DE OBRA | B30: AGIS-FN-AJUD | C30: Ajudante | D30: DIRETO | E30: 1 | F30: 4279 | G30: =E30*F30 | H30: 7.13 | I30: =G30*H30
A31: MÃO DE OBRA | B31: AGIS-FN-ENCAR | C31: Encarregado de Frente | D31: DIRETO | E31: 1 | F31: 7499.8 | G31: =E31*F31 | H31: 7.13 | I31: =G31*H31
A32: MÃO DE OBRA | B32: AGIS-FN-MOTOR-BASC | C32: Motorista de Caminhão Basculante | D32: DIRETO | E32: 8 | F32: 8382 | G32: =E32*F32 | H32: 7.13 | I32: =G32*H32
A33: EQUIPAMENTO | B33: AGIS-E0015 | C33: Escavadeira Hidráulica sobre esteira 38T | D33: — | E33: 1 | F33: 59048 | G33: =E33*F33 | H33: 7.13 | I33: =G33*H33
A34: COMBUSTÍVEL | B34: AGIS-E0015 | C34: Diesel S-10 (26.0 L/h) | D34: — | E34: 1 | F34: 33161.14 | G34: =E34*F34 | H34: 7.13 | I34: =G34*H34
A35: EQUIPAMENTO | B35: AGIS-E0002 | C35: Caminhão Basculante 14 m³ | D35: — | E35: 8 | F35: 26945.6 | G35: =E35*F35 | H35: 7.13 | I35: =G35*H35
A36: COMBUSTÍVEL | B36: AGIS-E0002 | C36: Diesel S-10 (2.5 L/h) | D36: — | E36: 8 | F36: 3188.57 | G36: =E36*F36 | H36: 7.13 | I36: =G36*H36
A37: Subtotal eap-1_2 | G37: =SUM(G29:G36) | H37: 7.13 | I37: =SUM(I29:I36)
A38: eap-1_3 — Esc/carg/transp 2aCat DMT<=2000m
A39: MÃO DE OBRA | B39: AGIS-FN-OPER-ESCAV | C39: Operador de Escavadeira | D39: DIRETO | E39: 1 | F39: 9394 | G39: =E39*F39 | H39: 1.61 | I39: =G39*H39
A40: MÃO DE OBRA | B40: AGIS-FN-AJUD | C40: Ajudante | D40: DIRETO | E40: 1 | F40: 4279 | G40: =E40*F40 | H40: 1.61 | I40: =G40*H40
...

Sheet DIRETOS.RES
A1: DIRETOS RESUMIDO — COMPONENTES MO/EQ/COMB/MAT s/BDI e c/BDI
A2: Item ID | B2: Descrição | C2: Un. | D2: Quantitativo | E2: MO s/BDI | F2: EQ s/BDI | G2: Comb. s/BDI | H2: MAT s/BDI | I2: Total s/BDI | J2: MO c/BDI | K2: EQ c/BDI | L2: Comb. c/BDI | M2: MAT c/BDI | N2: Total c/BDI
A3: eap-1_0 | B3: Desmatamento e limpeza de area vegetada | C3: m2 | D3: 2400000 | E3: 462885.6 | F3: 930979.2 | G3: 710138.4 | H3: 0 | I3: 2104003.2 | J3: 601635.56 | K3: 1137493.7 | L3: 738543.94 | M3: 0 | N3: 2477673.2
A4: eap-1_1 | B4: Esc/carg/transp 1aCat DMT<=2000m | C4: m3 | D4: 107463.11 | E4: 160309.48 | F4: 521747.78 | G4: 140922.82 | H4: 0 | I4: 822980.08 | J4: 208362.25 | K4: 637484.48 | L4: 146559.73 | M4: 0 | N4: 992406.46
A5: eap-1_2 | B5: Esc/carg/transp 1aCat DMT<=3000m | C5: m3 | D5: 336915.09 | E5: 560277.67 | F5: 1821276.1 | G5: 469151.24 | H5: 0 | I5: 2850705 | J5: 728220.91 | K5: 2225280.6 | L5: 487917.29 | M5: 0 | N5: 3441418.8
A6: eap-1_3 | B6: Esc/carg/transp 2aCat DMT<=2000m | C6: m3 | D6: 105311.33 | E6: 204790.84 | F6: 667530.62 | G6: 190682.17 | H6: 0 | I6: 1063003.6 | J6: 266176.89 | K6: 815605.6 | L6: 198309.46 | M6: 0 | N6: 1280092
A7: eap-1_4 | B7: Esc/carg/transp 2aCat DMT<=3000m | C7: m3 | D7: 585945.77 | E7: 1223028.2 | F7: 3982636.5 | G7: 1097585.4 | H7: 0 | I7: 6303250.1 | J7: 1589630.9 | K7: 4866084.8 | L7: 1141488.8 | M7: 0 | N7: 7597204.5
A8: eap-1_5 | B8: Esc/carg/transp 3aCat DMT<=2000m | C8: m3 | D8: 304634.46 | E8: 623661.98 | F8: 3186950.1 | G8: 719694.03 | H8: 0 | I8: 4530306.1 | J8: 810604.65 | K8: 3893895.3 | L8: 748481.79 | M8: 0 | N8: 5452981.8
A9: eap-1_6 | B9: Esc/carg/transp 3aCat DMT<=3000m | C9: m3 | D9: 676519.04 | E9: 1699982.8 | F9: 8833151.5 | G9: 1796277.8 | H9: 0 | I9: 12329412 | J9: 2209552.6 | K9: 10792565 | L9: 1868128.9 | M9: 0 | N9: 14870247
A10: eap-1_7 | B10: Compactacao aterros 100% Proctor Normal | C10: m3 | D10: 1135635.3 | E10: 1870441.3 | F10: 4874679.3 | G10: 3624699.2 | H10: 0 | I10: 10369820 | J10: 2431106.1 | K10: 5956005.1 | L10: 3769687.1 | M10: 0 | N10: 12156798
A11: eap-1_8 | B11: Compactacao aterros 100% Proctor Intermediario | C11: m3 | D11: 29411 | E11: 63337.44 | F11: 165067.91 | G11: 122740.69 | H11: 0 | I11: 351146.05 | J11: 82322.84 | K11: 201684.1 | L11: 127650.32 | M11: 0 | N11: 411657.26
A12: eap-1_9 | B12: Construcao corpo aterro material 3a categoria | C12: m3 | D12: 981153.5 | E12: 932009.48 | F12: 2787969.3 | G12: 2042289.6 | H12: 0 | I12: 5762268.4 | J12: 1211379.3 | K12: 3406410.5 | L12: 2123981.2 | M12: 0 | N12: 6741771.1
A13: eap-1_10 | B13: Compactacao camada final aterro sobre rocha | C13: m3 | D13: 24721.17 | E13: 57847.54 | F13: 159080.73 | G13: 139968.79 | H13: 0 | I13: 356897.06 | J13: 75187.34 | K13: 194368.81 | L13: 145567.54 | M13: 0 | N13: 415123.69
A15: TOTAL DIRETO | E15: =SUM(E3:E14) | F15: =SUM(F3:F14) | G15: =SUM(G3:G14) | H15: =SUM(H3:H14) | I15: =SUM(I3:I14) | J15: =SUM(J3:J14) | K15: =SUM(K3:K14) | L15: =SUM(L3:L14) | ... N15: =SUM(N3:N14)

Sheet INDIRETOS.DET
A1: INDIRETOS — CUSTOS INDIRETOS DETALHADOS
A2: Categoria | B2: Tipo | C2: Código/Função | D2: Descrição | E2: Qtd | F2: Custo Mensal (R$) | G2: Perm. (m) | H2: Custo Total (R$)
A3: ADM — Administracao de obra
A4: ADM | B4: MÃO DE OBRA | C4: ADMINISTRATIVO | D4: ADMINISTRATIVO | E4: 1 | F4: 10000 | G4: 13 | H4: =E4*F4*G4
A5: ADM | B5: MÃO DE OBRA | C5: AUXILIAR ADMINISTRATIVO | D5: AUXILIAR ADMINISTRATIVO | E5: 3 | F5: 20277.36 | G5: 13 | H5: =E5*F5*G5
A6: ADM | B6: MÃO DE OBRA | C6: ALMOXARIFE | D6: ALMOXARIFE | E6: 1 | F6: 6194.96 | G6: 13 | H6: =E6*F6*G6
A7: ADM | B7: MÃO DE OBRA | C7: AUXILIAR DE ALMOXARIFE | D7: AUXILIAR DE ALMOXARIFE | E7: 1 | F7: 4463.06 | G7: 13 | H7: =E7*F7*G7
A8: ADM | B8: MÃO DE OBRA | C8: GERENTE DE CONTRATO | D8: GERENTE DE CONTRATO | E8: 1 | F8: 30000 | G8: 13 | H8: =E8*F8*G8
A9: ADM | B9: MÃO DE OBRA | C9: TÉCNICO DE PLANEJAMENTO | D9: TÉCNICO DE PLANEJAMENTO | E9: 1 | F9: 14000 | G9: 13 | H9: =E9*F9*G9
A10: ADM | B10: MÃO DE OBRA | C10: ENCARREGADO GERAL | D10: ENCARREGADO GERAL | E10: 2 | F10: 36000 | G10: 13 | H10: =E10*F10*G10
A11: ADM | B11: MÃO DE OBRA | C11: ENGENHEIRO CIVIL | D11: ENGENHEIRO CIVIL | E11: 1 | F11: 22000 | G11: 13 | H11: =E11*F11*G11
A12: ADM | B12: MÃO DE OBRA | C12: MECÂNICO | D12: MECÂNICO | E12: 2 | F12: 28987.2 | G12: 13 | H12: =E12*F12*G12
A13: ADM | B13: MÃO DE OBRA | C13: AUXILIAR MECÂNICO | D13: AUXILIAR MECÂNICO | E13: 2 | F13: 8926.12 | G13: 13 | H13: =E13*F13*G13
A14: ADM | B14: MÃO DE OBRA | C14: ENCARREGADO DE MECÂNICA | D14: ENCARREGADO DE MECÂNICA | E14: 1 | F14: 9027.16 | G14: 13 | H14: =E14*F14*G14
A15: ADM | B15: MÃO DE OBRA | C15: BORRACHEIRO | D15: BORRACHEIRO | E15: 2 | F15: 12389.92 | G15: 13 | H15: =E15*F15*G15
... A25: ADM | B25: MÃO DE OBRA | C25: PREFEITO DE ALOJAMENTO | D25: PREFEITO DE ALOJAMENTO | E25: 3 | F25: 24153 | G25: 13 | H25: =E25*F25*G25
A26: Subtotal ADM | H26: =SUM(H4:H25)
A27: TOP — Topografia
A28: TOP | B28: MÃO DE OBRA | C28: TOPÓGRAFO | D28: TOPÓGRAFO | E28: 2 | F28: 36000 | G28: 13 | H28: =E28*F28*G28
A29: TOP | B29: MÃO DE OBRA | C29: AUXILIAR DE TOPOGRAFIA | D29: AUXILIAR DE TOPOGRAFIA | E29: 2 | F29: 8926.12 | G29: 13 | H29: =E29*F29*G29
A30: TOP | B30: MÃO DE OBRA | C30: SALA TÉCNICA | D30: SALA TÉCNICA | E30: 1 | F30: 12000 | G30: 13 | H30: =E30*F30*G30
A31: TOP | B31: MÃO DE OBRA | C31: AJUDANTE | D31: AJUDANTE | E31: 1 | F31: 4112.26 | G31: 13 | H31: =E31*F31*G31
A32: Subtotal TOP | H32: =SUM(H28:H31)
A33: LAB — Laboratorio de solos e materiais
A34: LAB | B34: MÃO DE OBRA | C34: LABORATORISTA | D34: LABORATORISTA | E34: 1 | F34: 9000 | G34: 13 | H34: =E34*F34*G34
A35: LAB | B35: MÃO DE OBRA | C35: AUXILIAR DE LABORATÓRIO | D35: AUXILIAR DE LABORATÓRIO | E35: 1 | F35: 4463.06 | G35: 13 | H35: =E35*F35*G35
A36: Subtotal LAB | H36: =SUM(H34:H35)
A37: QSMS — Qualidade, Saude, Seguranca e Meio Ambiente
A38: QSMS | B38: MÃO DE OBRA | C38: TÉCNICO DE SEGURANÇA DO TRABALHO | D38: TÉCNICO DE SEGURANÇA DO TRABALHO | E38: 2 | F38: 15000 | G38: 13 | H38: =E38*F38*G38
A39: QSMS | B39: MÃO DE OBRA | C39: AJUDANTE ESPECIALIZADO | D39: AJUDANTE ESPECIALIZADO | E39: 1 | F39: 4463.06 | G39: 13 | H39: =E39*F39*G39
A40: QSMS | B40: MÃO DE OBRA | C40: GERENTE DE QSMS | D40: GERENTE DE QSMS | E40: 1 | F40: 15000 | G40: 13 | H40: =E40*F40*G40
A41: QSMS | B41: MÃO DE OBRA | C41: BIÓLOGO DE CAMPO | D41: BIÓLOGO DE CAMPO | E41: 1 | F41: 7500 | G41: 13 | H41: =E41*F41*G41
A42: QSMS | B42: MÃO DE OBRA | C42: BOTÂNICO DE CAMPO | D42: BOTÂNICO DE CAMPO | E42: 1 | F42: 7500 | G42: 13 | H42: =E42*F42*G42
A43: Subtotal QSMS | H43: =SUM(H38:H42)
A44: MOB — Mobilizacao e desmobilizacao
A45: MOB | B45: CUSTO TOTAL | C45: — | D45: Mobilizacao e desmobilizacao | E45: 1 | F45: 0 | G45: 13 | H45: 4054600.4
A46: Subtotal MOB | H46: =SUM(H45:H45)
A48: TOTAL INDIRETO | H48: =H26+H32+H36+H43+H46
A51: Distribuição Mensal de Indiretos
A52: Mês | B52: Despesa Indireta (R$)
...

Sheet INDIRETOS.RES
A1: INDIRETOS RESUMIDO — CATEGORIAS + INDICADORES
A2: Categoria | B2: Descrição | C2: Custo s/BDI (R$) | D2: BDI (%) | E2: Custo c/BDI (R$) | F2: % do Total
A3: ADM | B3: Administracao de obra | C3: 13766750 | D3: 25.21 | E3: 17236701 | F3: 70.29
A4: TOP | B4: Topografia | C4: 863205.59 | D4: 25.21 | E4: 1080779.1 | F4: 4.41
A5: LAB | B5: Laboratorio de solos e materiais | C5: 140291.06 | D5: 25.21 | E5: 175651.84 | F5: 0.72
A6: QSMS | B6: Qualidade, Saude, Seguranca e Meio Ambiente | C6: 759691.79 | D6: 25.21 | E6: 951174.38 | F6: 3.88
A7: MOB | B7: Mobilizacao e desmobilizacao | C7: 4054600.4 | D7: 25.21 | E7: 5076574.6 | F7: 20.7
A9: TOTAL INDIRETO | C9: =C3+C4+C5+C6+C7 | E9: =E3+E4+E5+E6+E7
A12: INDICADORES DE COMPOSIÇÃO DE CUSTO
A13: TOTAL DIRETO (catálogo s/BDI) | C13: 46843791
A14: TOTAL INDIRETO s/BDI | C14: 21284966
A15: RAZÃO CI / CD | C15: 45.44
A16: PREÇO DE VENDA TOTAL | C16: 85639774
A17: CI / PVT | C17: 24.85

Sheet PLANEJAMENTO
A1: PLANEJAMENTO — ORÇAMENTO POR EAP (COMPONENTES s/BDI e c/BDI)
A2: Item ID | B2: Descrição | C2: Un. | D2: Quantitativo | E2: MO s/BDI (R$) | F2: MO c/BDI (R$) | G2: EQ s/BDI (R$) | H2: EQ c/BDI (R$) | I2: Comb. s/BDI (R$) | J2: Comb. c/BDI (R$) | K2: MAT s/BDI (R$) | L2: MAT c/BDI (R$) | M2: Total s/BDI (R$) | N2: Total c/BDI (R$) | O2: Criticidade
A3: eap-1_0 | B3: Desmatamento e limpeza de area vegetada | C3: m2 | D3: 2400000 | E3: 462885.6 | F3: =E3*(1+BDI!$M$3) | G3: 930979.2 | H3: =G3*(1+BDI!$M$5) | I3: 710138.4 | J3: =I3*(1+BDI!$M$7) | K3: 0 | L3: =K3*(1+BDI!$M$4) | M3: =E3+G3+I3+K3 | N3: =F3+H3+J3+L3 | O3: B
A4: eap-1_1 | B4: Esc/carg/transp 1aCat DMT<=2000m | C4: m3 | D4: 107463.11 | E4: 160309.48 | F4: =E4*(1+BDI!$M$3) | G4: 521747.78 | H4: =G4*(1+BDI!$M$5) | I4: 140922.82 | J4: =I4*(1+BDI!$M$7) | K4: 0 | L4: =K4*(1+BDI!$M$4) | M4: =E4+G4+I4+K4 | N4: =F4+H4+J4+L4 | O4: B
A5: eap-1_2 | B5: Esc/carg/transp 1aCat DMT<=3000m | C5: m3 | D5: 336915.09 | E5: 560277.67 | F5: =E5*(1+BDI!$M$3) | G5: 1821276.1 | H5: =G5*(1+BDI!$M$5) | I5: 469151.24 | J5: =I5*(1+BDI!$M$7) | K5: 0 | L5: =K5*(1+BDI!$M$4) | M5: =E5+G5+I5+K5 | N5: =F5+H5+J5+L5 | O5: A
A6: eap-1_3 | B6: Esc/carg/transp 2aCat DMT<=2000m | C6: m3 | D6: 105311.33 | E6: 204790.84 | F6: =E6*(1+BDI!$M$3) | G6: 667530.62 | H6: =G6*(1+BDI!$M$5) | I6: 190682.17 | J6: =I6*(1+BDI!$M$7) | K6: 0 | L6: =K6*(1+BDI!$M$4) | M6: =E6+G6+I6+K6 | N6: =F6+H6+J6+L6 | O6: C
A7: eap-1_4 | B7: Esc/carg/transp 2aCat DMT<=3000m | C7: m3 | D7: 585945.77 | E7: 1223028.2 | F7: =E7*(1+BDI!$M$3) | G7: 3982636.5 | H7: =G7*(1+BDI!$M$5) | I7: 1097585.4 | J7: =I7*(1+BDI!$M$7) | K7: 0 | L7: =K7*(1+BDI!$M$4) | M7: =E7+G7+I7+K7 | N7: =F7+H7+J7+L7 | O7: A+
A8: eap-1_5 | B8: Esc/carg/transp 3aCat DMT<=2000m | C8: m3 | D8: 304634.46 | E8: 623661.98 | F8: =E8*(1+BDI!$M$3) | G8: 3186950.1 | H8: =G8*(1+BDI!$M$5) | I8: 719694.03 | J8: =I8*(1+BDI!$M$7) | K8: 0 | L8: =K8*(1+BDI!$M$4) | M8: =E8+G8+I8+K8 | N8: =F8+H8+J8+L8 | O8: B
A9: eap-1_6 | B9: Esc/carg/transp 3aCat DMT<=3000m | C9: m3 | D9: 676519.04 | E9: 1699982.8 | F9: =E9*(1+BDI!$M$3) | G9: 8833151.5 | H9: =G9*(1+BDI!$M$5) | I9: 1796277.8 | J9: =I9*(1+BDI!$M$7) | K9: 0 | L9: =K9*(1+BDI!$M$4) | M9: =E9+G9+I9+K9 | N9: =F9+H9+J9+L9 | O9: A+
A10: eap-1_7 | B10: Compactacao aterros 100% Proctor Normal | C10: m3 | D10: 1135635.3 | E10: 1870441.3 | F10: =E10*(1+BDI!$M$3) | G10: 4874679.3 | H10: =G10*(1+BDI!$M$5) | I10: 3624699.2 | J10: =I10*(1+BDI!$M$7) | K10: 0 | L10: =K10*(1+BDI!$M$4) | M10: =E10+G10+I10+K10 | N10: =F10+H10+J10+L10 | O10: A+
A11: eap-1_8 | B11: Compactacao aterros 100% Proctor Intermediario | C11: m3 | D11: 29411 | E11: 63337.44 | F11: =E11*(1+BDI!$M$3) | G11: 165067.91 | H11: =G11*(1+BDI!$M$5) | I11: 122740.69 | J11: =I11*(1+BDI!$M$7) | K11: 0 | L11: =K11*(1+BDI!$M$4) | M11: =E11+G11+I11+K11 | N11: =F11+H11+J11+L11 | O11: C
A12: eap-1_9 | B12: Construcao corpo aterro material 3a categoria | C12: m3 | D12: 981153.5 | E12: 932009.48 | F12: =E12*(1+BDI!$M$3) | G12: 2787969.3 | H12: =G12*(1+BDI!$M$5) | I12: 2042289.6 | J12: =I12*(1+BDI!$M$7) | K12: 0 | L12: =K12*(1+BDI!$M$4) | M12: =E12+G12+I12+K12 | N12: =F12+H12+J12+L12 | O12: A
A13: eap-1_10 | B13: Compactacao camada final aterro sobre rocha | C13: m3 | D13: 24721.17 | E13: 57847.54 | F13: =E13*(1+BDI!$M$3) | G13: 159080.73 | H13: =G13*(1+BDI!$M$5) | I13: 139968.79 | J13: =I13*(1+BDI!$M$7) | K13: 0 | L13: =K13*(1+BDI!$M$4) | M13: =E13+G13+I13+K13 | N13: =F13+H13+J13+L13 | O13: C
A15: TOTAL | E15: =SUM(E3:E14) | F15: =SUM(F3:F14) | G15: =SUM(G3:G14) | H15: =SUM(H3:H14) | I15: =SUM(I3:I14) | J15: =SUM(J3:J14) | K15: =SUM(K3:K14) | L15: =SUM(L3:L14) | ... N15: =SUM(N3:N14)

Sheet CRONOGRAMA.DET
A1: CRONOGRAMA SEMANAL — ACOMPANHAMENTO FÍSICO DE PRODUÇÃO
A2: Item ID | B2: Descrição | C2: Un. | D2: Quantitativo | E2: Métrica | F2: 01/Jun | G2: 08/Jun | H2: 15/Jun | I2: 22/Jun | J2: 29/Jun | K2: 06/Jul | L2: 13/Jul | M2: 20/Jul | N2: 27/Jul | O2: 03/Ago | P2: 10/Ago | Q2: 17/Ago | R2: 24/Ago | S2: 31/Ago | T2: 07/Set | U2: 14/Set | V2: 21/Set | W2: 28/Set | X2: 05/Out | Y2: 12/Out | Z2: 19/Out | AA2: 26/Out | AB2: 02/Nov | AC2: 09/Nov | AD2: 16/Nov | AE2: 23/Nov | AF2: 30/Nov | AG2: 07/Dez | AH2: 14/Dez | AI2: 21/Dez | AJ2: 28/Dez | AK2: 04/Jan | AL2: 11/Jan | AM2: 18/Jan | AN2: 25/Jan | AO2: 01/Fev | AP2: 08/Fev | AQ2: 15/Fev | AR2: 22/Fev | AS2: 01/Mar | AT2: 08/Mar | AU2: 15/Mar | AV2: 22/Mar | AW2: 29/Mar | AX2: 05/Abr | AY2: 12/Abr | AZ2: 19/Abr | BA2: 26/Abr | BB2: 03/Mai | BC2: 10/Mai | BD2: 17/Mai | BE2: 24/Mai | BF2: 31/Mai | BG2: 07/Jun | BH2: 14/Jun
E3: Praticabilidade | F3: 1 | G3: 1 | H3: 1 | I3: 1 | J3: 1 | K3: 1 | L3: 1 | M3: 1 | N3: 1 | O3: 1 | P3: 1 | Q3: 1 | R3: 1 | S3: 1 | T3: 1 | U3: 1 | V3: 1 | W3: 1 | X3: 1 | Y3: 1 | Z3: 1 | AA3: 1 | AB3: 1 | AC3: 1 | AD3: 1 | AE3: 1 | AF3: 1 | AG3: 1 | AH3: 1 | AI3: 1 | AJ3: 1 | AK3: 1 | AL3: 1 | AM3: 1 | AN3: 1 | AO3: 1 | AP3: 1 | AQ3: 1 | AR3: 1 | AS3: 1 | AT3: 1 | AU3: 1 | AV3: 1 | AW3: 1 | AX3: 1 | AY3: 1 | AZ3: 1 | BA3: 1 | BB3: 1 | BC3: 1 | BD3: 1 | BE3: 1 | BF3: 1 | BG3: 1 | BH3: 1
A4: eap-1_0 | B4: Desmatamento e limpeza de area vegetada | C4: m2 | D4: 2400000 | E4: Dias Trabalhados | F4: 6 | G4: 6 | H4: 6 | I4: 6 | J4: 6 | K4: 6 | L4: 6 | M4: 6 | N4: 6 | O4: 6 | P4: 6 | Q4: 6 | R4: 6 | S4: 6 | T4: 6 | U4: 6 | V4: 6 | W4: 6 | X4: 6 | Y4: 6 | Z4: 6 | AA4: 6 | AB4: 6 | AC4: 6 | AD4: 6 | AE4: 6 | AF4: 6 | AG4: 6 | AH4: 6 | AI4: 6 | AJ4: 6 | AK4: 6 | AL4: 6 | AM4: 6
E5: Nº De Equipes | F5: 2 | G5: 2 | H5: 2 | I5: 2 | J5: 2 | K5: 2 | L5: 2 | M5: 2 | N5: 2 | O5: 2 | P5: 2 | Q5: 2 | R5: 2 | S5: 2 | T5: 2 | U5: 2 | V5: 2 | W5: 2 | X5: 2 | Y5: 2 | Z5: 2 | AA5: 2 | AB5: 2 | AC5: 2 | AD5: 2 | AE5: 2 | AF5: 2 | AG5: 2 | AH5: 2 | AI5: 2 | AJ5: 2 | AK5: 2 | AL5: 2 | AM5: 2
E6: Qtd. Planejada | F6: 70848 | G6: 70848 | H6: 70848 | I6: 70848 | J6: 70848 | K6: 70848 | L6: 70848 | M6: 70848 | N6: 70848 | O6: 70848 | P6: 70848 | Q6: 70848 | R6: 70848 | S6: 70848 | T6: 70848 | U6: 70848 | V6: 70848 | W6: 70848 | X6: 66122.44 | Y6: 66122.44 | Z6: 66122.44 | AA6: 66122.44 | AB6: 66278.3 | AC6: 66278.3 | AD6: 66278.3 | AE6: 66278.3 | AF6: 66278.3 | AG6: 66278.3 | AH6: 66278.3 | AI6: 66278.3 | AJ6: 66278.3 | AK6: 59420.22 | AL6: 59420.22 | AM6: 59420.22
E7: Qtd Plan. Acumulada | F7: 70848 | G7: 141696 | H7: 212544 | I7: 283392 | J7: 354240 | K7: 425088 | L7: 495936 | M7: 566784 | N7: 637632 | O7: 708480 | P7: 779328 | Q7: 850176 | R7: 921024 | S7: 991872 | T7: 1062720 | U7: 1133568 | V7: 1204416 | W7: 1275264 | X7: 1341386.4 | Y7: 1407508.9 | Z7: 1473631.3 | AA7: 1539753.8 | AB7: 1606032.1 | AC7: 1672310.4 | AD7: 1738588.7 | AE7: 1804867 | AF7: 1871145.3 | AG7: 1937423.6 | AH7: 2003701.9 | AI7: 2069980.2 | AJ7: 2136258.5 | AK7: 2195678.7 | AL7: 2255098.9 | AM7: 2314519.1 | AN7: 2314519.1 | AO7: 2314519.1 | AP7: 2314519.1 | AQ7: 2314519.1 | AR7: 2314519.1 | AS7: 2314519.1 | AT7: 2314519.1 | AU7: 2314519.1 | AV7: 2314519.1 | AW7: 2314519.1 | AX7: 2314519.1 | AY7: 2314519.1 | AZ7: 2314519.1 | BA7: 2314519.1 | BB7: 2314519.1 | BC7: 2314519.1 | BD7: 2314519.1 | BE7: 2314519.1 | BF7: 2314519.1 | BG7: 2314519.1 | BH7: 2314519.1
E8: % Semanal | F8: 0.0306 | G8: 0.0306 | H8: 0.0306 | I8: 0.0306 | J8: 0.0306 | K8: 0.0306 | L8: 0.0306 | M8: 0.0306 | N8: 0.0306 | O8: 0.0306 | P8: 0.0306 | Q8: 0.0306 | R8: 0.0306 | S8: 0.0306 | T8: 0.0306 | U8: 0.0306 | V8: 0.0306 | W8: 0.0306 | X8: 0.0286 | Y8: 0.0286 | Z8: 0.0286 | AA8: 0.0286 | AB8: 0.0286 | AC8: 0.0286 | AD8: 0.0286 | AE8: 0.0286 | AF8: 0.0286 | AG8: 0.0286 | AH8: 0.0286 | AI8: 0.0286 | AJ8: 0.0286 | AK8: 0.0257 | AL8: 0.0257 | AM8: 0.0257
E9: % Acumulado | F9: 0.0306 | G9: 0.0612 | H9: 0.0918 | I9: 0.1224 | J9: 0.1531 | K9: 0.1837 | L9: 0.2143 | M9: 0.2449 | N9: 0.2755 | O9: 0.3061 | P9: 0.3367 | Q9: 0.3673 | R9: 0.3979 | S9: 0.4285 | T9: 0.4592 | U9: 0.4898 | V9: 0.5204 | W9: 0.551 | X9: 0.5796 | Y9: 0.6081 | Z9: 0.6367 | AA9: 0.6653 | AB9: 0.6939 | AC9: 0.7225 | AD9: 0.7512 | AE9: 0.7798 | AF9: 0.8084 | AG9: 0.8371 | AH9: 0.8657 | AI9: 0.8943 | AJ9: 0.923 | AK9: 0.9487 | AL9: 0.9743 | AM9: 1 | AN9: 1 | AO9: 1 | AP9: 1 | AQ9: 1 | AR9: 1 | AS9: 1 | AT9: 1 | AU9: 1 | AV9: 1 | AW9: 1 | AX9: 1 | AY9: 1 | AZ9: 1 | BA9: 1 | BB9: 1 | BC9: 1 | BD9: 1 | BE9: 1 | BF9: 1 | BG9: 1 | BH9: 1
A10: eap-1_1 | B10: Esc/carg/transp 1aCat DMT<=2000m | C10: m3 | D10: 107463.11 | E10: Dias Trabalhados | R10: 6 | S10: 6 | T10: 6 | U10: 6 | V10: 6 | W10: 6 | X10: 6 | Y10: 6 | Z10: 6 | AA10: 6
E11: Nº De Equipes | R11: 1 | S11: 1 | T11: 1 | U11: 1 | V11: 1 | W11: 1 | X11: 1 | Y11: 1 | Z11: 1 | AA11: 1
E12: Qtd. Planejada | R12: 11129.76 | S12: 11129.76 | T12: 11129.76 | U12: 11129.76 | V12: 11129.76 | W12: 11129.76 | X12: 10387.41 | Y12: 10387.41 | Z12: 10387.41 | AA12: 9522.32
E13: Qtd Plan. Acumulada | R13: 11129.76 | S13: 22259.52 | T13: 33389.28 | U13: 44519.04 | V13: 55648.8 | W13: 66778.56 | X13: 77165.97 | Y13: 87553.38 | Z13: 97940.79 | AA13: 107463.11 | AB13: 107463.11 | AC13: 107463.11 | AD13: 107463.11 | AE13: 107463.11 | AF13: 107463.11 | AG13: 107463.11 | AH13: 107463.11 | AI13: 107463.11 | AJ13: 107463.11 | AK13: 107463.11 | AL13: 107463.11 | AM13: 107463.11 | AN13: 107463.11 | AO13: 107463.11 | AP13: 107463.11 | AQ13: 107463.11 | AR13: 107463.11 | AS13: 107463.11 | AT13: 107463.11 | AU13: 107463.11 | AV13: 107463.11 | AW13: 107463.11 | AX13: 107463.11 | AY13: 107463.11 | AZ13: 107463.11 | BA13: 107463.11 | BB13: 107463.11 | BC13: 107463.11 | BD13: 107463.11 | BE13: 107463.11 | BF13: 107463.11 | BG13: 107463.11 | BH13: 107463.11
E14: % Semanal | R14: 0.1036 | S14: 0.1036 | T14: 0.1036 | U14: 0.1036 | V14: 0.1036 | W14: 0.1036 | X14: 0.0967 | Y14: 0.0967 | Z14: 0.0967 | AA14: 0.0886
E15: % Acumulado | R15: 0.1036 | S15: 0.2071 | T15: 0.3107 | U15: 0.4143 | V15: 0.5178 | W15: 0.6214 | X15: 0.7181 | Y15: 0.8147 | Z15: 0.9114 | AA15: 1 | AB15: 1 | AC15: 1 | AD15: 1 | AE15: 1 | AF15: 1 | AG15: 1 | AH15: 1 | AI15: 1 | AJ15: 1 | AK15: 1 | AL15: 1 | AM15: 1 | AN15: 1 | AO15: 1 | AP15: 1 | AQ15: 1 | AR15: 1 | AS15: 1 | AT15: 1 | AU15: 1 | AV15: 1 | AW15: 1 | AX15: 1 | AY15: 1 | AZ15: 1 | BA15: 1 | BB15: 1 | BC15: 1 | BD15: 1 | BE15: 1 | BF15: 1 | BG15: 1 | BH15: 1
A16: eap-1_2 | B16: Esc/carg/transp 1aCat DMT<=3000m | C16: m3 | D16: 336915.09 | E16: Dias Trabalhados | S16: 6 | T16: 6 | U16: 6 | V16: 6 | W16: 6 | X16: 6 | Y16: 6 | Z16: 6 | AA16: 6 | AB16: 6 | AC16: 6 | AD16: 6 | AE16: 6 | AF16: 6 | AG16: 6 | AH16: 6 | AI16: 6 | AJ16: 6 | AK16: 6 | AL16: 6 | AM16: 6 | AN16: 6 | AO16: 6 | AP16: 6 | AQ16: 6 | AR16: 6 | AS16: 6 | AT16: 6 | AU16: 6 | AV16: 6 | AW16: 6
E17: Nº De Equipes | S17: 1 | T17: 1 | U17: 1 | V17: 1 | W17: 1 | X17: 1 | Y17: 1 | Z17: 1 | AA17: 1 | AB17: 1 | AC17: 1 | AD17: 1 | AE17: 1 | AF17: 1 | AG17: 1 | AH17: 1 | AI17: 1 | AJ17: 1 | AK17: 1 | AL17: 1 | AM17: 1 | AN17: 1 | AO17: 1 | AP17: 1 | AQ17: 1 | AR17: 1 | AS17: 1 | AT17: 1 | AU17: 1 | AV17: 1 | AW17: 1
E18: Qtd. Planejada | S18: 11083.68 | T18: 11083.68 | U18: 11083.68 | V18: 11083.68 | W18: 11083.68 | X18: 10344.4 | Y18: 10344.4 | Z18: 10344.4 | AA18: 10344.4 | AB18: 10368.78 | AC18: 10368.78 | AD18: 10368.78 | AE18: 10368.78 | AF18: 10368.78 | AG18: 10368.78 | AH18: 10368.78 | AI18: 10368.78 | AJ18: 10368.78 | AK18: 9295.88 | AL18: 9295.88 | AM18: 9295.88 | AN18: 9295.88 | AO18: 8708.45 | AP18: 8708.45 | AQ18: 8708.45 | AR18: 8708.45 | AS18: 6793.19 | AT18: 6793.19 | AU18: 6793.19 | AV18: 6793.19 | AW18: 9975.31
E19: Qtd Plan. Acumulada | S19: 11083.68 | T19: 22167.36 | U19: 33251.04 | V19: 44334.72 | W19: 55418.4 | X19: 65762.8 | Y19: 76107.2 | Z19: 86451.6 | AA19: 96796 | AB19: 107164.78 | AC19: 117533.56 | AD19: 127902.34 | AE19: 138271.12 | AF19: 148639.9 | AG19: 159008.68 | AH19: 169377.46 | AI19: 179746.24 | AJ19: 190115.02 | AK19: 199410.9 | AL19: 208706.78 | AM19: 218002.66 | AN19: 227298.54 | AO19: 236006.99 | AP19: 244715.44 | AQ19: 253423.89 | AR19: 262132.34 | AS19: 268925.53 | AT19: 275718.72 | AU19: 282511.91 | AV19: 289305.1 | AW19: 299280.41 | AX19: 299280.41 | AY19: 299280.41 | AZ19: 299280.41 | BA19: 299280.41 | BB19: 299280.41 | BC19: 299280.41 | BD19: 299280.41 | BE19: 299280.41 | BF19: 299280.41 | BG19: 299280.41 | BH19: 299280.41
E20: % Semanal | S20: 0.037 | T20: 0.037 | U20: 0.037 | V20: 0.037 | W20: 0.037 | X20: 0.0346 | Y20: 0.0346 | Z20: 0.0346 | AA20: 0.0346 | AB20: 0.0346 | AC20: 0.0346 | AD20: 0.0346 | AE20: 0.0346 | AF20: 0.0346 | AG20: 0.0346 | AH20: 0.0346 | AI20: 0.0346 | AJ20: 0.0346 | AK20: 0.0311 | AL20: 0.0311 | AM20: 0.0311 | AN20: 0.0311 | AO20: 0.0291 | AP20: 0.0291 | AQ20: 0.0291 | AR20: 0.0291 | AS20: 0.0227 | AT20: 0.0227 | AU20: 0.0227 | AV20: 0.0227 | AW20: 0.0333
E21: % Acumulado | S21: 0.037 | T21: 0.0741 | U21: 0.1111 | V21: 0.1481 | W21: 0.1852 | X21: 0.2197 | Y21: 0.2543 | Z21: 0.2889 | AA21: 0.3234 | AB21: 0.3581 | AC21: 0.3927 | AD21: 0.4274 | AE21: 0.462 | AF21: 0.4967 | AG21: 0.5313 | AH21: 0.5659 | AI21: 0.6006 | AJ21: 0.6352 | AK21: 0.6663 | AL21: 0.6974 | AM21: 0.7284 | AN21: 0.7595 | AO21: 0.7886 | AP21: 0.8177 | AQ21: 0.8468 | AR21: 0.8759 | AS21: 0.8986 | AT21: 0.9213 | AU21: 0.944 | AV21: 0.9667 | AW21: 1 | AX21: 1 | AY21: 1 | AZ21: 1 | BA21: 1 | BB21: 1 | BC21: 1 | BD21: 1 | BE21: 1 | BF21: 1 | BG21: 1 | BH21: 1
A22: eap-1_3 | B22: Esc/carg/transp 2aCat DMT<=2000m | C22: m3 | D22: 105311.33 | E22: Dias Trabalhados | AU22: 6 | AV22: 6 | AW22: 6 | AX22: 6 | AY22: 6 | AZ22: 6 | BA22: 6
E23: Nº De Equipes | AU23: 2 | AV23: 2 | AW23: 2 | AX23: 2 | AY23: 2 | AZ23: 2 | BA23: 2
E24: Qtd. Planejada | AU24: 9312.94 | AV24: 9312.94 | AW24: 13675.39 | AX24: 13675.39 | AY24: 13675.39 | AZ24: 13675.39 | BA24: 13234.74
E25: Qtd Plan. Acumulada | AU25: 9312.94 | AV25: 18625.88 | AW25: 32301.27 | AX25: 45976.66 | AY25: 59652.05 | AZ25: 73327.44 | BA25: 86562.18 | BB25: 86562.18 | BC25: 86562.18 | BD25: 86562.18 | BE25: 86562.18 | BF25: 86562.18 | BG25: 86562.18 | BH25: 86562.18
E26: % Semanal | AU26: 0.1076 | AV26: 0.1076 | AW26: 0.158 | AX26: 0.158 | AY26: 0.158 | AZ26: 0.158 | BA26: 0.1529
E27: % Acumulado | AU27: 0.1076 | AV27: 0.2152 | AW27: 0.3732 | AX27: 0.5311 | AY27: 0.6891 | AZ27: 0.8471 | BA27: 1 | BB27: 1 | BC27: 1 | BD27: 1 | BE27: 1 | BF27: 1 | BG27: 1 | BH27: 1
A28: eap-1_4 | B28: Esc/carg/transp 2aCat DMT<=3000m | C28: m3 | D28: 585945.77 | E28: Dias Trabalhados | H28: 6 | I28: 6 | J28: 6 | K28: 6 | L28: 6 | M28: 6 | N28: 6 | O28: 6 | P28: 6 | Q28: 6 | R28: 6 | S28: 6 | T28: 6 | U28: 6 | V28: 6 | W28: 6 | X28: 6 | Y28: 6 | Z28: 6 | AA28: 6 | AB28: 6 | AC28: 6 | AD28: 6 | AE28: 6 | AF28: 6 | AG28: 6 | AH28: 6 | AI28: 6 | AJ28: 6 | AK28: 6 | AL28: 6 | AM28: 6 | AN28: 6 | AO28: 6 | AP28: 6 | AQ28: 6 | AR28: 6 | AS28: 6 | AT28: 6
E29: Nº De Equipes | H29: 2 | I29: 2 | J29: 2 | K29: 2 | L29: 2 | M29: 2 | N29: 2 | O29: 2 | P29: 2 | Q29: 2 | R29: 2 | S29: 2 | T29: 2 | U29: 2 | V29: 2 | W29: 2 | X29: 2 | Y29: 2 | Z29: 2 | AA29: 2 | AB29: 2 | AC29: 2 | AD29: 2 | AE29: 2 | AF29: 2 | AG29: 2 | AH29: 2 | AI29: 2 | AJ29: 2 | AK29: 2 | AL29: 2 | AM29: 2 | AN29: 2 | AO29: 2 | AP29: 2 | AQ29: 2 | AR29: 2 | AS29: 2 | AT29: 2
E30: Qtd. Planejada | H30: 15242.88 | I30: 15242.88 | J30: 15242.88 | K30: 15242.88 | L30: 15242.88 | M30: 15242.88 | N30: 15242.88 | O30: 15242.88 | P30: 15242.88 | Q30: 15242.88 | R30: 15242.88 | S30: 15242.88 | T30: 15242.88 | U30: 15242.88 | V30: 15242.88 | W30: 15242.88 | X30: 14226.18 | Y30: 14226.18 | Z30: 14226.18 | AA30: 14226.18 | AB30: 14259.71 | AC30: 14259.71 | AD30: 14259.71 | AE30: 14259.71 | AF30: 14259.71 | AG30: 14259.71 | AH30: 14259.71 | AI30: 14259.71 | AJ30: 14259.71 | AK30: 12784.2 | AL30: 12784.2 | AM30: 12784.2 | AN30: 12784.2 | AO30: 11976.33 | AP30: 11976.33 | AQ30: 11976.33 | AR30: 11976.33 | AS30: 9342.36 | AT30: 9342.36
E31: Qtd Plan. Acumulada | H31: 15242.88 | I31: 30485.76 | J31: 45728.64 | K31: 60971.52 | L31: 76214.4 | M31: 91457.28 | N31: 106700.16 | O31: 121943.04 | P31: 137185.92 | Q31: 152428.8 | R31: 167671.68 | S31: 182914.56 | T31: 198157.44 | U31: 213400.32 | V31: 228643.2 | W31: 243886.08 | X31: 258112.26 | Y31: 272338.44 | Z31: 286564.62 | AA31: 300790.8 | AB31: 315050.51 | AC31: 329310.22 | AD31: 343569.93 | AE31: 357829.64 | AF31: 372089.35 | AG31: 386349.06 | AH31: 400608.77 | AI31: 414868.48 | AJ31: 429128.19 | AK31: 441912.39 | AL31: 454696.59 | AM31: 467480.79 | AN31: 480264.99 | AO31: 492241.32 | AP31: 504217.65 | AQ31: 516193.98 | AR31: 528170.31 | AS31: 537512.67 | AT31: 546855.03 | AU31: 546855.03 | AV31: 546855.03 | AW31: 546855.03 | AX31: 546855.03 | AY31: 546855.03 | AZ31: 546855.03 | BA31: 546855.03 | BB31: 546855.03 | BC31: 546855.03 | BD31: 546855.03 | BE31: 546855.03 | BF31: 546855.03 | BG31: 546855.03 | BH31: 546855.03
E32: % Semanal | H32: 0.0279 | I32: 0.0279 | J32: 0.0279 | K32: 0.0279 | L32: 0.0279 | M32: 0.0279 | N32: 0.0279 | O32: 0.0279 | P32: 0.0279 | Q32: 0.0279 | R32: 0.0279 | S32: 0.0279 | T32: 0.0279 | U32: 0.0279 | V32: 0.0279 | W32: 0.0279 | X32: 0.026 | Y32: 0.026 | Z32: 0.026 | AA32: 0.026 | AB32: 0.0261 | AC32: 0.0261 | AD32: 0.0261 | AE32: 0.0261 | AF32: 0.0261 | AG32: 0.0261 | AH32: 0.0261 | AI32: 0.0261 | AJ32: 0.0261 | AK32: 0.0234 | AL32: 0.0234 | AM32: 0.0234 | AN32: 0.0234 | AO32: 0.0219 | AP32: 0.0219 | AQ32: 0.0219 | AR32: 0.0219 | AS32: 0.0171 | AT32: 0.0171
E33: % Acumulado | H33: 0.0279 | I33: 0.0557 | J33: 0.0836 | K33: 0.1115 | L33: 0.1394 | M33: 0.1672 | N33: 0.1951 | O33: 0.223 | P33: 0.2509 | Q33: 0.2787 | R33: 0.3066 | S33: 0.3345 | T33: 0.3624 | U33: 0.3902 | V33: 0.4181 | W33: 0.446 | X33: 0.472 | Y33: 0.498 | Z33: 0.524 | AA33: 0.55 | AB33: 0.5761 | AC33: 0.6022 | AD33: 0.6283 | AE33: 0.6543 | AF33: 0.6804 | AG33: 0.7065 | AH33: 0.7326 | AI33: 0.7586 | AJ33: 0.7847 | AK33: 0.8081 | AL33: 0.8315 | AM33: 0.8549 | AN33: 0.8782 | AO33: 0.9001 | AP33: 0.922 | AQ33: 0.9439 | AR33: 0.9658 | AS33: 0.9829 | AT33: 1 | AU33: 1 | AV33: 1 | AW33: 1 | AX33: 1 | AY33: 1 | AZ33: 1 | BA33: 1 | BB33: 1 | BC33: 1 | BD33: 1 | BE33: 1 | BF33: 1 | BG33: 1 | BH33: 1
A34: eap-1_5 | B34: Esc/carg/transp 3aCat DMT<=2000m | C34: m3 | D34: 304634.46 | E34: Dias Trabalhados | H34: 6 | I34: 6 | J34: 6 | K34: 6 | L34: 6 | M34: 6 | N34: 6 | O34: 6 | P34: 6 | Q34: 6 | R34: 6 | S34: 6 | T34: 6 | U34: 6 | V34: 6
E35: Nº De Equipes | H35: 3 | I35: 3 | J35: 3 | K35: 3 | L35: 3 | M35: 3 | N35: 3 | O35: 3 | P35: 3 | Q35: 3 | R35: 3 | S35: 3 | T35: 3 | U35: 3 | V35: 3
E36: Qtd. Planejada | H36: 20450.88 | I36: 20450.88 | J36: 20450.88 | K36: 20450.88 | L36: 20450.88 | M36: 20450.88 | N36: 20450.88 | O36: 20450.88 | P36: 20450.88 | Q36: 20450.88 | R36: 20450.88 | S36: 20450.88 | T36: 20450.88 | U36: 20450.88 | V36: 18322.14
E37: Qtd Plan. Acumulada | H37: 20450.88 | I37: 40901.76 | J37: 61352.64 | K37: 81803.52 | L37: 102254.4 | M37: 122705.28 | N37: 143156.16 | O37: 163607.04 | P37: 184057.92 | Q37: 204508.8 | R37: 224959.68 | S37: 245410.56 | T37: 265861.44 | U37: 286312.32 | V37: 304634.46 | W37: 304634.46 | X37: 304634.46 | Y37: 304634.46 | Z37: 304634.46 | AA37: 304634.46 | AB37: 304634.46 | AC37: 304634.46 | AD37: 304634.46 | AE37: 304634.46 | AF37: 304634.46 | AG37: 304634.46 | AH37: 304634.46 | AI37: 304634.46 | AJ37: 304634.46 | AK37: 304634.46 | AL37: 304634.46 | AM37: 304634.46 | AN37: 304634.46 | AO37: 304634.46 | AP37: 304634.46 | AQ37: 304634.46 | AR37: 304634.46 | AS37: 304634.46 | AT37: 304634.46 | AU37: 304634.46 | AV37: 304634.46 | AW37: 304634.46 | AX37: 304634.46 | AY37: 304634.46 | AZ37: 304634.46 | BA37: 304634.46 | BB37: 304634.46 | BC37: 304634.46 | BD37: 304634.46 | BE37: 304634.46 | BF37: 304634.46 | BG37: 304634.46 | BH37: 304634.46
E38: % Semanal | H38: 0.0671 | I38: 0.0671 | J38: 0.0671 | K38: 0.0671 | L38: 0.0671 | M38: 0.0671 | N38: 0.0671 | O38: 0.0671 | P38: 0.0671 | Q38: 0.0671 | R38: 0.0671 | S38: 0.0671 | T38: 0.0671 | U38: 0.0671 | V38: 0.0601
E39: % Acumulado | H39: 0.0671 | I39: 0.1343 | J39: 0.2014 | K39: 0.2685 | L39: 0.3357 | M39: 0.4028 | N39: 0.4699 | O39: 0.5371 | P39: 0.6042 | Q39: 0.6713 | R39: 0.7385 | S39: 0.8056 | T39: 0.8727 | U39: 0.9399 | V39: 1 | W39: 1 | X39: 1 | Y39: 1 | Z39: 1 | AA39: 1 | AB39: 1 | AC39: 1 | AD39: 1 | AE39: 1 | AF39: 1 | AG39: 1 | AH39: 1 | AI39: 1 | AJ39: 1 | AK39: 1 | AL39: 1 | AM39: 1 | AN39: 1 | AO39: 1 | AP39: 1 | AQ39: 1 | AR39: 1 | AS39: 1 | AT39: 1 | AU39: 1 | AV39: 1 | AW39: 1 | AX39: 1 | AY39: 1 | AZ39: 1 | BA39: 1 | BB39: 1 | BC39: 1 | BD39: 1 | BE39: 1 | BF39: 1 | BG39: 1 | BH39: 1
A40: eap-1_6 | B40: Esc/carg/transp 3aCat DMT<=3000m | C40: m3 | D40: 676519.04 | E40: Dias Trabalhados | H40: 6 | I40: 6 | J40: 6 | K40: 6 | L40: 6 | M40: 6 | N40: 6 | O40: 6 | P40: 6 | Q40: 6 | R40: 6 | S40: 6 | T40: 6 | U40: 6 | V40: 6 | W40: 6 | X40: 6 | Y40: 6 | Z40: 6 | AA40: 6 | AB40: 6 | AC40: 6 | AD40: 6 | AE40: 6 | AF40: 6 | AG40: 6 | AH40: 6 | AI40: 6 | AJ40: 6 | AK40: 6 | AL40: 6 | AM40: 6 | AN40: 6 | AO40: 6
...

Sheet CRONOGRAMA.RES
A1: CRONOGRAMA RESUMIDO — PRODUÇÃO MENSAL POR EAP
A2: Item ID | B2: Descrição | C2: Un. | D2: Total Qtd | E2: Jun/26 | F2: Jul/26 | G2: Ago/26 | H2: Set/26 | I2: Out/26 | J2: Nov/26 | K2: Dez/26 | L2: Jan/27 | M2: Fev/27 | N2: Mar/27 | O2: Abr/27 | P2: Mai/27 | Q2: Jun/27
A3: eap-1_0 | B3: Desmatamento e limpeza de area vegetada | C3: m2 | D3: 2400000 | E3: 354240 | F3: 283392 | G3: 354240 | H3: 283392 | I3: 264489.76 | J3: 331391.5 | K3: 265113.2 | L3: 178260.66
A4: eap-1_1 | B4: Esc/carg/transp 1aCat DMT<=2000m | C4: m3 | D4: 107463.11 | G4: 22259.52 | H4: 44519.04 | I4: 40684.55
A5: eap-1_2 | B5: Esc/carg/transp 1aCat DMT<=3000m | C5: m3 | D5: 336915.09 | G5: 11083.68 | H5: 44334.72 | I5: 41377.6 | J5: 51843.9 | K5: 41475.12 | L5: 37183.52 | M5: 34833.8 | N5: 37148.07
A6: eap-1_3 | B6: Esc/carg/transp 2aCat DMT<=2000m | C6: m3 | D6: 105311.33 | N6: 32301.27 | O6: 54260.91
A7: eap-1_4 | B7: Esc/carg/transp 2aCat DMT<=3000m | C7: m3 | D7: 585945.77 | E7: 45728.64 | F7: 60971.52 | G7: 76214.4 | H7: 60971.52 | I7: 56904.72 | J7: 71298.55 | K7: 57038.84 | L7: 51136.8 | M7: 47905.32 | N7: 18684.72
A8: eap-1_5 | B8: Esc/carg/transp 3aCat DMT<=2000m | C8: m3 | D8: 304634.46 | E8: 61352.64 | F8: 81803.52 | G8: 102254.4 | H8: 59223.9
A9: eap-1_6 | B9: Esc/carg/transp 3aCat DMT<=3000m | C9: m3 | D9: 676519.04 | E9: 61413.12 | F9: 81884.16 | G9: 102355.2 | H9: 81884.16 | I9: 76422.48 | J9: 95753.3 | K9: 76602.64 | L9: 68676.24 | M9: 16084.1
A10: eap-1_7 | B10: Compactacao aterros 100% Proctor Normal | C10: m3 | D10: 1135635.3 | G10: 33217.92 | H10: 132871.68 | I10: 124009.12 | J10: 155376.8 | K10: 124301.44 | L10: 111439.48 | M10: 104397.28 | N10: 111333.17 | O10: 118621.2
A11: eap-1_8 | B11: Compactacao aterros 100% Proctor Intermediario | C11: m3 | D11: 29411 | P11: 16596.09
A12: eap-1_9 | B12: Construcao corpo aterro material 3a categoria | C12: m3 | D12: 981153.5 | I12: 28884.22 | J12: 144761.5 | K12: 115809.2 | L12: 103825.96 | M12: 97264.88 | N12: 103726.91 | O12: 110517.02 | P12: 142765.35
A13: eap-1_10 | B13: Compactacao camada final aterro sobre rocha | C13: m3 | D13: 24721.17 | P13: 17961.6 | Q13: 6759.57

Sheet EQUIPE
A1: EQUIPE — COMPOSIÇÃO DE RECURSOS DIRETOS POR ATIVIDADE
A2: Item ID | B2: CPU ID | C2: Nome / Tipo | D2: Papel | E2: Qtd | F2: Custo Mensal (R$) | G2: Perm. (m) | H2: Nº Eq. | I2: Custo Total (R$)
A3: eap-1_0 — Desmatamento e limpeza de area vegetada
A4: eap-1_0 | B4: CPU-TERRA-ATI-003 | C4: Operador de Trator de Esteiras | D4: DIRETO | E4: 1 | F4: 9394 | G4: 7.82 | H4: 1 | I4: 73461.08
A5: eap-1_0 | B5: CPU-TERRA-ATI-003 | C5: Operador de Escavadeira | D5: DIRETO | E5: 1 | F5: 9394 | G5: 7.82 | H5: 1 | I5: 73461.08
A6: eap-1_0 | B6: CPU-TERRA-ATI-003 | C6: Operador de Motosserra | D6: DIRETO | E6: 1 | F6: 9394 | G6: 7.82 | H6: 1 | I6: 73461.08
A7: eap-1_0 | B7: CPU-TERRA-ATI-003 | C7: Ajudante | D7: DIRETO | E7: 1 | F7: 4279 | G7: 7.82 | H7: 1 | I7: 33461.78
A8: eap-1_0 | B8: CPU-TERRA-ATI-003 | C8: Encarregado de Frente | D8: DIRETO | E8: 1 | F8: 7499.8 | G8: 7.82 | H8: 1 | I8: 58648.44
A9: eap-1_0 | B9: CPU-TERRA-ATI-003 | C9: Apontador | D9: DIRETO | E9: 1 | F9: 6448.2 | G9: 7.82 | H9: 1 | I9: 50424.92
A10: eap-1_0 | B10: CPU-TERRA-ATI-003 | C10: Sinaleiro | D10: DIRETO | E10: 1 | F10: 4279 | G10: 7.82 | H10: 1 | I10: 33461.78
A11: eap-1_0 | B11: AGIS-TRAT-EST-20T | C11: Trator de Esteiras 20T [EQ] | D11: EQ | E11: 1 | F11: 52470 | G11: 7.82 | H11: 1 | I11: 410315.4
A12: eap-1_0 | B12: AGIS-TRAT-EST-20T | C12: Diesel — Trator de Esteiras 20T | D12: COMB | E12: 1 | F12: 33161.14 | G12: 7.82 | H12: 1 | I12: 259320.11
A13: eap-1_0 | B13: AGIS-ESCAV-22T | C13: Escavadeira Hidráulica sobre esteira 22T [EQ] | D13: EQ | E13: 1 | F13: 42416 | G13: 7.82 | H13: 1 | I13: 331693.12
A14: eap-1_0 | B14: AGIS-ESCAV-22T | C14: Diesel — Escavadeira Hidráulica sobre esteira 22T | D14: COMB | E14: 1 | F14: 28059.43 | G14: 7.82 | H14: 1 | I14: 219424.74
A15: eap-1_0 | B15: AGIS-MOTOSSERRA | C15: Motosserra a Gasolina [EQ] | D15: EQ | E15: 1 | F15: 3300 | G15: 7.82 | H15: 1 | I15: 25806
A16: eap-1_0 | B16: AGIS-MOTOSSERRA | C16: Diesel — Motosserra a Gasolina | D16: COMB | E16: 1 | F16: 1913.14 | G16: 7.82 | H16: 1 | I16: 14960.75
A17: Subtotal eap-1_0 | I17: 2097750.5
A18: eap-1_1 — Esc/carg/transp 1aCat DMT<=2000m
A19: eap-1_1 | B19: CPU-TERRA-ESCO-CARGA-1CAT-DMT2000 | C19: Operador de Escavadeira | D19: DIRETO | E19: 1 | F19: 9394 | G19: 2.3 | H19: 1 | I19: 21606.2
A20: eap-1_1 | B20: CPU-TERRA-ESCO-CARGA-1CAT-DMT2000 | C20: Ajudante | D20: DIRETO | E20: 1 | F20: 4279 | G20: 2.3 | H20: 1 | I20: 9841.7
A21: eap-1_1 | B21: CPU-TERRA-ESCO-CARGA-1CAT-DMT2000 | C21: Encarregado de Frente | D21: DIRETO | E21: 1 | F21: 7499.8 | G21: 2.3 | H21: 1 | I21: 17249.54
A22: eap-1_1 | B22: CPU-TERRA-ESCO-CARGA-1CAT-DMT2000 | C22: Motorista de Caminhão Basculante | D22: DIRETO | E22: 7 | F22: 58674 | G22: 2.3 | H22: 1 | I22: 134950.2
A23: eap-1_1 | B23: AGIS-E0015 | C23: Escavadeira Hidráulica sobre esteira 38T [EQ] | D23: EQ | E23: 1 | F23: 59048 | G23: 2.3 | H23: 1 | I23: 135810.4
A24: eap-1_1 | B24: AGIS-E0015 | C24: Diesel — Escavadeira Hidráulica sobre esteira 38T | D24: COMB | E24: 1 | F24: 33161.14 | G24: 2.3 | H24: 1 | I24: 76270.62
A25: eap-1_1 | B25: AGIS-E0002 | C25: Caminhão Basculante 14 m³ [EQ] | D25: EQ | E25: 7 | F25: 26945.6 | G25: 2.3 | H25: 1 | I25: 61974.88
A26: eap-1_1 | B26: AGIS-E0002 | C26: Diesel — Caminhão Basculante 14 m³ | D26: COMB | E26: 7 | F26: 3188.57 | G26: 2.3 | H26: 1 | I26: 7333.71
A27: Subtotal eap-1_1 | I27: 938899.81
A28: eap-1_2 — Esc/carg/transp 1aCat DMT<=3000m
A29: eap-1_2 | B29: CPU-TERRA-ESCO-CARGA-1CAT-DMT3000 | C29: Operador de Escavadeira | D29: DIRETO | E29: 1 | F29: 9394 | G29: 7.13 | H29: 1 | I29: 66979.22
A30: eap-1_2 | B30: CPU-TERRA-ESCO-CARGA-1CAT-DMT3000 | C30: Ajudante | D30: DIRETO | E30: 1 | F30: 4279 | G30: 7.13 | H30: 1 | I30: 30509.27
A31: eap-1_2 | B31: CPU-TERRA-ESCO-CARGA-1CAT-DMT3000 | C31: Encarregado de Frente | D31: DIRETO | E31: 1 | F31: 7499.8 | G31: 7.13 | H31: 1 | I31: 53473.57
A32: eap-1_2 | B32: CPU-TERRA-ESCO-CARGA-1CAT-DMT3000 | C32: Motorista de Caminhão Basculante | D32: DIRETO | E32: 8 | F32: 67056 | G32: 7.13 | H32: 1 | I32: 478109.28
A33: eap-1_2 | B33: AGIS-E0015 | C33: Escavadeira Hidráulica sobre esteira 38T [EQ] | D33: EQ | E33: 1 | F33: 59048 | G33: 7.13 | H33: 1 | I33: 421012.24
A34: eap-1_2 | B34: AGIS-E0015 | C34: Diesel — Escavadeira Hidráulica sobre esteira 38T | D34: COMB | E34: 1 | F34: 33161.14 | G34: 7.13 | H34: 1 | I34: 236438.93
A35: eap-1_2 | B35: AGIS-E0002 | C35: Caminhão Basculante 14 m³ [EQ] | D35: EQ | E35: 8 | F35: 26945.6 | G35: 7.13 | H35: 1 | I35: 192122.13
A36: eap-1_2 | B36: AGIS-E0002 | C36: Diesel — Caminhão Basculante 14 m³ | D36: COMB | E36: 8 | F36: 3188.57 | G36: 7.13 | H36: 1 | I36: 22734.5
A37: Subtotal eap-1_2 | I37: 2910596.3
A38: eap-1_3 — Esc/carg/transp 2aCat DMT<=2000m
A39: eap-1_3 | B39: CPU-TERRA-ESCO-CARGA-2CAT-DMT2000 | C39: Operador de Escavadeira | D39: DIRETO | E39: 1 | F39: 9394 | G39: 1.61 | H39: 1 | I39: 15124.34
A40: eap-1_3 | B40: CPU-TERRA-ESCO-CARGA-2CAT-DMT2000 | C40: Ajudante | D40: DIRETO | E40: 1 | F40: 4279 | G40: 1.61 | H40: 1 | I40: 6889.19
...

Sheet EQUILIBRIO
A1: PONTO DE EQUILÍBRIO — CUSTO FIXO vs PREÇO DE VENDA (CPU)
A2: Item ID | B2: CPU ID | C2: Custo Fixo Equipe (R$) | D2: Preço Venda CPU (R$) | E2: Delta (R$) | F2: Status
A3: eap-1_0 | B3: CPU-TERRA-ATI-003 | C3: 2097749.9 | D3: 2477673.2 | E3: 379923.24 | F3: OK
A4: eap-1_1 | B4: CPU-TERRA-ESCO-CARGA-1CAT-DMT2000 | C4: 871125.3 | D4: 992406.46 | E4: 121281.16 | F4: OK
A5: eap-1_2 | B5: CPU-TERRA-ESCO-CARGA-1CAT-DMT3000 | C5: 2978388.1 | D5: 3441418.8 | E5: 463030.71 | F5: OK
A6: eap-1_3 | B6: CPU-TERRA-ESCO-CARGA-2CAT-DMT2000 | C6: 1097045.4 | D6: 1280092 | E6: 183046.61 | F6: OK
A7: eap-1_4 | B7: CPU-TERRA-ESCO-CARGA-2CAT-DMT3000 | C7: 6540503.7 | D7: 7597204.5 | E7: 1056700.8 | F7: OK
A8: eap-1_5 | B8: CPU-TERRA-ESCO-CARGA-3CAT-DMT2000 | C8: 4673919.8 | D8: 5452981.8 | E8: 779061.92 | F8: OK
A9: eap-1_6 | B9: CPU-TERRA-ESCO-CARGA-3CAT-DMT3000 | C9: 13038269 | D9: 14870247 | E9: 1831978.2 | F9: OK
A10: eap-1_7 | B10: CPU-TERRA-COMPAC-PN | C10: 10522970 | D10: 12156798 | E10: 1633827.8 | F10: OK
A11: eap-1_8 | B11: CPU-TERRA-COMPAC-PI | C11: 225479.85 | D11: 411657.26 | E11: 186177.41 | F11: OK
A12: eap-1_9 | B12: CPU-TERRA-CORPO-ATERRO-3CAT | C12: 5760051.5 | D12: 6741771.1 | E12: 981719.59 | F12: OK
A13: eap-1_10 | B13: CPU-TERRA-COMPAC-FINAL-ROCHA | C13: 394885.9 | D13: 415123.69 | E13: 20237.79 | F13: OK

Sheet CALENDARIO.OP
A1: CALENDARIO OPERACIONAL
A3: Semana ISO | B3: Dias úteis base | C3: Dias úteis efetivos | D3: Fator calendário | E3: Fator clima | F3: Fator total | G3: Eventos aplicados
A4: 2026-W23 | B4: 6 | C4: 6 | D4: 1 | E4: 1 | F4: 1
A5: 2026-W24 | B5: 6 | C5: 6 | D5: 1 | E5: 1 | F5: 1
A6: 2026-W25 | B6: 6 | C6: 6 | D6: 1 | E6: 1 | F6: 1
A7: 2026-W26 | B7: 6 | C7: 6 | D7: 1 | E7: 1 | F7: 1
A8: 2026-W27 | B8: 6 | C8: 6 | D8: 1 | E8: 1 | F8: 1
A9: 2026-W28 | B9: 6 | C9: 6 | D9: 1 | E9: 1 | F9: 1
A10: 2026-W29 | B10: 6 | C10: 6 | D10: 1 | E10: 1 | F10: 1
A11: 2026-W30 | B11: 6 | C11: 6 | D11: 1 | E11: 1 | F11: 1
A12: 2026-W31 | B12: 6 | C12: 6 | D12: 1 | E12: 1 | F12: 1
A13: 2026-W32 | B13: 6 | C13: 6 | D13: 1 | E13: 1 | F13: 1
A14: 2026-W33 | B14: 6 | C14: 6 | D14: 1 | E14: 1 | F14: 1
A15: 2026-W34 | B15: 6 | C15: 6 | D15: 1 | E15: 1 | F15: 1
... A59: 2027-W25 | B59: 6 | C59: 6 | D59: 1 | E59: 1 | F59: 1

Sheet RESULTADO
A1: RESULTADO FINANCEIRO — MENDESLOBO CONSTRUTORA
A3: PROJETO
A4: Nome | B4: AGIS - Ferrovia Nova Transnordestina (Supressao e Terraplanagem)
A5: Tipo de obra | B5: terraplenagem
A6: Localização | B6: Ceara, Brasil
A7: Período | B7: 2026-06-01 -> 2027-06-27
A8: Regime | B8: 6 dias/sem · 8 h/dia
A10: RECEITA CONTRATUAL (COM BDI)
A11: Preço de venda s/ BDI | B11: =PLANEJAMENTO!$M$15
A12: Preço de venda c/ BDI | B12: 85639774
A14: CUSTOS
A15: Custo direto (catálogo s/BDI) | B15: =PLANEJAMENTO!$M$15
A16: ADM | B16: ='INDIRETOS.DET'!$H$26
A17: TOP | B17: ='INDIRETOS.DET'!$H$32
A18: LAB | B18: ='INDIRETOS.DET'!$H$36
A19: QSMS | B19: ='INDIRETOS.DET'!$H$43
A20: MOB | B20: ='INDIRETOS.DET'!$H$46
A21: Custo indireto (subtotal) | B21: ='INDIRETOS.DET'!$H$48
A22: CUSTO TOTAL | B22: =B15+B21
A24: RESULTADO
A25: Resultado bruto (R$) | B25: =B12-B22
A26: Margem bruta (%) | B26: =IF(B12>0, B25/B12, 0)
A28: STATUS: VERMELHO
A30: COMPOSIÇÃO DE CUSTO
A31: Total Direto (catálogo s/BDI) | B31: =PLANEJAMENTO!$M$15
A32: Total Direto (c/BDI) | B32: 85639774
A33: RAZÃO CI / CD (%) | B33: 45.44
A34: CI / PVT (%) | B34: 24.85
A36: CAPITAL DE GIRO
A37: Exposição máxima | B37: 8083316.4
A38: Parcela mensal (meses 2 a n) | B38: 6587674
A39: Resíduo (mês n+1) | B39: 6587686
A40: Duração da execução (meses) | B40: 13
A41: ALAVANCAS DE REAJUSTE
A42: Preço de venda total | B42: 85639774 | C42: Depende de MO/EQ/MAT/DIESEL + BDI indireto
A43: Base catálogo s/BDI | B43: 46843791 | C43: Knob de partida para precificação
A44: Markup efetivo | B44: 0.25702828 | C44: Resultado consolidado, não a fórmula de composição
A45: Custo direto de equipes | B45: 48544218 | C45: Sensível a permanência, produtividade e nº de frentes
A46: Custo fixo mensal de equipes | B46: 3844188.3 | C46: Multiplica diretamente pela permanência
A47: Permanência média (meses) | B47: 5.1436364 | C47: Reduzir prazo reduz custo fixo e mobilização
...

Sheet ANALISE.FC_CAIXA
A1: FLUXO DE CAIXA — ACOMPANHAMENTO MENSAL
A2: Mês | B2: Despesa (R$) | C2: Receita (R$) | D2: Rec. Acumulada (R$) | E2: Saldo do Mês (R$) | F2: Saldo Atual (R$) | G2: Exposição Acum. (R$)
A3: Jun/26 | B3: 8083316.4 | C3: 0 | D3: 0 | E3: -8083316.4 | F3: -8083316.4 | G3: 8083316.4
A4: Jul/26 | B4: 4807790.6 | C4: 6587674 | D4: 6587674 | E4: 1779883.4 | F4: -6303433 | G4: 6303433
A5: Ago/26 | B5: 6278658.5 | C5: 6587674 | D5: 13175348 | E5: 309015.49 | F5: -5994417.5 | G5: 5994417.5
A6: Set/26 | B6: 6401356 | C6: 6587674 | D6: 19763022 | E6: 186317.95 | F6: -5808099.6 | G6: 5808099.6
A7: Out/26 | B7: 5395086.1 | C7: 6587674 | D7: 26350696 | E7: 1192587.9 | F7: -4615511.7 | G7: 4615511.7
A8: Nov/26 | B8: 6704830.9 | C8: 6587674 | D8: 32938370 | E8: -117156.86 | F8: -4732668.6 | G8: 4732668.6
A9: Dez/26 | B9: 5602786.8 | C9: 6587674 | D9: 39526044 | E9: 984887.17 | F9: -3747781.4 | G9: 3747781.4
A10: Jan/27 | B10: 5094563.1 | C10: 6587674 | D10: 46113718 | E10: 1493110.9 | F10: -2254670.5 | G10: 2254670.5
